<?xml version="1.0"?>
<robot name="2dof_manipulator/2dof_manip_1dof_inner">
 <link name="jlink1">
  <inertial>
    <mass value="1"/>
    <inertia ixx="0.010833333333333335" ixy="0" ixz="0" iyy="0.010833333333333335" iyz="0" izz="0.010000000000000002"/>
  </inertial>
  <visual>
    <origin rpy="0 0 1.57" xyz="0 0 0"/>
    <geometry>
      <cylinder length="0.1" radius="0.2"/>
    </geometry>
  </visual>
  <collision>
    <origin rpy="0 0 1.57" xyz="0 0 0"/>
    <geometry>
      <cylinder length="0.1" radius="0.2"/>
    </geometry>
  </collision>
 </link>

 <link name="link1">
  <inertial>
    <mass value="1"/>
    <inertia ixx="0.01416666666666667" ixy="0" ixz="0" iyy="0.20083333333333334" iyz="0" izz="0.1883333333333333"/>
  </inertial>
  <visual>
    <origin rpy="0 0 0" xyz="0 0.95 0"/>
    <geometry>
      <box size="0.4 1.5 0.1"/>
    </geometry>
  </visual>
  <collision>
    <origin rpy="0 0 0" xyz="0 0.95 0"/>
    <geometry>
      <box size="0.4 1.5 0.1"/>
    </geometry>
  </collision>
 </link>

 <link name="jlink2">
  <inertial>
    <mass value="1"/>
    <inertia ixx="0.010833333333333335" ixy="0" ixz="0" iyy="0.010833333333333335" iyz="0" izz="0.010000000000000002"/>
  </inertial>
  <visual>
    <origin rpy="0 0 1.57" xyz="0 0 0"/>
    <geometry>
      <cylinder length="0.1" radius="0.2"/>
    </geometry>
  </visual>
  <collision>
    <origin rpy="0 0 1.57" xyz="0 0 0"/>
    <geometry>
      <cylinder length="0.1" radius="0.2"/>
    </geometry>
  </collision>
 </link>

<joint name="joint_revolute_jlink1_link1_Z" type="revolute">
  <origin rpy="0 0 0" xyz="0 0 0"/>
  <parent link="jlink1"/>
  <child link="link1"/>
  <axis xyz="0 0 1"/>
  <dynamics damping="0.01" friction="0.5"/>
  <limit lower="-3.14" upper="3.14" effort="0.01" velocity="100"/>
</joint>

<joint name="joint_fixed_link1_jlink2" type="fixed">
  <origin rpy="0 0 0" xyz="0 1.9 0"/>
  <parent link="link1"/>
  <child link="jlink2"/>
</joint>

  <klampt package_root="../../.." default_acc_max="4" >
  </klampt>
</robot>