<?xml version="1.0"?>
<robot name="2dof_manipulator/2dof_manip">
 <link name="jlink1">
  <inertial>
    <mass value="1"/>
    <inertia ixx="0.010833333333333335" ixy="0" ixz="0" iyy="0.010833333333333335" iyz="0" izz="0.010000000000000002"/>
  </inertial>
  <visual>
    <origin rpy="0 0 1.57" xyz="0 0 0"/>
    <geometry>
      <cylinder length="0.1" radius="0.2"/>
    </geometry>
  </visual>
  <collision>
    <origin rpy="0 0 1.57" xyz="0 0 0"/>
    <geometry>
      <cylinder length="0.1" radius="0.2"/>
    </geometry>
  </collision>
 </link>

 <link name="link1">
  <inertial>
    <mass value="1"/>
    <inertia ixx="0.01416666666666667" ixy="0" ixz="0" iyy="0.20083333333333334" iyz="0" izz="0.1883333333333333"/>
  </inertial>
  <visual>
    <origin rpy="0 0 0" xyz="0 0.95 0"/>
    <geometry>
      <box size="0.4 1.5 0.1"/>
    </geometry>
  </visual>
  <collision>
    <origin rpy="0 0 0" xyz="0 0.95 0"/>
    <geometry>
      <box size="0.4 1.5 0.1"/>
    </geometry>
  </collision>
 </link>

 <link name="jlink2">
  <inertial>
    <mass value="1"/>
    <inertia ixx="0.010833333333333335" ixy="0" ixz="0" iyy="0.010833333333333335" iyz="0" izz="0.010000000000000002"/>
  </inertial>
  <visual>
    <origin rpy="0 0 1.57" xyz="0 0 0"/>
    <geometry>
      <cylinder length="0.1" radius="0.2"/>
    </geometry>
  </visual>
  <collision>
    <origin rpy="0 0 1.57" xyz="0 0 0"/>
    <geometry>
      <cylinder length="0.1" radius="0.2"/>
    </geometry>
  </collision>
 </link>

<joint name="joint_revolute_jlink1_link1_Z" type="revolute">
  <origin rpy="0 0 0" xyz="0 0 0"/>
  <parent link="jlink1"/>
  <child link="link1"/>
  <axis xyz="0 0 1"/>
  <dynamics damping="0.01" friction="0.5"/>
  <limit lower="-3.14" upper="3.14" effort="0.01" velocity="100"/>
</joint>

<joint name="joint_fixed_link1_jlink2" type="fixed">
  <origin rpy="0 0 0" xyz="0 1.9 0"/>
  <parent link="link1"/>
  <child link="jlink2"/>
</joint>

 <link name="link2">
  <inertial>
    <mass value="1"/>
    <inertia ixx="0.01416666666666667" ixy="0" ixz="0" iyy="0.20083333330833333" iyz="0" izz="0.1883333333083333"/>
  </inertial>
  <visual>
    <origin rpy="0 0 0" xyz="0 0.95 0"/>
    <geometry>
      <box size="0.4 1.4999999999 0.1"/>
    </geometry>
  </visual>
  <collision>
    <origin rpy="0 0 0" xyz="0 0.95 0"/>
    <geometry>
      <box size="0.4 1.4999999999 0.1"/>
    </geometry>
  </collision>
 </link>

<joint name="joint_revolute_jlink2_link2_Z" type="revolute">
  <origin rpy="0 0 0" xyz="0 0 0"/>
  <parent link="jlink2"/>
  <child link="link2"/>
  <axis xyz="0 0 1"/>
  <dynamics damping="0.01" friction="0.5"/>
  <limit lower="-3.14" upper="3.14" effort="0.01" velocity="100"/>
</joint>

 <link name="link3">
  <inertial>
    <mass value="1"/>
    <inertia ixx="0.04770833333333333" ixy="0" ixz="0" iyy="0.04770833333333333" iyz="0" izz="0.001666666666666667"/>
  </inertial>
  <visual>
    <origin rpy="0 0 0" xyz="0 0 0"/>
    <geometry>
      <box size="0.75 0.1 0.1"/>
    </geometry>
  </visual>
  <collision>
    <origin rpy="0 0 0" xyz="0 0 0"/>
    <geometry>
      <box size="0.75 0.1 0.1"/>
    </geometry>
  </collision>
 </link>

 <link name="endeffectorL">
  <inertial>
    <mass value="1"/>
    <inertia ixx="0.001666666666666667" ixy="0" ixz="0" iyy="0.01416666666666667" iyz="0" izz="0.01416666666666667"/>
  </inertial>
  <visual>
    <origin rpy="0 0 0" xyz="-0.25 0.2 0"/>
    <geometry>
      <box size="0.1 0.4 0.1"/>
    </geometry>
  </visual>
  <collision>
    <origin rpy="0 0 0" xyz="-0.25 0.2 0"/>
    <geometry>
      <box size="0.1 0.4 0.1"/>
    </geometry>
  </collision>
 </link>

 <link name="endeffectorR">
  <inertial>
    <mass value="1"/>
    <inertia ixx="0.001666666666666667" ixy="0" ixz="0" iyy="0.01416666666666667" iyz="0" izz="0.01416666666666667"/>
  </inertial>
  <visual>
    <origin rpy="0 0 0" xyz="0.05 0.2 0"/>
    <geometry>
      <box size="0.1 0.4 0.1"/>
    </geometry>
  </visual>
  <collision>
    <origin rpy="0 0 0" xyz="0.05 0.2 0"/>
    <geometry>
      <box size="0.1 0.4 0.1"/>
    </geometry>
  </collision>
 </link>

<joint name="joint_fixed_link2_link3" type="fixed">
  <origin rpy="0 0 0" xyz="0 1.7 0"/>
  <parent link="link2"/>
  <child link="link3"/>
</joint>

<joint name="joint_fixed_link3_endeffectorL" type="fixed">
  <origin rpy="0 0 0" xyz="0 0.05 0"/>
  <parent link="link3"/>
  <child link="endeffectorL"/>
</joint>

<joint name="joint_prismatic_link3_endeffectorR" type="prismatic">
  <origin rpy="0 0 0" xyz="0.2 0.05 0"/>
  <parent link="link3"/>
  <child link="endeffectorR"/>
  <limit lower="-0.3" upper="0.1" effort="0.01" velocity="100"/>
</joint>

  <klampt package_root="../../.." default_acc_max="4" fixed_root_link="0">
  </klampt>
</robot>
