<?xml version="1.0"?>
<robot name="box">
 <link name="bottom">
  <inertial>
    <mass value="1"/>
    <inertia ixx="0.3335416666666667" ixy="0" ixz="0" iyy="0.41666666666666663" iyz="0" izz="0.08354166666666665"/>
  </inertial>
  <visual>
    <origin rpy="0 0 0" xyz="0 0 0"/>
    <geometry>
      <box size="2.0 1.0 0.05"/>
    </geometry>
  </visual>
  <collision>
    <origin rpy="0 0 0" xyz="0 0 0"/>
    <geometry>
      <box size="2.0 1.0 0.05"/>
    </geometry>
  </collision>
 </link>

 <link name="bottom-sideB">
  <inertial>
    <mass value="1"/>
    <inertia ixx="0.33348958333333334" ixy="0" ixz="0" iyy="0.33348958333333334" iyz="0" izz="0.00015625000000000003"/>
  </inertial>
  <visual>
    <origin rpy="0 1.57 0" xyz="0 -0.525 0"/>
    <geometry>
      <cylinder length="2.0" radius="0.025"/>
    </geometry>
  </visual>
  <collision>
    <origin rpy="0 1.57 0" xyz="0 -0.525 0"/>
    <geometry>
      <cylinder length="2.0" radius="0.025"/>
    </geometry>
  </collision>
 </link>

<joint name="joint_fixed_bottom_bottom-sideB" type="fixed">
  <origin rpy="0 0 0" xyz="0 0 0"/>
  <parent link="bottom"/>
  <child link="bottom-sideB"/>
</joint>

 <link name="sideB">
  <inertial>
    <mass value="1"/>
    <inertia ixx="0.3335416666666667" ixy="0" ixz="0" iyy="0.37416666666666665" iyz="0" izz="0.04104166666666666"/>
  </inertial>
  <visual>
    <origin rpy="0 0 0" xyz="0 -0.375 0"/>
    <geometry>
      <box size="2.0 0.7 0.05"/>
    </geometry>
  </visual>
  <collision>
    <origin rpy="0 0 0" xyz="0 -0.375 0"/>
    <geometry>
      <box size="2.0 0.7 0.05"/>
    </geometry>
  </collision>
 </link>

<joint name="joint_revolute_bottom-sideB_sideB_Z" type="revolute">
  <origin rpy="0 0 0" xyz="0 -0.525 0"/>
  <parent link="bottom-sideB"/>
  <child link="sideB"/>
  <axis xyz="1 0 0"/>
  <dynamics damping="0.01" friction="0.5"/>
  <limit lower="-1.57" upper="1.57" effort="0.01" velocity="100"/>
</joint>

 <link name="bottom-sideALEFT">
  <inertial>
    <mass value="1"/>
    <inertia ixx="0.02628958333333334" ixy="0" ixz="0" iyy="0.02628958333333334" iyz="0" izz="0.00015625000000000003"/>
  </inertial>
  <visual>
    <origin rpy="0 1.57 0" xyz="-0.66 0.525 0"/>
    <geometry>
      <cylinder length="0.56" radius="0.025"/>
    </geometry>
  </visual>
  <collision>
    <origin rpy="0 1.57 0" xyz="-0.66 0.525 0"/>
    <geometry>
      <cylinder length="0.56" radius="0.025"/>
    </geometry>
  </collision>
 </link>

<joint name="joint_fixed_bottom_bottom-sideALEFT" type="fixed">
  <origin rpy="0 0 0" xyz="0 0 0"/>
  <parent link="bottom"/>
  <child link="bottom-sideALEFT"/>
</joint>

 <link name="sideALEFT">
  <inertial>
    <mass value="1"/>
    <inertia ixx="0.03650833333333334" ixy="0" ixz="0" iyy="0.07713333333333333" iyz="0" izz="0.04104166666666666"/>
  </inertial>
  <visual>
    <origin rpy="0 0 0" xyz="-0.66 0.375 0"/>
    <geometry>
      <box size="0.66 0.7 0.05"/>
    </geometry>
  </visual>
  <collision>
    <origin rpy="0 0 0" xyz="-0.66 0.375 0"/>
    <geometry>
      <box size="0.66 0.7 0.05"/>
    </geometry>
  </collision>
 </link>

<joint name="joint_revolute_bottom-sideALEFT_sideALEFT_Z" type="revolute">
  <origin rpy="0 0 0" xyz="0 0.525 0"/>
  <parent link="bottom-sideALEFT"/>
  <child link="sideALEFT"/>
  <axis xyz="1 0 0"/>
  <dynamics damping="0.01" friction="0.5"/>
  <limit lower="-1.57" upper="1.57" effort="0.01" velocity="100"/>
</joint>

 <link name="bottom-sideARIGHT">
  <inertial>
    <mass value="1"/>
    <inertia ixx="0.02628958333333334" ixy="0" ixz="0" iyy="0.02628958333333334" iyz="0" izz="0.00015625000000000003"/>
  </inertial>
  <visual>
    <origin rpy="0 1.57 0" xyz="0.66 0.525 0"/>
    <geometry>
      <cylinder length="0.56" radius="0.025"/>
    </geometry>
  </visual>
  <collision>
    <origin rpy="0 1.57 0" xyz="0.66 0.525 0"/>
    <geometry>
      <cylinder length="0.56" radius="0.025"/>
    </geometry>
  </collision>
 </link>

<joint name="joint_fixed_bottom_bottom-sideARIGHT" type="fixed">
  <origin rpy="0 0 0" xyz="0 0 0"/>
  <parent link="bottom"/>
  <child link="bottom-sideARIGHT"/>
</joint>

 <link name="sideARIGHT">
  <inertial>
    <mass value="1"/>
    <inertia ixx="0.03650833333333334" ixy="0" ixz="0" iyy="0.07713333333333333" iyz="0" izz="0.04104166666666666"/>
  </inertial>
  <visual>
    <origin rpy="0 0 0" xyz="0.66 0.375 0"/>
    <geometry>
      <box size="0.66 0.7 0.05"/>
    </geometry>
  </visual>
  <collision>
    <origin rpy="0 0 0" xyz="0.66 0.375 0"/>
    <geometry>
      <box size="0.66 0.7 0.05"/>
    </geometry>
  </collision>
 </link>

<joint name="joint_revolute_bottom-sideARIGHT_sideARIGHT_Z" type="revolute">
  <origin rpy="0 0 0" xyz="0 0.525 0"/>
  <parent link="bottom-sideARIGHT"/>
  <child link="sideARIGHT"/>
  <axis xyz="1 0 0"/>
  <dynamics damping="0.01" friction="0.5"/>
  <limit lower="-1.57" upper="1.57" effort="0.01" velocity="100"/>
</joint>

 <link name="sideA-left">
  <inertial>
    <mass value="1"/>
    <inertia ixx="0.04098958333333332" ixy="0" ixz="0" iyy="0.04098958333333332" iyz="0" izz="0.00015625000000000003"/>
  </inertial>
  <visual>
    <origin rpy="1.57 0 0" xyz="-1.025 0 0"/>
    <geometry>
      <cylinder length="0.7" radius="0.025"/>
    </geometry>
  </visual>
  <collision>
    <origin rpy="1.57 0 0" xyz="-1.025 0 0"/>
    <geometry>
      <cylinder length="0.7" radius="0.025"/>
    </geometry>
  </collision>
 </link>

<joint name="joint_fixed_sideALEFT_sideA-left" type="fixed">
  <origin rpy="0 0 0" xyz="0 0.375 0"/>
  <parent link="sideALEFT"/>
  <child link="sideA-left"/>
</joint>

 <link name="sideA1">
  <inertial>
    <mass value="1"/>
    <inertia ixx="0.013541666666666669" ixy="0" ixz="0" iyy="0.046408333333333336" iyz="0" izz="0.03328333333333333"/>
  </inertial>
  <visual>
    <origin rpy="0 0 0" xyz="-0.225 0 0"/>
    <geometry>
      <box size="0.4 0.63 0.05"/>
    </geometry>
  </visual>
  <collision>
    <origin rpy="0 0 0" xyz="-0.225 0 0"/>
    <geometry>
      <box size="0.4 0.63 0.05"/>
    </geometry>
  </collision>
 </link>

<joint name="joint_revolute_sideA-left_sideA1_Z" type="revolute">
  <origin rpy="0 0 0" xyz="-1.025 0 0"/>
  <parent link="sideA-left"/>
  <child link="sideA1"/>
  <axis xyz="0 1 0"/>
  <dynamics damping="0.01" friction="0.5"/>
  <limit lower="-1.57" upper="1.57" effort="0.01" velocity="100"/>
</joint>

 <link name="sideA-right">
  <inertial>
    <mass value="1"/>
    <inertia ixx="0.04098958333333332" ixy="0" ixz="0" iyy="0.04098958333333332" iyz="0" izz="0.00015625000000000003"/>
  </inertial>
  <visual>
    <origin rpy="1.57 0 0" xyz="1.025 0 0"/>
    <geometry>
      <cylinder length="0.7" radius="0.025"/>
    </geometry>
  </visual>
  <collision>
    <origin rpy="1.57 0 0" xyz="1.025 0 0"/>
    <geometry>
      <cylinder length="0.7" radius="0.025"/>
    </geometry>
  </collision>
 </link>

<joint name="joint_fixed_sideARIGHT_sideA-right" type="fixed">
  <origin rpy="0 0 0" xyz="0 0.375 0"/>
  <parent link="sideARIGHT"/>
  <child link="sideA-right"/>
</joint>

 <link name="sideA2">
  <inertial>
    <mass value="1"/>
    <inertia ixx="0.013541666666666669" ixy="0" ixz="0" iyy="0.046408333333333336" iyz="0" izz="0.03328333333333333"/>
  </inertial>
  <visual>
    <origin rpy="0 0 0" xyz="0.225 0 0"/>
    <geometry>
      <box size="0.4 0.63 0.05"/>
    </geometry>
  </visual>
  <collision>
    <origin rpy="0 0 0" xyz="0.225 0 0"/>
    <geometry>
      <box size="0.4 0.63 0.05"/>
    </geometry>
  </collision>
 </link>

<joint name="joint_revolute_sideA-right_sideA2_Z" type="revolute">
  <origin rpy="0 0 0" xyz="1.025 0 0"/>
  <parent link="sideA-right"/>
  <child link="sideA2"/>
  <axis xyz="0 1 0"/>
  <dynamics damping="0.01" friction="0.5"/>
  <limit lower="-1.57" upper="1.57" effort="0.01" velocity="100"/>
</joint>

 <link name="sideB-left">
  <inertial>
    <mass value="1"/>
    <inertia ixx="0.04098958333333332" ixy="0" ixz="0" iyy="0.04098958333333332" iyz="0" izz="0.00015625000000000003"/>
  </inertial>
  <visual>
    <origin rpy="1.57 0 0" xyz="-1.025 0 0"/>
    <geometry>
      <cylinder length="0.7" radius="0.025"/>
    </geometry>
  </visual>
  <collision>
    <origin rpy="1.57 0 0" xyz="-1.025 0 0"/>
    <geometry>
      <cylinder length="0.7" radius="0.025"/>
    </geometry>
  </collision>
 </link>

<joint name="joint_fixed_sideB_sideB-left" type="fixed">
  <origin rpy="0 0 0" xyz="0 -0.375 0"/>
  <parent link="sideB"/>
  <child link="sideB-left"/>
</joint>

 <link name="sideB1">
  <inertial>
    <mass value="1"/>
    <inertia ixx="0.013541666666666669" ixy="0" ixz="0" iyy="0.046408333333333336" iyz="0" izz="0.03328333333333333"/>
  </inertial>
  <visual>
    <origin rpy="0 0 0" xyz="-0.225 0 0"/>
    <geometry>
      <box size="0.4 0.63 0.05"/>
    </geometry>
  </visual>
  <collision>
    <origin rpy="0 0 0" xyz="-0.225 0 0"/>
    <geometry>
      <box size="0.4 0.63 0.05"/>
    </geometry>
  </collision>
 </link>

<joint name="joint_revolute_sideB-left_sideB1_Z" type="revolute">
  <origin rpy="0 0 0" xyz="-1.025 0 0"/>
  <parent link="sideB-left"/>
  <child link="sideB1"/>
  <axis xyz="0 1 0"/>
  <dynamics damping="0.01" friction="0.5"/>
  <limit lower="-1.57" upper="1.57" effort="0.01" velocity="100"/>
</joint>

 <link name="sideB-right">
  <inertial>
    <mass value="1"/>
    <inertia ixx="0.04098958333333332" ixy="0" ixz="0" iyy="0.04098958333333332" iyz="0" izz="0.00015625000000000003"/>
  </inertial>
  <visual>
    <origin rpy="1.57 0 0" xyz="1.025 0 0"/>
    <geometry>
      <cylinder length="0.7" radius="0.025"/>
    </geometry>
  </visual>
  <collision>
    <origin rpy="1.57 0 0" xyz="1.025 0 0"/>
    <geometry>
      <cylinder length="0.7" radius="0.025"/>
    </geometry>
  </collision>
 </link>

<joint name="joint_fixed_sideB_sideB-right" type="fixed">
  <origin rpy="0 0 0" xyz="0 -0.375 0"/>
  <parent link="sideB"/>
  <child link="sideB-right"/>
</joint>

 <link name="sideB2">
  <inertial>
    <mass value="1"/>
    <inertia ixx="0.013541666666666669" ixy="0" ixz="0" iyy="0.046408333333333336" iyz="0" izz="0.03328333333333333"/>
  </inertial>
  <visual>
    <origin rpy="0 0 0" xyz="0.225 0 0"/>
    <geometry>
      <box size="0.4 0.63 0.05"/>
    </geometry>
  </visual>
  <collision>
    <origin rpy="0 0 0" xyz="0.225 0 0"/>
    <geometry>
      <box size="0.4 0.63 0.05"/>
    </geometry>
  </collision>
 </link>

<joint name="joint_revolute_sideB-right_sideB2_Z" type="revolute">
  <origin rpy="0 0 0" xyz="1.025 0 0"/>
  <parent link="sideB-right"/>
  <child link="sideB2"/>
  <axis xyz="0 1 0"/>
  <dynamics damping="0.01" friction="0.5"/>
  <limit lower="-1.57" upper="1.57" effort="0.01" velocity="100"/>
</joint>

 <link name="padB1">
  <inertial>
    <mass value="1"/>
    <inertia ixx="0.0005604166666666667" ixy="0" ixz="0" iyy="0.08368541666666665" iyz="0" izz="0.08354166666666665"/>
  </inertial>
  <visual>
    <origin rpy="0 0 0" xyz="-1.0325 0 0"/>
    <geometry>
      <box size="0.065 1.0 0.05"/>
    </geometry>
  </visual>
  <collision>
    <origin rpy="0 0 0" xyz="-1.0325 0 0"/>
    <geometry>
      <box size="0.065 1.0 0.05"/>
    </geometry>
  </collision>
 </link>

<joint name="joint_fixed_bottom_padB1" type="fixed">
  <origin rpy="0 0 0" xyz="0 0 0"/>
  <parent link="bottom"/>
  <child link="padB1"/>
</joint>

 <link name="padB-cylinder">
  <inertial>
    <mass value="1"/>
    <inertia ixx="0.08348958333333333" ixy="0" ixz="0" iyy="0.08348958333333333" iyz="0" izz="0.00015625000000000003"/>
  </inertial>
  <visual>
    <origin rpy="1.57 0 0" xyz="-1.0899999999999999 0 0"/>
    <geometry>
      <cylinder length="1.0" radius="0.025"/>
    </geometry>
  </visual>
  <collision>
    <origin rpy="1.57 0 0" xyz="-1.0899999999999999 0 0"/>
    <geometry>
      <cylinder length="1.0" radius="0.025"/>
    </geometry>
  </collision>
 </link>

<joint name="joint_fixed_padB1_padB-cylinder" type="fixed">
  <origin rpy="0 0 0" xyz="0 0 0"/>
  <parent link="padB1"/>
  <child link="padB-cylinder"/>
</joint>

 <link name="B1">
  <inertial>
    <mass value="1"/>
    <inertia ixx="0.04104166666666666" ixy="0" ixz="0" iyy="0.12416666666666666" iyz="0" izz="0.08354166666666665"/>
  </inertial>
  <visual>
    <origin rpy="0 0 0" xyz="-0.375 0 0"/>
    <geometry>
      <box size="0.7 1.0 0.05"/>
    </geometry>
  </visual>
  <collision>
    <origin rpy="0 0 0" xyz="-0.375 0 0"/>
    <geometry>
      <box size="0.7 1.0 0.05"/>
    </geometry>
  </collision>
 </link>

<joint name="joint_revolute_padB-cylinder_B1_Z" type="revolute">
  <origin rpy="0 0 0" xyz="-1.0899999999999999 0 0"/>
  <parent link="padB-cylinder"/>
  <child link="B1"/>
  <axis xyz="0 1 0"/>
  <dynamics damping="0.01" friction="0.5"/>
  <limit lower="-1.57" upper="1.57" effort="0.01" velocity="100"/>
</joint>

 <link name="padB2-cylinder">
  <inertial>
    <mass value="1"/>
    <inertia ixx="0.08348958333333333" ixy="0" ixz="0" iyy="0.08348958333333333" iyz="0" izz="0.00015625000000000003"/>
  </inertial>
  <visual>
    <origin rpy="1.57 0 0" xyz="-0.375 0 0"/>
    <geometry>
      <cylinder length="1.0" radius="0.025"/>
    </geometry>
  </visual>
  <collision>
    <origin rpy="1.57 0 0" xyz="-0.375 0 0"/>
    <geometry>
      <cylinder length="1.0" radius="0.025"/>
    </geometry>
  </collision>
 </link>

<joint name="joint_fixed_B1_padB2-cylinder" type="fixed">
  <origin rpy="0 0 0" xyz="-0.375 0 0"/>
  <parent link="B1"/>
  <child link="padB2-cylinder"/>
</joint>

 <link name="padB2">
  <inertial>
    <mass value="1"/>
    <inertia ixx="0.0007416666666666667" ixy="0" ixz="0" iyy="0.08386666666666666" iyz="0" izz="0.08354166666666665"/>
  </inertial>
  <visual>
    <origin rpy="0 0 0" xyz="-0.065 0 0"/>
    <geometry>
      <box size="0.08 1.0 0.05"/>
    </geometry>
  </visual>
  <collision>
    <origin rpy="0 0 0" xyz="-0.065 0 0"/>
    <geometry>
      <box size="0.08 1.0 0.05"/>
    </geometry>
  </collision>
 </link>

<joint name="joint_revolute_padB2-cylinder_padB2_Z" type="revolute">
  <origin rpy="0 0 0" xyz="-0.375 0 0"/>
  <parent link="padB2-cylinder"/>
  <child link="padB2"/>
  <axis xyz="0 1 0"/>
  <dynamics damping="0.01" friction="0.5"/>
  <limit lower="-1.57" upper="1.57" effort="0.01" velocity="100"/>
</joint>

 <link name="B2-cylinder">
  <inertial>
    <mass value="1"/>
    <inertia ixx="0.08348958333333333" ixy="0" ixz="0" iyy="0.08348958333333333" iyz="0" izz="0.00015625000000000003"/>
  </inertial>
  <visual>
    <origin rpy="1.57 0 0" xyz="-0.065 0 0"/>
    <geometry>
      <cylinder length="1.0" radius="0.025"/>
    </geometry>
  </visual>
  <collision>
    <origin rpy="1.57 0 0" xyz="-0.065 0 0"/>
    <geometry>
      <cylinder length="1.0" radius="0.025"/>
    </geometry>
  </collision>
 </link>

<joint name="joint_fixed_padB2_B2-cylinder" type="fixed">
  <origin rpy="0 0 0" xyz="-0.065 0 0"/>
  <parent link="padB2"/>
  <child link="B2-cylinder"/>
</joint>

 <link name="B2">
  <inertial>
    <mass value="1"/>
    <inertia ixx="0.03224166666666667" ixy="0" ixz="0" iyy="0.11536666666666667" iyz="0" izz="0.08354166666666665"/>
  </inertial>
  <visual>
    <origin rpy="0 0 0" xyz="-0.335 0 0"/>
    <geometry>
      <box size="0.62 1.0 0.05"/>
    </geometry>
  </visual>
  <collision>
    <origin rpy="0 0 0" xyz="-0.335 0 0"/>
    <geometry>
      <box size="0.62 1.0 0.05"/>
    </geometry>
  </collision>
 </link>

<joint name="joint_revolute_B2-cylinder_B2_Z" type="revolute">
  <origin rpy="0 0 0" xyz="-0.065 0 0"/>
  <parent link="B2-cylinder"/>
  <child link="B2"/>
  <axis xyz="0 1 0"/>
  <dynamics damping="0.01" friction="0.5"/>
  <limit lower="-1.57" upper="1.57" effort="0.01" velocity="100"/>
</joint>

 <link name="padB3">
  <inertial>
    <mass value="1"/>
    <inertia ixx="0.0005604166666666667" ixy="0" ixz="0" iyy="0.08368541666666665" iyz="0" izz="0.08354166666666665"/>
  </inertial>
  <visual>
    <origin rpy="0 0 0" xyz="1.0325 0 0"/>
    <geometry>
      <box size="0.065 1.0 0.05"/>
    </geometry>
  </visual>
  <collision>
    <origin rpy="0 0 0" xyz="1.0325 0 0"/>
    <geometry>
      <box size="0.065 1.0 0.05"/>
    </geometry>
  </collision>
 </link>

<joint name="joint_fixed_bottom_padB3" type="fixed">
  <origin rpy="0 0 0" xyz="0 0 0"/>
  <parent link="bottom"/>
  <child link="padB3"/>
</joint>

 <link name="padB3-cylinder">
  <inertial>
    <mass value="1"/>
    <inertia ixx="0.08348958333333333" ixy="0" ixz="0" iyy="0.08348958333333333" iyz="0" izz="0.00015625000000000003"/>
  </inertial>
  <visual>
    <origin rpy="1.57 0 0" xyz="1.0899999999999999 0 0"/>
    <geometry>
      <cylinder length="1.0" radius="0.025"/>
    </geometry>
  </visual>
  <collision>
    <origin rpy="1.57 0 0" xyz="1.0899999999999999 0 0"/>
    <geometry>
      <cylinder length="1.0" radius="0.025"/>
    </geometry>
  </collision>
 </link>

<joint name="joint_fixed_padB3_padB3-cylinder" type="fixed">
  <origin rpy="0 0 0" xyz="0 0 0"/>
  <parent link="padB3"/>
  <child link="padB3-cylinder"/>
</joint>

 <link name="B3">
  <inertial>
    <mass value="1"/>
    <inertia ixx="0.04104166666666666" ixy="0" ixz="0" iyy="0.12416666666666666" iyz="0" izz="0.08354166666666665"/>
  </inertial>
  <visual>
    <origin rpy="0 0 0" xyz="0.375 0 0"/>
    <geometry>
      <box size="0.7 1.0 0.05"/>
    </geometry>
  </visual>
  <collision>
    <origin rpy="0 0 0" xyz="0.375 0 0"/>
    <geometry>
      <box size="0.7 1.0 0.05"/>
    </geometry>
  </collision>
 </link>

<joint name="joint_revolute_padB3-cylinder_B3_Z" type="revolute">
  <origin rpy="0 0 0" xyz="1.0899999999999999 0 0"/>
  <parent link="padB3-cylinder"/>
  <child link="B3"/>
  <axis xyz="0 1 0"/>
  <dynamics damping="0.01" friction="0.5"/>
  <limit lower="-1.57" upper="1.57" effort="0.01" velocity="100"/>
</joint>

 <link name="padB4-cylinder">
  <inertial>
    <mass value="1"/>
    <inertia ixx="0.08348958333333333" ixy="0" ixz="0" iyy="0.08348958333333333" iyz="0" izz="0.00015625000000000003"/>
  </inertial>
  <visual>
    <origin rpy="1.57 0 0" xyz="0.375 0 0"/>
    <geometry>
      <cylinder length="1.0" radius="0.025"/>
    </geometry>
  </visual>
  <collision>
    <origin rpy="1.57 0 0" xyz="0.375 0 0"/>
    <geometry>
      <cylinder length="1.0" radius="0.025"/>
    </geometry>
  </collision>
 </link>

<joint name="joint_fixed_B3_padB4-cylinder" type="fixed">
  <origin rpy="0 0 0" xyz="0.375 0 0"/>
  <parent link="B3"/>
  <child link="padB4-cylinder"/>
</joint>

 <link name="padB4">
  <inertial>
    <mass value="1"/>
    <inertia ixx="0.0007416666666666667" ixy="0" ixz="0" iyy="0.08386666666666666" iyz="0" izz="0.08354166666666665"/>
  </inertial>
  <visual>
    <origin rpy="0 0 0" xyz="0.065 0 0"/>
    <geometry>
      <box size="0.08 1.0 0.05"/>
    </geometry>
  </visual>
  <collision>
    <origin rpy="0 0 0" xyz="0.065 0 0"/>
    <geometry>
      <box size="0.08 1.0 0.05"/>
    </geometry>
  </collision>
 </link>

<joint name="joint_revolute_padB4-cylinder_padB4_Z" type="revolute">
  <origin rpy="0 0 0" xyz="0.375 0 0"/>
  <parent link="padB4-cylinder"/>
  <child link="padB4"/>
  <axis xyz="0 1 0"/>
  <dynamics damping="0.01" friction="0.5"/>
  <limit lower="-1.57" upper="1.57" effort="0.01" velocity="100"/>
</joint>

 <link name="B4-cylinder">
  <inertial>
    <mass value="1"/>
    <inertia ixx="0.08348958333333333" ixy="0" ixz="0" iyy="0.08348958333333333" iyz="0" izz="0.00015625000000000003"/>
  </inertial>
  <visual>
    <origin rpy="1.57 0 0" xyz="0.065 0 0"/>
    <geometry>
      <cylinder length="1.0" radius="0.025"/>
    </geometry>
  </visual>
  <collision>
    <origin rpy="1.57 0 0" xyz="0.065 0 0"/>
    <geometry>
      <cylinder length="1.0" radius="0.025"/>
    </geometry>
  </collision>
 </link>

<joint name="joint_fixed_padB4_B4-cylinder" type="fixed">
  <origin rpy="0 0 0" xyz="0.065 0 0"/>
  <parent link="padB4"/>
  <child link="B4-cylinder"/>
</joint>

 <link name="B4">
  <inertial>
    <mass value="1"/>
    <inertia ixx="0.03224166666666667" ixy="0" ixz="0" iyy="0.11536666666666667" iyz="0" izz="0.08354166666666665"/>
  </inertial>
  <visual>
    <origin rpy="0 0 0" xyz="0.335 0 0"/>
    <geometry>
      <box size="0.62 1.0 0.05"/>
    </geometry>
  </visual>
  <collision>
    <origin rpy="0 0 0" xyz="0.335 0 0"/>
    <geometry>
      <box size="0.62 1.0 0.05"/>
    </geometry>
  </collision>
 </link>

<joint name="joint_revolute_B4-cylinder_B4_Z" type="revolute">
  <origin rpy="0 0 0" xyz="0.065 0 0"/>
  <parent link="B4-cylinder"/>
  <child link="B4"/>
  <axis xyz="0 1 0"/>
  <dynamics damping="0.01" friction="0.5"/>
  <limit lower="-1.57" upper="1.57" effort="0.01" velocity="100"/>
</joint>

 <link name="zbottom-ZsideA">
  <inertial>
    <mass value="1"/>
    <inertia ixx="0.03116458333333333" ixy="0" ixz="0" iyy="0.03116458333333333" iyz="0" izz="0.00015625000000000003"/>
  </inertial>
  <visual>
    <origin rpy="0 1.57 0" xyz="0 0.525 0"/>
    <geometry>
      <cylinder length="0.61" radius="0.025"/>
    </geometry>
  </visual>
  <collision>
    <origin rpy="0 1.57 0" xyz="0 0.525 0"/>
    <geometry>
      <cylinder length="0.61" radius="0.025"/>
    </geometry>
  </collision>
 </link>

<joint name="joint_fixed_bottom_zbottom-ZsideA" type="fixed">
  <origin rpy="0 0 0" xyz="0 0 0"/>
  <parent link="bottom"/>
  <child link="zbottom-ZsideA"/>
</joint>

 <link name="ZsideA">
  <inertial>
    <mass value="1"/>
    <inertia ixx="0.031216666666666663" ixy="0" ixz="0" iyy="0.07184166666666665" iyz="0" izz="0.04104166666666666"/>
  </inertial>
  <visual>
    <origin rpy="0 0 0" xyz="0 0.375 0"/>
    <geometry>
      <box size="0.61 0.7 0.05"/>
    </geometry>
  </visual>
  <collision>
    <origin rpy="0 0 0" xyz="0 0.375 0"/>
    <geometry>
      <box size="0.61 0.7 0.05"/>
    </geometry>
  </collision>
 </link>

<joint name="joint_revolute_zbottom-ZsideA_ZsideA_Z" type="revolute">
  <origin rpy="0 0 0" xyz="0 0.525 0"/>
  <parent link="zbottom-ZsideA"/>
  <child link="ZsideA"/>
  <axis xyz="1 0 0"/>
  <dynamics damping="0.01" friction="0.5"/>
  <limit lower="-1.57" upper="1.57" effort="0.01" velocity="100"/>
</joint>

 <link name="ZsideA-top">
  <inertial>
    <mass value="1"/>
    <inertia ixx="0.03116458333333333" ixy="0" ixz="0" iyy="0.03116458333333333" iyz="0" izz="0.00015625000000000003"/>
  </inertial>
  <visual>
    <origin rpy="0 1.57 0" xyz="0 0.375 0"/>
    <geometry>
      <cylinder length="0.61" radius="0.025"/>
    </geometry>
  </visual>
  <collision>
    <origin rpy="0 1.57 0" xyz="0 0.375 0"/>
    <geometry>
      <cylinder length="0.61" radius="0.025"/>
    </geometry>
  </collision>
 </link>

<joint name="joint_fixed_ZsideA_ZsideA-top" type="fixed">
  <origin rpy="0 0 0" xyz="0 0.375 0"/>
  <parent link="ZsideA"/>
  <child link="ZsideA-top"/>
</joint>

 <link name="Ztop">
  <inertial>
    <mass value="1"/>
    <inertia ixx="0.25250833333333333" ixy="0" ixz="0" iyy="0.32515208333333334" iyz="0" izz="0.07306041666666667"/>
  </inertial>
  <visual>
    <origin rpy="0 0 0" xyz="0 0.49250000000000005 0"/>
    <geometry>
      <box size="1.74 0.935 0.05"/>
    </geometry>
  </visual>
  <collision>
    <origin rpy="0 0 0" xyz="0 0.49250000000000005 0"/>
    <geometry>
      <box size="1.74 0.935 0.05"/>
    </geometry>
  </collision>
 </link>

<joint name="joint_revolute_ZsideA-top_Ztop_Z" type="revolute">
  <origin rpy="0 0 0" xyz="0 0.375 0"/>
  <parent link="ZsideA-top"/>
  <child link="Ztop"/>
  <axis xyz="1 0 0"/>
  <dynamics damping="0.01" friction="0.5"/>
  <limit lower="-1.57" upper="1.57" effort="0.01" velocity="100"/>
</joint>

 <link name="ZT3-cylinder">
  <inertial>
    <mass value="1"/>
    <inertia ixx="0.23395833333333335" ixy="0" ixz="0" iyy="0.23395833333333335" iyz="0" izz="0.00015625000000000003"/>
  </inertial>
  <visual>
    <origin rpy="0 1.57 0" xyz="0 0.49250000000000005 0"/>
    <geometry>
      <cylinder length="1.675" radius="0.025"/>
    </geometry>
  </visual>
  <collision>
    <origin rpy="0 1.57 0" xyz="0 0.49250000000000005 0"/>
    <geometry>
      <cylinder length="1.675" radius="0.025"/>
    </geometry>
  </collision>
 </link>

<joint name="joint_fixed_Ztop_ZT3-cylinder" type="fixed">
  <origin rpy="0 0 0" xyz="0 0.49250000000000005 0"/>
  <parent link="Ztop"/>
  <child link="ZT3-cylinder"/>
</joint>

 <link name="ZT3">
  <inertial>
    <mass value="1"/>
    <inertia ixx="0.23401041666666667" ixy="0" ixz="0" iyy="0.2374770833333333" iyz="0" izz="0.003883333333333333"/>
  </inertial>
  <visual>
    <origin rpy="0 0 0" xyz="0 0.13 0"/>
    <geometry>
      <box size="1.675 0.21 0.05"/>
    </geometry>
  </visual>
  <collision>
    <origin rpy="0 0 0" xyz="0 0.13 0"/>
    <geometry>
      <box size="1.675 0.21 0.05"/>
    </geometry>
  </collision>
 </link>

<joint name="joint_revolute_ZT3-cylinder_ZT3_Z" type="revolute">
  <origin rpy="0 0 0" xyz="0 0.49250000000000005 0"/>
  <parent link="ZT3-cylinder"/>
  <child link="ZT3"/>
  <axis xyz="1 0 0"/>
  <dynamics damping="0.01" friction="0.5"/>
  <limit lower="-1.57" upper="1.57" effort="0.01" velocity="100"/>
</joint>

 <link name="ZTop-left">
  <inertial>
    <mass value="1"/>
    <inertia ixx="0.026383000000000004" ixy="0" ixz="0" iyy="0.026383000000000004" iyz="0" izz="0.00015625000000000003"/>
  </inertial>
  <visual>
    <origin rpy="1.57 0 0" xyz="-0.895 0.49250000000000005 0"/>
    <geometry>
      <cylinder length="0.561" radius="0.025"/>
    </geometry>
  </visual>
  <collision>
    <origin rpy="1.57 0 0" xyz="-0.895 0.49250000000000005 0"/>
    <geometry>
      <cylinder length="0.561" radius="0.025"/>
    </geometry>
  </collision>
 </link>

<joint name="joint_fixed_Ztop_ZTop-left" type="fixed">
  <origin rpy="0 0 0" xyz="0 0 0"/>
  <parent link="Ztop"/>
  <child link="ZTop-left"/>
</joint>

 <link name="ZT1">
  <inertial>
    <mass value="1"/>
    <inertia ixx="0.0006166666666666666" ixy="0" ixz="0" iyy="0.02663508333333334" iyz="0" izz="0.026435083333333338"/>
  </inertial>
  <visual>
    <origin rpy="0 0 0" xyz="-0.06 0.49250000000000005 0"/>
    <geometry>
      <box size="0.06999999999999999 0.561 0.05"/>
    </geometry>
  </visual>
  <collision>
    <origin rpy="0 0 0" xyz="-0.06 0.49250000000000005 0"/>
    <geometry>
      <box size="0.06999999999999999 0.561 0.05"/>
    </geometry>
  </collision>
 </link>

<joint name="joint_revolute_ZTop-left_ZT1_Z" type="revolute">
  <origin rpy="0 0 0" xyz="-0.895 0 0"/>
  <parent link="ZTop-left"/>
  <child link="ZT1"/>
  <axis xyz="0 1 0"/>
  <dynamics damping="0.01" friction="0.5"/>
  <limit lower="-1.57" upper="1.57" effort="0.01" velocity="100"/>
</joint>

 <link name="ZTop-right">
  <inertial>
    <mass value="1"/>
    <inertia ixx="0.026383000000000004" ixy="0" ixz="0" iyy="0.026383000000000004" iyz="0" izz="0.00015625000000000003"/>
  </inertial>
  <visual>
    <origin rpy="1.57 0 0" xyz="0.895 0.49250000000000005 0"/>
    <geometry>
      <cylinder length="0.561" radius="0.025"/>
    </geometry>
  </visual>
  <collision>
    <origin rpy="1.57 0 0" xyz="0.895 0.49250000000000005 0"/>
    <geometry>
      <cylinder length="0.561" radius="0.025"/>
    </geometry>
  </collision>
 </link>

<joint name="joint_fixed_Ztop_ZTop-right" type="fixed">
  <origin rpy="0 0 0" xyz="0 0 0"/>
  <parent link="Ztop"/>
  <child link="ZTop-right"/>
</joint>

 <link name="ZT2">
  <inertial>
    <mass value="1"/>
    <inertia ixx="0.0006166666666666666" ixy="0" ixz="0" iyy="0.02663508333333334" iyz="0" izz="0.026435083333333338"/>
  </inertial>
  <visual>
    <origin rpy="0 0 0" xyz="0.06 0.49250000000000005 0"/>
    <geometry>
      <box size="0.06999999999999999 0.561 0.05"/>
    </geometry>
  </visual>
  <collision>
    <origin rpy="0 0 0" xyz="0.06 0.49250000000000005 0"/>
    <geometry>
      <box size="0.06999999999999999 0.561 0.05"/>
    </geometry>
  </collision>
 </link>

<joint name="joint_revolute_ZTop-right_ZT2_Z" type="revolute">
  <origin rpy="0 0 0" xyz="0.895 0 0"/>
  <parent link="ZTop-right"/>
  <child link="ZT2"/>
  <axis xyz="0 1 0"/>
  <dynamics damping="0.01" friction="0.5"/>
  <limit lower="-1.57" upper="1.57" effort="0.01" velocity="100"/>
</joint>

  <klampt package_root="../../.." default_acc_max="4" >
  </klampt>
</robot>