<?xml version="1.0"?>
<robot name="planar_manipulator/2dof_manip_no_endeffector">
 <link name="jlink0">
  <inertial>
    <mass value="1"/>
    <inertia ixx="0.0108333333333" ixy="0" ixz="0" iyy="0.0108333333333" iyz="0" izz="0.01"/>
  </inertial>
 </link>

 <link name="link0">
  <inertial>
    <mass value="1"/>
    <inertia ixx="0.0141666666667" ixy="0" ixz="0" iyy="0.200833333333" iyz="0" izz="0.188333333333"/>
  </inertial>
  <visual>
    <origin rpy="0 0 0" xyz="0 0.95 0"/>
    <geometry>
      <box size="0.4 1.5 0.1"/>
    </geometry>
  </visual>
  <collision>
    <origin rpy="0 0 0" xyz="0 0.95 0"/>
    <geometry>
      <box size="0.4 1.5 0.1"/>
    </geometry>
  </collision>
 </link>

<joint name="joint_revolute_jlink0_link0_Z" type="revolute">
  <origin rpy="0 0 0" xyz="0 0 0"/>
  <parent link="jlink0"/>
  <child link="link0"/>
  <axis xyz="0 0 1"/>
  <dynamics damping="0.01" friction="0.5"/>
  <limit lower="-3.14" upper="3.14" effort="0.01" velocity="100"/>
</joint>

 <link name="jlink1">
  <inertial>
    <mass value="1"/>
    <inertia ixx="0.0108333333333" ixy="0" ixz="0" iyy="0.0108333333333" iyz="0" izz="0.01"/>
  </inertial>
  <visual>
    <origin rpy="0 0 1.57" xyz="0 0 0"/>
    <geometry>
      <cylinder length="0.1" radius="0.2"/>
    </geometry>
  </visual>
  <collision>
    <origin rpy="0 0 1.57" xyz="0 0 0"/>
    <geometry>
      <cylinder length="0.1" radius="0.2"/>
    </geometry>
  </collision>
 </link>

<joint name="joint_fixed_link0_jlink1" type="fixed">
  <origin rpy="0 0 0" xyz="0 1.9 0"/>
  <parent link="link0"/>
  <child link="jlink1"/>
</joint>

 <link name="link1">
  <inertial>
    <mass value="1"/>
    <inertia ixx="0.0141666666667" ixy="0" ixz="0" iyy="0.200833333333" iyz="0" izz="0.188333333333"/>
  </inertial>
  <visual>
    <origin rpy="0 0 0" xyz="0 0.95 0"/>
    <geometry>
      <box size="0.4 1.5 0.1"/>
    </geometry>
  </visual>
  <collision>
    <origin rpy="0 0 0" xyz="0 0.95 0"/>
    <geometry>
      <box size="0.4 1.5 0.1"/>
    </geometry>
  </collision>
 </link>

<joint name="joint_revolute_jlink1_link1_Z" type="revolute">
  <origin rpy="0 0 0" xyz="0 0 0"/>
  <parent link="jlink1"/>
  <child link="link1"/>
  <axis xyz="0 0 1"/>
  <dynamics damping="0.01" friction="0.5"/>
  <limit lower="-3.14" upper="3.14" effort="0.01" velocity="100"/>
</joint>

 <link name="jlink2">
  <inertial>
    <mass value="1"/>
    <inertia ixx="0.0108333333333" ixy="0" ixz="0" iyy="0.0108333333333" iyz="0" izz="0.01"/>
  </inertial>
  <visual>
    <origin rpy="0 0 1.57" xyz="0 0 0"/>
    <geometry>
      <cylinder length="0.1" radius="0.2"/>
    </geometry>
  </visual>
  <collision>
    <origin rpy="0 0 1.57" xyz="0 0 0"/>
    <geometry>
      <cylinder length="0.1" radius="0.2"/>
    </geometry>
  </collision>
 </link>

<joint name="joint_fixed_link1_jlink2" type="fixed">
  <origin rpy="0 0 0" xyz="0 1.9 0"/>
  <parent link="link1"/>
  <child link="jlink2"/>
</joint>

  <klampt package_root="../../.." fixed_root_link="1" default_acc_max="4" >
  <link name = "jlink2" physical = "0" />
  </klampt>
</robot>