<?xml version="1.0"?>
<robot name="snake/snake_2_segments">
<link name="eye">
  <inertial>
   <mass value="1"/>
   <inertia ixx="0.00576" ixy="0" ixz="0" iyy="0.00576" iyz="0" izz="0.00576"/>
  </inertial>
  <collision>
    <origin rpy="0 0 0" xyz="0 0 0"/>
    <geometry>
      <sphere radius="0.12"/>
    </geometry>
  </collision>
  <visual>
    <origin rpy="0 0 0" xyz="0 0 0"/>
    <geometry>
      <sphere radius="0.12"/>
    </geometry>
  </visual>
</link>

 <link name="body0">
  <inertial>
    <mass value="1"/>
    <inertia ixx="0.0048" ixy="0" ixz="0" iyy="0.0048" iyz="0" izz="0.0036"/>
  </inertial>
  <visual>
    <origin rpy="0 1.57 0" xyz="0 0 0"/>
    <geometry>
      <cylinder length="0.12" radius="0.12"/>
    </geometry>
  </visual>
  <collision>
    <origin rpy="0 1.57 0" xyz="0 0 0"/>
    <geometry>
      <cylinder length="0.12" radius="0.12"/>
    </geometry>
  </collision>
 </link>

<joint name="joint_fixed_eye_body0" type="fixed">
  <origin rpy="0 0 0" xyz="-0.06 0 0"/>
  <parent link="eye"/>
  <child link="body0"/>
</joint>

<link name="body1_joint_link">
  <inertial>
   <mass value="1"/>
   <inertia ixx="0.00144" ixy="0" ixz="0" iyy="0.00144" iyz="0" izz="0.00144"/>
  </inertial>
  <collision>
    <origin rpy="0 0 0" xyz="0 0 0"/>
    <geometry>
      <sphere radius="0.06"/>
    </geometry>
  </collision>
  <visual>
    <origin rpy="0 0 0" xyz="0 0 0"/>
    <geometry>
      <sphere radius="0.06"/>
    </geometry>
  </visual>
</link>

<joint name="joint_fixed_body0_body1_joint_link" type="fixed">
  <origin rpy="0 0 0" xyz="-0.12001 0 0"/>
  <parent link="body0"/>
  <child link="body1_joint_link"/>
</joint>

<joint name="joint_spherical_body1_joint_link_body1_Z" type="revolute">
  <origin rpy="0 0 0" xyz="0 0 0"/>
  <parent link="body1_joint_link"/>
  <child link="body1_joint_link_spherical_joint_link"/>
  <axis xyz="0 0 1"/>
  <dynamics damping="0.01" friction="0.5"/>
  <limit lower="-0.785398163397" upper="0.785398163397" effort="0.01" velocity="100"/>
</joint>

<link name="body1_joint_link_spherical_joint_link" physical="0">
  <inertial>
   <mass value="1"/>
   <inertia ixx="4e-07" ixy="0" ixz="0" iyy="4e-07" iyz="0" izz="4e-07"/>
  </inertial>
  <collision>
    <origin rpy="0 0 0" xyz="0 0 0"/>
    <geometry>
      <sphere radius="0.001"/>
    </geometry>
  </collision>
  <visual>
    <origin rpy="0 0 0" xyz="0 0 0"/>
    <geometry>
      <sphere radius="0.001"/>
    </geometry>
  </visual>
</link>

<joint name="joint_spherical_body1_joint_link_body1_Y" type="revolute">
  <origin rpy="0 0 0" xyz="0 0 0"/>
  <parent link="body1_joint_link_spherical_joint_link"/>
  <child link="body1"/>
  <axis xyz="0 1 0"/>
  <dynamics damping="0.01" friction="0.5"/>
  <limit lower="-0.785398163397" upper="0.785398163397" effort="0.01" velocity="100"/>
</joint>

 <link name="body1">
  <inertial>
    <mass value="1"/>
    <inertia ixx="0.0111" ixy="0" ixz="0" iyy="0.0111" iyz="0" izz="0.0036"/>
  </inertial>
  <visual>
    <origin rpy="0 1.57 0" xyz="-0.21001 0 0"/>
    <geometry>
      <cylinder length="0.3" radius="0.12"/>
    </geometry>
  </visual>
  <collision>
    <origin rpy="0 1.57 0" xyz="-0.21001 0 0"/>
    <geometry>
      <cylinder length="0.3" radius="0.12"/>
    </geometry>
  </collision>
 </link>

<link name="body2_joint_link">
  <inertial>
   <mass value="1"/>
   <inertia ixx="0.00144" ixy="0" ixz="0" iyy="0.00144" iyz="0" izz="0.00144"/>
  </inertial>
  <collision>
    <origin rpy="0 0 0" xyz="0 0 0"/>
    <geometry>
      <sphere radius="0.06"/>
    </geometry>
  </collision>
  <visual>
    <origin rpy="0 0 0" xyz="0 0 0"/>
    <geometry>
      <sphere radius="0.06"/>
    </geometry>
  </visual>
</link>

<joint name="joint_fixed_body1_body2_joint_link" type="fixed">
  <origin rpy="0 0 0" xyz="-0.42001 0 0"/>
  <parent link="body1"/>
  <child link="body2_joint_link"/>
</joint>

<joint name="joint_spherical_body2_joint_link_body2_Z" type="revolute">
  <origin rpy="0 0 0" xyz="0 0 0"/>
  <parent link="body2_joint_link"/>
  <child link="body2_joint_link_spherical_joint_link"/>
  <axis xyz="0 0 1"/>
  <dynamics damping="0.01" friction="0.5"/>
  <limit lower="-0.785398163397" upper="0.785398163397" effort="0.01" velocity="100"/>
</joint>

<link name="body2_joint_link_spherical_joint_link" physical="0">
  <inertial>
   <mass value="1"/>
   <inertia ixx="4e-07" ixy="0" ixz="0" iyy="4e-07" iyz="0" izz="4e-07"/>
  </inertial>
  <collision>
    <origin rpy="0 0 0" xyz="0 0 0"/>
    <geometry>
      <sphere radius="0.001"/>
    </geometry>
  </collision>
  <visual>
    <origin rpy="0 0 0" xyz="0 0 0"/>
    <geometry>
      <sphere radius="0.001"/>
    </geometry>
  </visual>
</link>

<joint name="joint_spherical_body2_joint_link_body2_Y" type="revolute">
  <origin rpy="0 0 0" xyz="0 0 0"/>
  <parent link="body2_joint_link_spherical_joint_link"/>
  <child link="body2"/>
  <axis xyz="0 1 0"/>
  <dynamics damping="0.01" friction="0.5"/>
  <limit lower="-0.785398163397" upper="0.785398163397" effort="0.01" velocity="100"/>
</joint>

 <link name="body2">
  <inertial>
    <mass value="1"/>
    <inertia ixx="0.0111" ixy="0" ixz="0" iyy="0.0111" iyz="0" izz="0.0036"/>
  </inertial>
  <visual>
    <origin rpy="0 1.57 0" xyz="-0.21001 0 0"/>
    <geometry>
      <cylinder length="0.3" radius="0.12"/>
    </geometry>
  </visual>
  <collision>
    <origin rpy="0 1.57 0" xyz="-0.21001 0 0"/>
    <geometry>
      <cylinder length="0.3" radius="0.12"/>
    </geometry>
  </collision>
 </link>

  <klampt package_root="../../.." default_acc_max="4" >
  </klampt>
</robot>