<?xml version="1.0"?>
<robot name="snake/snake_5_segments">
<link name="eye">
  <inertial>
   <mass value="1"/>
   <inertia ixx="0.004000000000000001" ixy="0" ixz="0" iyy="0.004000000000000001" iyz="0" izz="0.004000000000000001"/>
  </inertial>
  <collision>
    <origin rpy="0 0 0" xyz="0 0 0"/>
    <geometry>
      <sphere radius="0.1"/>
    </geometry>
  </collision>
  <visual>
    <origin rpy="0 0 0" xyz="0 0 0"/>
    <geometry>
      <sphere radius="0.1"/>
    </geometry>
  </visual>
</link>

 <link name="body0">
  <inertial>
    <mass value="1"/>
    <inertia ixx="0.003333333333333334" ixy="0" ixz="0" iyy="0.003333333333333334" iyz="0" izz="0.0025000000000000005"/>
  </inertial>
  <visual>
    <origin rpy="0 1.57 0" xyz="0 0 0"/>
    <geometry>
      <cylinder length="0.1" radius="0.1"/>
    </geometry>
  </visual>
  <collision>
    <origin rpy="0 1.57 0" xyz="0 0 0"/>
    <geometry>
      <cylinder length="0.1" radius="0.1"/>
    </geometry>
  </collision>
 </link>

<joint name="joint_fixed_eye_body0" type="fixed">
  <origin rpy="0 0 0" xyz="-0.05 0 0"/>
  <parent link="eye"/>
  <child link="body0"/>
</joint>

<link name="body1_joint_link">
  <inertial>
   <mass value="1"/>
   <inertia ixx="0.0019599999999999995" ixy="0" ixz="0" iyy="0.0019599999999999995" iyz="0" izz="0.0019599999999999995"/>
  </inertial>
  <collision>
    <origin rpy="0 0 0" xyz="0 0 0"/>
    <geometry>
      <sphere radius="0.06999999999999999"/>
    </geometry>
  </collision>
  <visual>
    <origin rpy="0 0 0" xyz="0 0 0"/>
    <geometry>
      <sphere radius="0.06999999999999999"/>
    </geometry>
  </visual>
</link>

<joint name="joint_fixed_body0_body1_joint_link" type="fixed">
  <origin rpy="0 0 0" xyz="-0.12000999999999999 0 0"/>
  <parent link="body0"/>
  <child link="body1_joint_link"/>
</joint>

<joint name="joint_spherical_body1_joint_link_body1_Z" type="revolute">
  <origin rpy="0 0 0" xyz="0 0 0"/>
  <parent link="body1_joint_link"/>
  <child link="body1_joint_link_spherical_joint_link"/>
  <axis xyz="0 0 1"/>
  <dynamics damping="0.01" friction="0.5"/>
  <limit lower="-1.1780972450961724" upper="1.1780972450961724" effort="0.01" velocity="100"/>
</joint>

<link name="body1_joint_link_spherical_joint_link" physical="0">
  <inertial>
   <mass value="1"/>
   <inertia ixx="4.0000000000000003e-07" ixy="0" ixz="0" iyy="4.0000000000000003e-07" iyz="0" izz="4.0000000000000003e-07"/>
  </inertial>
  <collision>
    <origin rpy="0 0 0" xyz="0 0 0"/>
    <geometry>
      <sphere radius="0.001"/>
    </geometry>
  </collision>
  <visual>
    <origin rpy="0 0 0" xyz="0 0 0"/>
    <geometry>
      <sphere radius="0.001"/>
    </geometry>
  </visual>
</link>

<joint name="joint_spherical_body1_joint_link_body1_Y" type="revolute">
  <origin rpy="0 0 0" xyz="0 0 0"/>
  <parent link="body1_joint_link_spherical_joint_link"/>
  <child link="body1"/>
  <axis xyz="0 1 0"/>
  <dynamics damping="0.01" friction="0.5"/>
  <limit lower="-1.1780972450961724" upper="1.1780972450961724" effort="0.01" velocity="100"/>
</joint>

 <link name="body1">
  <inertial>
    <mass value="1"/>
    <inertia ixx="0.010000000000000002" ixy="0" ixz="0" iyy="0.010000000000000002" iyz="0" izz="0.0025000000000000005"/>
  </inertial>
  <visual>
    <origin rpy="0 1.57 0" xyz="-0.22001000000000004 0 0"/>
    <geometry>
      <cylinder length="0.30000000000000004" radius="0.1"/>
    </geometry>
  </visual>
  <collision>
    <origin rpy="0 1.57 0" xyz="-0.22001000000000004 0 0"/>
    <geometry>
      <cylinder length="0.30000000000000004" radius="0.1"/>
    </geometry>
  </collision>
 </link>

<link name="body2_joint_link">
  <inertial>
   <mass value="1"/>
   <inertia ixx="0.0019599999999999995" ixy="0" ixz="0" iyy="0.0019599999999999995" iyz="0" izz="0.0019599999999999995"/>
  </inertial>
  <collision>
    <origin rpy="0 0 0" xyz="0 0 0"/>
    <geometry>
      <sphere radius="0.06999999999999999"/>
    </geometry>
  </collision>
  <visual>
    <origin rpy="0 0 0" xyz="0 0 0"/>
    <geometry>
      <sphere radius="0.06999999999999999"/>
    </geometry>
  </visual>
</link>

<joint name="joint_fixed_body1_body2_joint_link" type="fixed">
  <origin rpy="0 0 0" xyz="-0.44001000000000007 0 0"/>
  <parent link="body1"/>
  <child link="body2_joint_link"/>
</joint>

<joint name="joint_spherical_body2_joint_link_body2_Z" type="revolute">
  <origin rpy="0 0 0" xyz="0 0 0"/>
  <parent link="body2_joint_link"/>
  <child link="body2_joint_link_spherical_joint_link"/>
  <axis xyz="0 0 1"/>
  <dynamics damping="0.01" friction="0.5"/>
  <limit lower="-1.1780972450961724" upper="1.1780972450961724" effort="0.01" velocity="100"/>
</joint>

<link name="body2_joint_link_spherical_joint_link" physical="0">
  <inertial>
   <mass value="1"/>
   <inertia ixx="4.0000000000000003e-07" ixy="0" ixz="0" iyy="4.0000000000000003e-07" iyz="0" izz="4.0000000000000003e-07"/>
  </inertial>
  <collision>
    <origin rpy="0 0 0" xyz="0 0 0"/>
    <geometry>
      <sphere radius="0.001"/>
    </geometry>
  </collision>
  <visual>
    <origin rpy="0 0 0" xyz="0 0 0"/>
    <geometry>
      <sphere radius="0.001"/>
    </geometry>
  </visual>
</link>

<joint name="joint_spherical_body2_joint_link_body2_Y" type="revolute">
  <origin rpy="0 0 0" xyz="0 0 0"/>
  <parent link="body2_joint_link_spherical_joint_link"/>
  <child link="body2"/>
  <axis xyz="0 1 0"/>
  <dynamics damping="0.01" friction="0.5"/>
  <limit lower="-1.1780972450961724" upper="1.1780972450961724" effort="0.01" velocity="100"/>
</joint>

 <link name="body2">
  <inertial>
    <mass value="1"/>
    <inertia ixx="0.010000000000000002" ixy="0" ixz="0" iyy="0.010000000000000002" iyz="0" izz="0.0025000000000000005"/>
  </inertial>
  <visual>
    <origin rpy="0 1.57 0" xyz="-0.22001000000000004 0 0"/>
    <geometry>
      <cylinder length="0.30000000000000004" radius="0.1"/>
    </geometry>
  </visual>
  <collision>
    <origin rpy="0 1.57 0" xyz="-0.22001000000000004 0 0"/>
    <geometry>
      <cylinder length="0.30000000000000004" radius="0.1"/>
    </geometry>
  </collision>
 </link>

<link name="body3_joint_link">
  <inertial>
   <mass value="1"/>
   <inertia ixx="0.0019599999999999995" ixy="0" ixz="0" iyy="0.0019599999999999995" iyz="0" izz="0.0019599999999999995"/>
  </inertial>
  <collision>
    <origin rpy="0 0 0" xyz="0 0 0"/>
    <geometry>
      <sphere radius="0.06999999999999999"/>
    </geometry>
  </collision>
  <visual>
    <origin rpy="0 0 0" xyz="0 0 0"/>
    <geometry>
      <sphere radius="0.06999999999999999"/>
    </geometry>
  </visual>
</link>

<joint name="joint_fixed_body2_body3_joint_link" type="fixed">
  <origin rpy="0 0 0" xyz="-0.44001000000000007 0 0"/>
  <parent link="body2"/>
  <child link="body3_joint_link"/>
</joint>

<joint name="joint_spherical_body3_joint_link_body3_Z" type="revolute">
  <origin rpy="0 0 0" xyz="0 0 0"/>
  <parent link="body3_joint_link"/>
  <child link="body3_joint_link_spherical_joint_link"/>
  <axis xyz="0 0 1"/>
  <dynamics damping="0.01" friction="0.5"/>
  <limit lower="-1.1780972450961724" upper="1.1780972450961724" effort="0.01" velocity="100"/>
</joint>

<link name="body3_joint_link_spherical_joint_link" physical="0">
  <inertial>
   <mass value="1"/>
   <inertia ixx="4.0000000000000003e-07" ixy="0" ixz="0" iyy="4.0000000000000003e-07" iyz="0" izz="4.0000000000000003e-07"/>
  </inertial>
  <collision>
    <origin rpy="0 0 0" xyz="0 0 0"/>
    <geometry>
      <sphere radius="0.001"/>
    </geometry>
  </collision>
  <visual>
    <origin rpy="0 0 0" xyz="0 0 0"/>
    <geometry>
      <sphere radius="0.001"/>
    </geometry>
  </visual>
</link>

<joint name="joint_spherical_body3_joint_link_body3_Y" type="revolute">
  <origin rpy="0 0 0" xyz="0 0 0"/>
  <parent link="body3_joint_link_spherical_joint_link"/>
  <child link="body3"/>
  <axis xyz="0 1 0"/>
  <dynamics damping="0.01" friction="0.5"/>
  <limit lower="-1.1780972450961724" upper="1.1780972450961724" effort="0.01" velocity="100"/>
</joint>

 <link name="body3">
  <inertial>
    <mass value="1"/>
    <inertia ixx="0.010000000000000002" ixy="0" ixz="0" iyy="0.010000000000000002" iyz="0" izz="0.0025000000000000005"/>
  </inertial>
  <visual>
    <origin rpy="0 1.57 0" xyz="-0.22001000000000004 0 0"/>
    <geometry>
      <cylinder length="0.30000000000000004" radius="0.1"/>
    </geometry>
  </visual>
  <collision>
    <origin rpy="0 1.57 0" xyz="-0.22001000000000004 0 0"/>
    <geometry>
      <cylinder length="0.30000000000000004" radius="0.1"/>
    </geometry>
  </collision>
 </link>

<link name="body4_joint_link">
  <inertial>
   <mass value="1"/>
   <inertia ixx="0.0019599999999999995" ixy="0" ixz="0" iyy="0.0019599999999999995" iyz="0" izz="0.0019599999999999995"/>
  </inertial>
  <collision>
    <origin rpy="0 0 0" xyz="0 0 0"/>
    <geometry>
      <sphere radius="0.06999999999999999"/>
    </geometry>
  </collision>
  <visual>
    <origin rpy="0 0 0" xyz="0 0 0"/>
    <geometry>
      <sphere radius="0.06999999999999999"/>
    </geometry>
  </visual>
</link>

<joint name="joint_fixed_body3_body4_joint_link" type="fixed">
  <origin rpy="0 0 0" xyz="-0.44001000000000007 0 0"/>
  <parent link="body3"/>
  <child link="body4_joint_link"/>
</joint>

<joint name="joint_spherical_body4_joint_link_body4_Z" type="revolute">
  <origin rpy="0 0 0" xyz="0 0 0"/>
  <parent link="body4_joint_link"/>
  <child link="body4_joint_link_spherical_joint_link"/>
  <axis xyz="0 0 1"/>
  <dynamics damping="0.01" friction="0.5"/>
  <limit lower="-1.1780972450961724" upper="1.1780972450961724" effort="0.01" velocity="100"/>
</joint>

<link name="body4_joint_link_spherical_joint_link" physical="0">
  <inertial>
   <mass value="1"/>
   <inertia ixx="4.0000000000000003e-07" ixy="0" ixz="0" iyy="4.0000000000000003e-07" iyz="0" izz="4.0000000000000003e-07"/>
  </inertial>
  <collision>
    <origin rpy="0 0 0" xyz="0 0 0"/>
    <geometry>
      <sphere radius="0.001"/>
    </geometry>
  </collision>
  <visual>
    <origin rpy="0 0 0" xyz="0 0 0"/>
    <geometry>
      <sphere radius="0.001"/>
    </geometry>
  </visual>
</link>

<joint name="joint_spherical_body4_joint_link_body4_Y" type="revolute">
  <origin rpy="0 0 0" xyz="0 0 0"/>
  <parent link="body4_joint_link_spherical_joint_link"/>
  <child link="body4"/>
  <axis xyz="0 1 0"/>
  <dynamics damping="0.01" friction="0.5"/>
  <limit lower="-1.1780972450961724" upper="1.1780972450961724" effort="0.01" velocity="100"/>
</joint>

 <link name="body4">
  <inertial>
    <mass value="1"/>
    <inertia ixx="0.010000000000000002" ixy="0" ixz="0" iyy="0.010000000000000002" iyz="0" izz="0.0025000000000000005"/>
  </inertial>
  <visual>
    <origin rpy="0 1.57 0" xyz="-0.22001000000000004 0 0"/>
    <geometry>
      <cylinder length="0.30000000000000004" radius="0.1"/>
    </geometry>
  </visual>
  <collision>
    <origin rpy="0 1.57 0" xyz="-0.22001000000000004 0 0"/>
    <geometry>
      <cylinder length="0.30000000000000004" radius="0.1"/>
    </geometry>
  </collision>
 </link>

<link name="body5_joint_link">
  <inertial>
   <mass value="1"/>
   <inertia ixx="0.0019599999999999995" ixy="0" ixz="0" iyy="0.0019599999999999995" iyz="0" izz="0.0019599999999999995"/>
  </inertial>
  <collision>
    <origin rpy="0 0 0" xyz="0 0 0"/>
    <geometry>
      <sphere radius="0.06999999999999999"/>
    </geometry>
  </collision>
  <visual>
    <origin rpy="0 0 0" xyz="0 0 0"/>
    <geometry>
      <sphere radius="0.06999999999999999"/>
    </geometry>
  </visual>
</link>

<joint name="joint_fixed_body4_body5_joint_link" type="fixed">
  <origin rpy="0 0 0" xyz="-0.44001000000000007 0 0"/>
  <parent link="body4"/>
  <child link="body5_joint_link"/>
</joint>

<joint name="joint_spherical_body5_joint_link_body5_Z" type="revolute">
  <origin rpy="0 0 0" xyz="0 0 0"/>
  <parent link="body5_joint_link"/>
  <child link="body5_joint_link_spherical_joint_link"/>
  <axis xyz="0 0 1"/>
  <dynamics damping="0.01" friction="0.5"/>
  <limit lower="-1.1780972450961724" upper="1.1780972450961724" effort="0.01" velocity="100"/>
</joint>

<link name="body5_joint_link_spherical_joint_link" physical="0">
  <inertial>
   <mass value="1"/>
   <inertia ixx="4.0000000000000003e-07" ixy="0" ixz="0" iyy="4.0000000000000003e-07" iyz="0" izz="4.0000000000000003e-07"/>
  </inertial>
  <collision>
    <origin rpy="0 0 0" xyz="0 0 0"/>
    <geometry>
      <sphere radius="0.001"/>
    </geometry>
  </collision>
  <visual>
    <origin rpy="0 0 0" xyz="0 0 0"/>
    <geometry>
      <sphere radius="0.001"/>
    </geometry>
  </visual>
</link>

<joint name="joint_spherical_body5_joint_link_body5_Y" type="revolute">
  <origin rpy="0 0 0" xyz="0 0 0"/>
  <parent link="body5_joint_link_spherical_joint_link"/>
  <child link="body5"/>
  <axis xyz="0 1 0"/>
  <dynamics damping="0.01" friction="0.5"/>
  <limit lower="-1.1780972450961724" upper="1.1780972450961724" effort="0.01" velocity="100"/>
</joint>

 <link name="body5">
  <inertial>
    <mass value="1"/>
    <inertia ixx="0.010000000000000002" ixy="0" ixz="0" iyy="0.010000000000000002" iyz="0" izz="0.0025000000000000005"/>
  </inertial>
  <visual>
    <origin rpy="0 1.57 0" xyz="-0.22001000000000004 0 0"/>
    <geometry>
      <cylinder length="0.30000000000000004" radius="0.1"/>
    </geometry>
  </visual>
  <collision>
    <origin rpy="0 1.57 0" xyz="-0.22001000000000004 0 0"/>
    <geometry>
      <cylinder length="0.30000000000000004" radius="0.1"/>
    </geometry>
  </collision>
 </link>

  <klampt package_root="../../.." default_acc_max="4" >
  </klampt>
</robot>