<?xml version="1.0"?>
<robot name="cable/cable_4_segments">
 <link name="body0">
  <inertial>
    <mass value="1"/>
    <inertia ixx="0.0010583333333333334" ixy="0" ixz="0" iyy="0.0010583333333333334" iyz="0" izz="0.000225"/>
  </inertial>
  <visual>
    <origin rpy="0 1.57 0" xyz="0 0 0"/>
    <geometry>
      <cylinder length="0.1" radius="0.03"/>
    </geometry>
  </visual>
  <collision>
    <origin rpy="0 1.57 0" xyz="0 0 0"/>
    <geometry>
      <cylinder length="0.1" radius="0.03"/>
    </geometry>
  </collision>
 </link>

<link name="body1_joint_link">
  <inertial>
   <mass value="1"/>
   <inertia ixx="0.00035999999999999997" ixy="0" ixz="0" iyy="0.00035999999999999997" iyz="0" izz="0.00035999999999999997"/>
  </inertial>
  <collision>
    <origin rpy="0 0 0" xyz="0 0 0"/>
    <geometry>
      <sphere radius="0.03"/>
    </geometry>
  </collision>
  <visual>
    <origin rpy="0 0 0" xyz="0 0 0"/>
    <geometry>
      <sphere radius="0.03"/>
    </geometry>
  </visual>
</link>

<joint name="joint_fixed_body0_body1_joint_link" type="fixed">
  <origin rpy="0 0 0" xyz="-0.08001 0 0"/>
  <parent link="body0"/>
  <child link="body1_joint_link"/>
</joint>

<joint name="joint_spherical_body1_joint_link_body1_Z" type="revolute">
  <origin rpy="0 0 0" xyz="0 0 0"/>
  <parent link="body1_joint_link"/>
  <child link="body1_joint_link_spherical_joint_link"/>
  <axis xyz="0 0 1"/>
  <dynamics damping="0.01" friction="0.5"/>
  <limit lower="-1.5707963267948966" upper="1.5707963267948966" effort="0.01" velocity="100"/>
</joint>

<link name="body1_joint_link_spherical_joint_link" physical="0">
  <inertial>
   <mass value="1"/>
   <inertia ixx="4.0000000000000003e-07" ixy="0" ixz="0" iyy="4.0000000000000003e-07" iyz="0" izz="4.0000000000000003e-07"/>
  </inertial>
  <collision>
    <origin rpy="0 0 0" xyz="0 0 0"/>
    <geometry>
      <sphere radius="0.001"/>
    </geometry>
  </collision>
  <visual>
    <origin rpy="0 0 0" xyz="0 0 0"/>
    <geometry>
      <sphere radius="0.001"/>
    </geometry>
  </visual>
</link>

<joint name="joint_spherical_body1_joint_link_body1_Y" type="revolute">
  <origin rpy="0 0 0" xyz="0 0 0"/>
  <parent link="body1_joint_link_spherical_joint_link"/>
  <child link="body1"/>
  <axis xyz="0 1 0"/>
  <dynamics damping="0.01" friction="0.5"/>
  <limit lower="-1.5707963267948966" upper="1.5707963267948966" effort="0.01" velocity="100"/>
</joint>

 <link name="body1">
  <inertial>
    <mass value="1"/>
    <inertia ixx="0.0010583333333333334" ixy="0" ixz="0" iyy="0.0010583333333333334" iyz="0" izz="0.000225"/>
  </inertial>
  <visual>
    <origin rpy="0 1.57 0" xyz="-0.08001 0 0"/>
    <geometry>
      <cylinder length="0.1" radius="0.03"/>
    </geometry>
  </visual>
  <collision>
    <origin rpy="0 1.57 0" xyz="-0.08001 0 0"/>
    <geometry>
      <cylinder length="0.1" radius="0.03"/>
    </geometry>
  </collision>
 </link>

<link name="body2_joint_link">
  <inertial>
   <mass value="1"/>
   <inertia ixx="0.00035999999999999997" ixy="0" ixz="0" iyy="0.00035999999999999997" iyz="0" izz="0.00035999999999999997"/>
  </inertial>
  <collision>
    <origin rpy="0 0 0" xyz="0 0 0"/>
    <geometry>
      <sphere radius="0.03"/>
    </geometry>
  </collision>
  <visual>
    <origin rpy="0 0 0" xyz="0 0 0"/>
    <geometry>
      <sphere radius="0.03"/>
    </geometry>
  </visual>
</link>

<joint name="joint_fixed_body1_body2_joint_link" type="fixed">
  <origin rpy="0 0 0" xyz="-0.16001 0 0"/>
  <parent link="body1"/>
  <child link="body2_joint_link"/>
</joint>

<joint name="joint_spherical_body2_joint_link_body2_Z" type="revolute">
  <origin rpy="0 0 0" xyz="0 0 0"/>
  <parent link="body2_joint_link"/>
  <child link="body2_joint_link_spherical_joint_link"/>
  <axis xyz="0 0 1"/>
  <dynamics damping="0.01" friction="0.5"/>
  <limit lower="-1.5707963267948966" upper="1.5707963267948966" effort="0.01" velocity="100"/>
</joint>

<link name="body2_joint_link_spherical_joint_link" physical="0">
  <inertial>
   <mass value="1"/>
   <inertia ixx="4.0000000000000003e-07" ixy="0" ixz="0" iyy="4.0000000000000003e-07" iyz="0" izz="4.0000000000000003e-07"/>
  </inertial>
  <collision>
    <origin rpy="0 0 0" xyz="0 0 0"/>
    <geometry>
      <sphere radius="0.001"/>
    </geometry>
  </collision>
  <visual>
    <origin rpy="0 0 0" xyz="0 0 0"/>
    <geometry>
      <sphere radius="0.001"/>
    </geometry>
  </visual>
</link>

<joint name="joint_spherical_body2_joint_link_body2_Y" type="revolute">
  <origin rpy="0 0 0" xyz="0 0 0"/>
  <parent link="body2_joint_link_spherical_joint_link"/>
  <child link="body2"/>
  <axis xyz="0 1 0"/>
  <dynamics damping="0.01" friction="0.5"/>
  <limit lower="-1.5707963267948966" upper="1.5707963267948966" effort="0.01" velocity="100"/>
</joint>

 <link name="body2">
  <inertial>
    <mass value="1"/>
    <inertia ixx="0.0010583333333333334" ixy="0" ixz="0" iyy="0.0010583333333333334" iyz="0" izz="0.000225"/>
  </inertial>
  <visual>
    <origin rpy="0 1.57 0" xyz="-0.08001 0 0"/>
    <geometry>
      <cylinder length="0.1" radius="0.03"/>
    </geometry>
  </visual>
  <collision>
    <origin rpy="0 1.57 0" xyz="-0.08001 0 0"/>
    <geometry>
      <cylinder length="0.1" radius="0.03"/>
    </geometry>
  </collision>
 </link>

<link name="body3_joint_link">
  <inertial>
   <mass value="1"/>
   <inertia ixx="0.00035999999999999997" ixy="0" ixz="0" iyy="0.00035999999999999997" iyz="0" izz="0.00035999999999999997"/>
  </inertial>
  <collision>
    <origin rpy="0 0 0" xyz="0 0 0"/>
    <geometry>
      <sphere radius="0.03"/>
    </geometry>
  </collision>
  <visual>
    <origin rpy="0 0 0" xyz="0 0 0"/>
    <geometry>
      <sphere radius="0.03"/>
    </geometry>
  </visual>
</link>

<joint name="joint_fixed_body2_body3_joint_link" type="fixed">
  <origin rpy="0 0 0" xyz="-0.16001 0 0"/>
  <parent link="body2"/>
  <child link="body3_joint_link"/>
</joint>

<joint name="joint_spherical_body3_joint_link_body3_Z" type="revolute">
  <origin rpy="0 0 0" xyz="0 0 0"/>
  <parent link="body3_joint_link"/>
  <child link="body3_joint_link_spherical_joint_link"/>
  <axis xyz="0 0 1"/>
  <dynamics damping="0.01" friction="0.5"/>
  <limit lower="-1.5707963267948966" upper="1.5707963267948966" effort="0.01" velocity="100"/>
</joint>

<link name="body3_joint_link_spherical_joint_link" physical="0">
  <inertial>
   <mass value="1"/>
   <inertia ixx="4.0000000000000003e-07" ixy="0" ixz="0" iyy="4.0000000000000003e-07" iyz="0" izz="4.0000000000000003e-07"/>
  </inertial>
  <collision>
    <origin rpy="0 0 0" xyz="0 0 0"/>
    <geometry>
      <sphere radius="0.001"/>
    </geometry>
  </collision>
  <visual>
    <origin rpy="0 0 0" xyz="0 0 0"/>
    <geometry>
      <sphere radius="0.001"/>
    </geometry>
  </visual>
</link>

<joint name="joint_spherical_body3_joint_link_body3_Y" type="revolute">
  <origin rpy="0 0 0" xyz="0 0 0"/>
  <parent link="body3_joint_link_spherical_joint_link"/>
  <child link="body3"/>
  <axis xyz="0 1 0"/>
  <dynamics damping="0.01" friction="0.5"/>
  <limit lower="-1.5707963267948966" upper="1.5707963267948966" effort="0.01" velocity="100"/>
</joint>

 <link name="body3">
  <inertial>
    <mass value="1"/>
    <inertia ixx="0.0010583333333333334" ixy="0" ixz="0" iyy="0.0010583333333333334" iyz="0" izz="0.000225"/>
  </inertial>
  <visual>
    <origin rpy="0 1.57 0" xyz="-0.08001 0 0"/>
    <geometry>
      <cylinder length="0.1" radius="0.03"/>
    </geometry>
  </visual>
  <collision>
    <origin rpy="0 1.57 0" xyz="-0.08001 0 0"/>
    <geometry>
      <cylinder length="0.1" radius="0.03"/>
    </geometry>
  </collision>
 </link>

<link name="body4_joint_link">
  <inertial>
   <mass value="1"/>
   <inertia ixx="0.00035999999999999997" ixy="0" ixz="0" iyy="0.00035999999999999997" iyz="0" izz="0.00035999999999999997"/>
  </inertial>
  <collision>
    <origin rpy="0 0 0" xyz="0 0 0"/>
    <geometry>
      <sphere radius="0.03"/>
    </geometry>
  </collision>
  <visual>
    <origin rpy="0 0 0" xyz="0 0 0"/>
    <geometry>
      <sphere radius="0.03"/>
    </geometry>
  </visual>
</link>

<joint name="joint_fixed_body3_body4_joint_link" type="fixed">
  <origin rpy="0 0 0" xyz="-0.16001 0 0"/>
  <parent link="body3"/>
  <child link="body4_joint_link"/>
</joint>

<joint name="joint_spherical_body4_joint_link_body4_Z" type="revolute">
  <origin rpy="0 0 0" xyz="0 0 0"/>
  <parent link="body4_joint_link"/>
  <child link="body4_joint_link_spherical_joint_link"/>
  <axis xyz="0 0 1"/>
  <dynamics damping="0.01" friction="0.5"/>
  <limit lower="-1.5707963267948966" upper="1.5707963267948966" effort="0.01" velocity="100"/>
</joint>

<link name="body4_joint_link_spherical_joint_link" physical="0">
  <inertial>
   <mass value="1"/>
   <inertia ixx="4.0000000000000003e-07" ixy="0" ixz="0" iyy="4.0000000000000003e-07" iyz="0" izz="4.0000000000000003e-07"/>
  </inertial>
  <collision>
    <origin rpy="0 0 0" xyz="0 0 0"/>
    <geometry>
      <sphere radius="0.001"/>
    </geometry>
  </collision>
  <visual>
    <origin rpy="0 0 0" xyz="0 0 0"/>
    <geometry>
      <sphere radius="0.001"/>
    </geometry>
  </visual>
</link>

<joint name="joint_spherical_body4_joint_link_body4_Y" type="revolute">
  <origin rpy="0 0 0" xyz="0 0 0"/>
  <parent link="body4_joint_link_spherical_joint_link"/>
  <child link="body4"/>
  <axis xyz="0 1 0"/>
  <dynamics damping="0.01" friction="0.5"/>
  <limit lower="-1.5707963267948966" upper="1.5707963267948966" effort="0.01" velocity="100"/>
</joint>

 <link name="body4">
  <inertial>
    <mass value="1"/>
    <inertia ixx="0.0010583333333333334" ixy="0" ixz="0" iyy="0.0010583333333333334" iyz="0" izz="0.000225"/>
  </inertial>
  <visual>
    <origin rpy="0 1.57 0" xyz="-0.08001 0 0"/>
    <geometry>
      <cylinder length="0.1" radius="0.03"/>
    </geometry>
  </visual>
  <collision>
    <origin rpy="0 1.57 0" xyz="-0.08001 0 0"/>
    <geometry>
      <cylinder length="0.1" radius="0.03"/>
    </geometry>
  </collision>
 </link>

  <klampt package_root="../../.." default_acc_max="4" >
  </klampt>
</robot>