<?xml version="1.0"?>
<robot name="sentinel/octopus_1_arms_2_segments">
<link name="eye">
  <inertial>
   <mass value="1"/>
   <inertia ixx="0.004000000000000001" ixy="0" ixz="0" iyy="0.004000000000000001" iyz="0" izz="0.004000000000000001"/>
  </inertial>
  <collision>
    <origin rpy="0 0 0" xyz="0 0 0"/>
    <geometry>
      <sphere radius="0.1"/>
    </geometry>
  </collision>
  <visual>
    <origin rpy="0 0 0" xyz="0 0 0"/>
    <geometry>
      <sphere radius="0.1"/>
    </geometry>
  </visual>
</link>

 <link name="head">
  <inertial>
    <mass value="1"/>
    <inertia ixx="0.0058333333333333345" ixy="0" ixz="0" iyy="0.0058333333333333345" iyz="0" izz="0.0025000000000000005"/>
  </inertial>
  <visual>
    <origin rpy="0 1.57 0" xyz="-0.1 0 0"/>
    <geometry>
      <cylinder length="0.2" radius="0.1"/>
    </geometry>
  </visual>
  <collision>
    <origin rpy="0 1.57 0" xyz="-0.1 0 0"/>
    <geometry>
      <cylinder length="0.2" radius="0.1"/>
    </geometry>
  </collision>
 </link>

<joint name="joint_fixed_eye_head" type="fixed">
  <origin rpy="0 0 0" xyz="0 0 0"/>
  <parent link="eye"/>
  <child link="head"/>
</joint>

<!--############################################################################
branch_00
##############################################################################-->
 <link name="branch_00_cylinder_stub">
  <inertial>
    <mass value="1"/>
    <inertia ixx="0.0005687499999999999" ixy="0" ixz="0" iyy="0.0005687499999999999" iyz="0" izz="0.0001"/>
  </inertial>
  <visual>
    <origin rpy="0 1.57 0" xyz="-0.0375 0 0"/>
    <geometry>
      <cylinder length="0.075" radius="0.02"/>
    </geometry>
  </visual>
  <collision>
    <origin rpy="0 1.57 0" xyz="-0.0375 0 0"/>
    <geometry>
      <cylinder length="0.075" radius="0.02"/>
    </geometry>
  </collision>
 </link>

<joint name="joint_fixed_head_branch_00_cylinder_stub" type="fixed">
  <origin rpy="0 0 0" xyz="-0.2 0.06999999999999999 0.0"/>
  <parent link="head"/>
  <child link="branch_00_cylinder_stub"/>
</joint>

<link name="branch_00_sphere_stub">
  <inertial>
   <mass value="1"/>
   <inertia ixx="0.00014439999999999999" ixy="0" ixz="0" iyy="0.00014439999999999999" iyz="0" izz="0.00014439999999999999"/>
  </inertial>
  <collision>
    <origin rpy="0 0 0" xyz="-0.095 0 0"/>
    <geometry>
      <sphere radius="0.019"/>
    </geometry>
  </collision>
  <visual>
    <origin rpy="0 0 0" xyz="-0.095 0 0"/>
    <geometry>
      <sphere radius="0.019"/>
    </geometry>
  </visual>
</link>

<joint name="joint_fixed_branch_00_cylinder_stub_branch_00_sphere_stub" type="fixed">
  <origin rpy="0 0 0" xyz="0 0 0"/>
  <parent link="branch_00_cylinder_stub"/>
  <child link="branch_00_sphere_stub"/>
</joint>

 <link name="branch_00_cylinder">
  <inertial>
    <mass value="1"/>
    <inertia ixx="0.0019749999999999998" ixy="0" ixz="0" iyy="0.0019749999999999998" iyz="0" izz="0.0001"/>
  </inertial>
  <visual>
    <origin rpy="0 1.5707963267948966 1.57" xyz="-0.095 0.095 0.0"/>
    <geometry>
      <cylinder length="0.15" radius="0.02"/>
    </geometry>
  </visual>
  <collision>
    <origin rpy="0 1.5707963267948966 1.57" xyz="-0.095 0.095 0.0"/>
    <geometry>
      <cylinder length="0.15" radius="0.02"/>
    </geometry>
  </collision>
 </link>

<joint name="joint_fixed_branch_00_sphere_stub_branch_00_cylinder" type="fixed">
  <origin rpy="0 0 0" xyz="0 0 0"/>
  <parent link="branch_00_sphere_stub"/>
  <child link="branch_00_cylinder"/>
</joint>

<link name="branch_00">
  <inertial>
   <mass value="1"/>
   <inertia ixx="0.00014439999999999999" ixy="0" ixz="0" iyy="0.00014439999999999999" iyz="0" izz="0.00014439999999999999"/>
  </inertial>
  <collision>
    <origin rpy="0 0 0" xyz="0 0 0"/>
    <geometry>
      <sphere radius="0.019"/>
    </geometry>
  </collision>
  <visual>
    <origin rpy="0 0 0" xyz="0 0 0"/>
    <geometry>
      <sphere radius="0.019"/>
    </geometry>
  </visual>
</link>

<joint name="joint_fixed_branch_00_cylinder_branch_00" type="fixed">
  <origin rpy="0 0 0" xyz="-0.095 0.19 0.0"/>
  <parent link="branch_00_cylinder"/>
  <child link="branch_00"/>
</joint>

<!--############################################################################
branch_01
##############################################################################-->
 <link name="branch_01_cylinder">
  <inertial>
    <mass value="1"/>
    <inertia ixx="0.0019749999999999998" ixy="0" ixz="0" iyy="0.0019749999999999998" iyz="0" izz="0.0001"/>
  </inertial>
  <visual>
    <origin rpy="0 1.57 0" xyz="-0.095 0 0"/>
    <geometry>
      <cylinder length="0.15" radius="0.02"/>
    </geometry>
  </visual>
  <collision>
    <origin rpy="0 1.57 0" xyz="-0.095 0 0"/>
    <geometry>
      <cylinder length="0.15" radius="0.02"/>
    </geometry>
  </collision>
 </link>

<joint name="joint_revolute_branch_00_branch_01_cylinder_Z" type="revolute">
  <origin rpy="0 0 0" xyz="0 0 0"/>
  <parent link="branch_00"/>
  <child link="branch_01_cylinder"/>
  <axis xyz="0 0.0 -1.0"/>
  <dynamics damping="0.01" friction="0.5"/>
  <limit lower="-1.5707963267948966" upper="1.5707963267948966" effort="0.01" velocity="100"/>
</joint>

<link name="branch_01">
  <inertial>
   <mass value="1"/>
   <inertia ixx="0.00014439999999999999" ixy="0" ixz="0" iyy="0.00014439999999999999" iyz="0" izz="0.00014439999999999999"/>
  </inertial>
  <collision>
    <origin rpy="0 0 0" xyz="0 0 0"/>
    <geometry>
      <sphere radius="0.019"/>
    </geometry>
  </collision>
  <visual>
    <origin rpy="0 0 0" xyz="0 0 0"/>
    <geometry>
      <sphere radius="0.019"/>
    </geometry>
  </visual>
</link>

<joint name="joint_fixed_branch_01_cylinder_branch_01" type="fixed">
  <origin rpy="0 0 0" xyz="-0.19 0 0"/>
  <parent link="branch_01_cylinder"/>
  <child link="branch_01"/>
</joint>

<!--############################################################################
branch_02
##############################################################################-->
 <link name="branch_02_cylinder">
  <inertial>
    <mass value="1"/>
    <inertia ixx="0.0019749999999999998" ixy="0" ixz="0" iyy="0.0019749999999999998" iyz="0" izz="0.0001"/>
  </inertial>
  <visual>
    <origin rpy="0 1.57 0" xyz="-0.095 0 0"/>
    <geometry>
      <cylinder length="0.15" radius="0.02"/>
    </geometry>
  </visual>
  <collision>
    <origin rpy="0 1.57 0" xyz="-0.095 0 0"/>
    <geometry>
      <cylinder length="0.15" radius="0.02"/>
    </geometry>
  </collision>
 </link>

<joint name="joint_revolute_branch_01_branch_02_cylinder_Z" type="revolute">
  <origin rpy="0 0 0" xyz="0 0 0"/>
  <parent link="branch_01"/>
  <child link="branch_02_cylinder"/>
  <axis xyz="0 0.0 -1.0"/>
  <dynamics damping="0.01" friction="0.5"/>
  <limit lower="-1.5707963267948966" upper="1.5707963267948966" effort="0.01" velocity="100"/>
</joint>

<link name="branch_02">
  <inertial>
   <mass value="1"/>
   <inertia ixx="0.00014439999999999999" ixy="0" ixz="0" iyy="0.00014439999999999999" iyz="0" izz="0.00014439999999999999"/>
  </inertial>
  <collision>
    <origin rpy="0 0 0" xyz="0 0 0"/>
    <geometry>
      <sphere radius="0.019"/>
    </geometry>
  </collision>
  <visual>
    <origin rpy="0 0 0" xyz="0 0 0"/>
    <geometry>
      <sphere radius="0.019"/>
    </geometry>
  </visual>
</link>

<joint name="joint_fixed_branch_02_cylinder_branch_02" type="fixed">
  <origin rpy="0 0 0" xyz="-0.19 0 0"/>
  <parent link="branch_02_cylinder"/>
  <child link="branch_02"/>
</joint>

  <klampt package_root="../../.." default_acc_max="4" >
  </klampt>
</robot>