<?xml version="1.0"?>
<robot name="sentinel/octopus_2_arms_4_segments">
<link name="eye">
  <inertial>
   <mass value="1"/>
   <inertia ixx="0.004000000000000001" ixy="0" ixz="0" iyy="0.004000000000000001" iyz="0" izz="0.004000000000000001"/>
  </inertial>
  <collision>
    <origin rpy="0 0 0" xyz="0 0 0"/>
    <geometry>
      <sphere radius="0.1"/>
    </geometry>
  </collision>
  <visual>
    <origin rpy="0 0 0" xyz="0 0 0"/>
    <geometry>
      <sphere radius="0.1"/>
    </geometry>
  </visual>
</link>

 <link name="head">
  <inertial>
    <mass value="1"/>
    <inertia ixx="0.0058333333333333345" ixy="0" ixz="0" iyy="0.0058333333333333345" iyz="0" izz="0.0025000000000000005"/>
  </inertial>
  <visual>
    <origin rpy="0 1.57 0" xyz="-0.1 0 0"/>
    <geometry>
      <cylinder length="0.2" radius="0.1"/>
    </geometry>
  </visual>
  <collision>
    <origin rpy="0 1.57 0" xyz="-0.1 0 0"/>
    <geometry>
      <cylinder length="0.2" radius="0.1"/>
    </geometry>
  </collision>
 </link>

<joint name="joint_fixed_eye_head" type="fixed">
  <origin rpy="0 0 0" xyz="0 0 0"/>
  <parent link="eye"/>
  <child link="head"/>
</joint>

<!--############################################################################
branch_00
##############################################################################-->
 <link name="branch_00_cylinder_stub">
  <inertial>
    <mass value="1"/>
    <inertia ixx="0.0005687499999999999" ixy="0" ixz="0" iyy="0.0005687499999999999" iyz="0" izz="0.0001"/>
  </inertial>
  <visual>
    <origin rpy="0 1.57 0" xyz="-0.0375 0 0"/>
    <geometry>
      <cylinder length="0.075" radius="0.02"/>
    </geometry>
  </visual>
  <collision>
    <origin rpy="0 1.57 0" xyz="-0.0375 0 0"/>
    <geometry>
      <cylinder length="0.075" radius="0.02"/>
    </geometry>
  </collision>
 </link>

<joint name="joint_fixed_head_branch_00_cylinder_stub" type="fixed">
  <origin rpy="0 0 0" xyz="-0.2 0.06999999999999999 0.0"/>
  <parent link="head"/>
  <child link="branch_00_cylinder_stub"/>
</joint>

<link name="branch_00_sphere_stub">
  <inertial>
   <mass value="1"/>
   <inertia ixx="0.00014439999999999999" ixy="0" ixz="0" iyy="0.00014439999999999999" iyz="0" izz="0.00014439999999999999"/>
  </inertial>
  <collision>
    <origin rpy="0 0 0" xyz="-0.095 0 0"/>
    <geometry>
      <sphere radius="0.019"/>
    </geometry>
  </collision>
  <visual>
    <origin rpy="0 0 0" xyz="-0.095 0 0"/>
    <geometry>
      <sphere radius="0.019"/>
    </geometry>
  </visual>
</link>

<joint name="joint_fixed_branch_00_cylinder_stub_branch_00_sphere_stub" type="fixed">
  <origin rpy="0 0 0" xyz="0 0 0"/>
  <parent link="branch_00_cylinder_stub"/>
  <child link="branch_00_sphere_stub"/>
</joint>

 <link name="branch_00_cylinder">
  <inertial>
    <mass value="1"/>
    <inertia ixx="0.0019749999999999998" ixy="0" ixz="0" iyy="0.0019749999999999998" iyz="0" izz="0.0001"/>
  </inertial>
  <visual>
    <origin rpy="0 1.5707963267948966 1.57" xyz="-0.095 0.095 0.0"/>
    <geometry>
      <cylinder length="0.15" radius="0.02"/>
    </geometry>
  </visual>
  <collision>
    <origin rpy="0 1.5707963267948966 1.57" xyz="-0.095 0.095 0.0"/>
    <geometry>
      <cylinder length="0.15" radius="0.02"/>
    </geometry>
  </collision>
 </link>

<joint name="joint_fixed_branch_00_sphere_stub_branch_00_cylinder" type="fixed">
  <origin rpy="0 0 0" xyz="0 0 0"/>
  <parent link="branch_00_sphere_stub"/>
  <child link="branch_00_cylinder"/>
</joint>

<link name="branch_00">
  <inertial>
   <mass value="1"/>
   <inertia ixx="0.00014439999999999999" ixy="0" ixz="0" iyy="0.00014439999999999999" iyz="0" izz="0.00014439999999999999"/>
  </inertial>
  <collision>
    <origin rpy="0 0 0" xyz="0 0 0"/>
    <geometry>
      <sphere radius="0.019"/>
    </geometry>
  </collision>
  <visual>
    <origin rpy="0 0 0" xyz="0 0 0"/>
    <geometry>
      <sphere radius="0.019"/>
    </geometry>
  </visual>
</link>

<joint name="joint_fixed_branch_00_cylinder_branch_00" type="fixed">
  <origin rpy="0 0 0" xyz="-0.095 0.19 0.0"/>
  <parent link="branch_00_cylinder"/>
  <child link="branch_00"/>
</joint>

<!--############################################################################
branch_01
##############################################################################-->
 <link name="branch_01_cylinder">
  <inertial>
    <mass value="1"/>
    <inertia ixx="0.0019749999999999998" ixy="0" ixz="0" iyy="0.0019749999999999998" iyz="0" izz="0.0001"/>
  </inertial>
  <visual>
    <origin rpy="0 1.57 0" xyz="-0.095 0 0"/>
    <geometry>
      <cylinder length="0.15" radius="0.02"/>
    </geometry>
  </visual>
  <collision>
    <origin rpy="0 1.57 0" xyz="-0.095 0 0"/>
    <geometry>
      <cylinder length="0.15" radius="0.02"/>
    </geometry>
  </collision>
 </link>

<joint name="joint_revolute_branch_00_branch_01_cylinder_Z" type="revolute">
  <origin rpy="0 0 0" xyz="0 0 0"/>
  <parent link="branch_00"/>
  <child link="branch_01_cylinder"/>
  <axis xyz="0 0.0 -1.0"/>
  <dynamics damping="0.01" friction="0.5"/>
  <limit lower="-1.5707963267948966" upper="1.5707963267948966" effort="0.01" velocity="100"/>
</joint>

<link name="branch_01">
  <inertial>
   <mass value="1"/>
   <inertia ixx="0.00014439999999999999" ixy="0" ixz="0" iyy="0.00014439999999999999" iyz="0" izz="0.00014439999999999999"/>
  </inertial>
  <collision>
    <origin rpy="0 0 0" xyz="0 0 0"/>
    <geometry>
      <sphere radius="0.019"/>
    </geometry>
  </collision>
  <visual>
    <origin rpy="0 0 0" xyz="0 0 0"/>
    <geometry>
      <sphere radius="0.019"/>
    </geometry>
  </visual>
</link>

<joint name="joint_fixed_branch_01_cylinder_branch_01" type="fixed">
  <origin rpy="0 0 0" xyz="-0.19 0 0"/>
  <parent link="branch_01_cylinder"/>
  <child link="branch_01"/>
</joint>

<!--############################################################################
branch_02
##############################################################################-->
 <link name="branch_02_cylinder">
  <inertial>
    <mass value="1"/>
    <inertia ixx="0.0019749999999999998" ixy="0" ixz="0" iyy="0.0019749999999999998" iyz="0" izz="0.0001"/>
  </inertial>
  <visual>
    <origin rpy="0 1.57 0" xyz="-0.095 0 0"/>
    <geometry>
      <cylinder length="0.15" radius="0.02"/>
    </geometry>
  </visual>
  <collision>
    <origin rpy="0 1.57 0" xyz="-0.095 0 0"/>
    <geometry>
      <cylinder length="0.15" radius="0.02"/>
    </geometry>
  </collision>
 </link>

<joint name="joint_revolute_branch_01_branch_02_cylinder_Z" type="revolute">
  <origin rpy="0 0 0" xyz="0 0 0"/>
  <parent link="branch_01"/>
  <child link="branch_02_cylinder"/>
  <axis xyz="0 0.0 -1.0"/>
  <dynamics damping="0.01" friction="0.5"/>
  <limit lower="-1.5707963267948966" upper="1.5707963267948966" effort="0.01" velocity="100"/>
</joint>

<link name="branch_02">
  <inertial>
   <mass value="1"/>
   <inertia ixx="0.00014439999999999999" ixy="0" ixz="0" iyy="0.00014439999999999999" iyz="0" izz="0.00014439999999999999"/>
  </inertial>
  <collision>
    <origin rpy="0 0 0" xyz="0 0 0"/>
    <geometry>
      <sphere radius="0.019"/>
    </geometry>
  </collision>
  <visual>
    <origin rpy="0 0 0" xyz="0 0 0"/>
    <geometry>
      <sphere radius="0.019"/>
    </geometry>
  </visual>
</link>

<joint name="joint_fixed_branch_02_cylinder_branch_02" type="fixed">
  <origin rpy="0 0 0" xyz="-0.19 0 0"/>
  <parent link="branch_02_cylinder"/>
  <child link="branch_02"/>
</joint>

<!--############################################################################
branch_03
##############################################################################-->
 <link name="branch_03_cylinder">
  <inertial>
    <mass value="1"/>
    <inertia ixx="0.0019749999999999998" ixy="0" ixz="0" iyy="0.0019749999999999998" iyz="0" izz="0.0001"/>
  </inertial>
  <visual>
    <origin rpy="0 1.57 0" xyz="-0.095 0 0"/>
    <geometry>
      <cylinder length="0.15" radius="0.02"/>
    </geometry>
  </visual>
  <collision>
    <origin rpy="0 1.57 0" xyz="-0.095 0 0"/>
    <geometry>
      <cylinder length="0.15" radius="0.02"/>
    </geometry>
  </collision>
 </link>

<joint name="joint_revolute_branch_02_branch_03_cylinder_Z" type="revolute">
  <origin rpy="0 0 0" xyz="0 0 0"/>
  <parent link="branch_02"/>
  <child link="branch_03_cylinder"/>
  <axis xyz="0 0.0 -1.0"/>
  <dynamics damping="0.01" friction="0.5"/>
  <limit lower="-1.5707963267948966" upper="1.5707963267948966" effort="0.01" velocity="100"/>
</joint>

<link name="branch_03">
  <inertial>
   <mass value="1"/>
   <inertia ixx="0.00014439999999999999" ixy="0" ixz="0" iyy="0.00014439999999999999" iyz="0" izz="0.00014439999999999999"/>
  </inertial>
  <collision>
    <origin rpy="0 0 0" xyz="0 0 0"/>
    <geometry>
      <sphere radius="0.019"/>
    </geometry>
  </collision>
  <visual>
    <origin rpy="0 0 0" xyz="0 0 0"/>
    <geometry>
      <sphere radius="0.019"/>
    </geometry>
  </visual>
</link>

<joint name="joint_fixed_branch_03_cylinder_branch_03" type="fixed">
  <origin rpy="0 0 0" xyz="-0.19 0 0"/>
  <parent link="branch_03_cylinder"/>
  <child link="branch_03"/>
</joint>

<!--############################################################################
branch_04
##############################################################################-->
 <link name="branch_04_cylinder">
  <inertial>
    <mass value="1"/>
    <inertia ixx="0.0019749999999999998" ixy="0" ixz="0" iyy="0.0019749999999999998" iyz="0" izz="0.0001"/>
  </inertial>
  <visual>
    <origin rpy="0 1.57 0" xyz="-0.095 0 0"/>
    <geometry>
      <cylinder length="0.15" radius="0.02"/>
    </geometry>
  </visual>
  <collision>
    <origin rpy="0 1.57 0" xyz="-0.095 0 0"/>
    <geometry>
      <cylinder length="0.15" radius="0.02"/>
    </geometry>
  </collision>
 </link>

<joint name="joint_revolute_branch_03_branch_04_cylinder_Z" type="revolute">
  <origin rpy="0 0 0" xyz="0 0 0"/>
  <parent link="branch_03"/>
  <child link="branch_04_cylinder"/>
  <axis xyz="0 0.0 -1.0"/>
  <dynamics damping="0.01" friction="0.5"/>
  <limit lower="-1.5707963267948966" upper="1.5707963267948966" effort="0.01" velocity="100"/>
</joint>

<link name="branch_04">
  <inertial>
   <mass value="1"/>
   <inertia ixx="0.00014439999999999999" ixy="0" ixz="0" iyy="0.00014439999999999999" iyz="0" izz="0.00014439999999999999"/>
  </inertial>
  <collision>
    <origin rpy="0 0 0" xyz="0 0 0"/>
    <geometry>
      <sphere radius="0.019"/>
    </geometry>
  </collision>
  <visual>
    <origin rpy="0 0 0" xyz="0 0 0"/>
    <geometry>
      <sphere radius="0.019"/>
    </geometry>
  </visual>
</link>

<joint name="joint_fixed_branch_04_cylinder_branch_04" type="fixed">
  <origin rpy="0 0 0" xyz="-0.19 0 0"/>
  <parent link="branch_04_cylinder"/>
  <child link="branch_04"/>
</joint>

<!--############################################################################
branch_05
##############################################################################-->
 <link name="branch_05_cylinder">
  <inertial>
    <mass value="1"/>
    <inertia ixx="0.0019749999999999998" ixy="0" ixz="0" iyy="0.0019749999999999998" iyz="0" izz="0.0001"/>
  </inertial>
  <visual>
    <origin rpy="0 1.57 0" xyz="-0.095 0 0"/>
    <geometry>
      <cylinder length="0.15" radius="0.02"/>
    </geometry>
  </visual>
  <collision>
    <origin rpy="0 1.57 0" xyz="-0.095 0 0"/>
    <geometry>
      <cylinder length="0.15" radius="0.02"/>
    </geometry>
  </collision>
 </link>

<joint name="joint_revolute_branch_04_branch_05_cylinder_Z" type="revolute">
  <origin rpy="0 0 0" xyz="0 0 0"/>
  <parent link="branch_04"/>
  <child link="branch_05_cylinder"/>
  <axis xyz="0 0.0 -1.0"/>
  <dynamics damping="0.01" friction="0.5"/>
  <limit lower="-1.5707963267948966" upper="1.5707963267948966" effort="0.01" velocity="100"/>
</joint>

<link name="branch_05">
  <inertial>
   <mass value="1"/>
   <inertia ixx="0.00014439999999999999" ixy="0" ixz="0" iyy="0.00014439999999999999" iyz="0" izz="0.00014439999999999999"/>
  </inertial>
  <collision>
    <origin rpy="0 0 0" xyz="0 0 0"/>
    <geometry>
      <sphere radius="0.019"/>
    </geometry>
  </collision>
  <visual>
    <origin rpy="0 0 0" xyz="0 0 0"/>
    <geometry>
      <sphere radius="0.019"/>
    </geometry>
  </visual>
</link>

<joint name="joint_fixed_branch_05_cylinder_branch_05" type="fixed">
  <origin rpy="0 0 0" xyz="-0.19 0 0"/>
  <parent link="branch_05_cylinder"/>
  <child link="branch_05"/>
</joint>

<!--############################################################################
branch_06
##############################################################################-->
 <link name="branch_06_cylinder">
  <inertial>
    <mass value="1"/>
    <inertia ixx="0.0019749999999999998" ixy="0" ixz="0" iyy="0.0019749999999999998" iyz="0" izz="0.0001"/>
  </inertial>
  <visual>
    <origin rpy="0 1.57 0" xyz="-0.095 0 0"/>
    <geometry>
      <cylinder length="0.15" radius="0.02"/>
    </geometry>
  </visual>
  <collision>
    <origin rpy="0 1.57 0" xyz="-0.095 0 0"/>
    <geometry>
      <cylinder length="0.15" radius="0.02"/>
    </geometry>
  </collision>
 </link>

<joint name="joint_revolute_branch_05_branch_06_cylinder_Z" type="revolute">
  <origin rpy="0 0 0" xyz="0 0 0"/>
  <parent link="branch_05"/>
  <child link="branch_06_cylinder"/>
  <axis xyz="0 0.0 -1.0"/>
  <dynamics damping="0.01" friction="0.5"/>
  <limit lower="-1.5707963267948966" upper="1.5707963267948966" effort="0.01" velocity="100"/>
</joint>

<link name="branch_06">
  <inertial>
   <mass value="1"/>
   <inertia ixx="0.00014439999999999999" ixy="0" ixz="0" iyy="0.00014439999999999999" iyz="0" izz="0.00014439999999999999"/>
  </inertial>
  <collision>
    <origin rpy="0 0 0" xyz="0 0 0"/>
    <geometry>
      <sphere radius="0.019"/>
    </geometry>
  </collision>
  <visual>
    <origin rpy="0 0 0" xyz="0 0 0"/>
    <geometry>
      <sphere radius="0.019"/>
    </geometry>
  </visual>
</link>

<joint name="joint_fixed_branch_06_cylinder_branch_06" type="fixed">
  <origin rpy="0 0 0" xyz="-0.19 0 0"/>
  <parent link="branch_06_cylinder"/>
  <child link="branch_06"/>
</joint>

<!--############################################################################
branch_10
##############################################################################-->
 <link name="branch_10_cylinder_stub">
  <inertial>
    <mass value="1"/>
    <inertia ixx="0.0005687499999999999" ixy="0" ixz="0" iyy="0.0005687499999999999" iyz="0" izz="0.0001"/>
  </inertial>
  <visual>
    <origin rpy="0 1.57 0" xyz="-0.0375 0 0"/>
    <geometry>
      <cylinder length="0.075" radius="0.02"/>
    </geometry>
  </visual>
  <collision>
    <origin rpy="0 1.57 0" xyz="-0.0375 0 0"/>
    <geometry>
      <cylinder length="0.075" radius="0.02"/>
    </geometry>
  </collision>
 </link>

<joint name="joint_fixed_head_branch_10_cylinder_stub" type="fixed">
  <origin rpy="0 0 0" xyz="-0.2 0.049497474683058325 0.04949747468305832"/>
  <parent link="head"/>
  <child link="branch_10_cylinder_stub"/>
</joint>

<link name="branch_10_sphere_stub">
  <inertial>
   <mass value="1"/>
   <inertia ixx="0.00014439999999999999" ixy="0" ixz="0" iyy="0.00014439999999999999" iyz="0" izz="0.00014439999999999999"/>
  </inertial>
  <collision>
    <origin rpy="0 0 0" xyz="-0.095 0 0"/>
    <geometry>
      <sphere radius="0.019"/>
    </geometry>
  </collision>
  <visual>
    <origin rpy="0 0 0" xyz="-0.095 0 0"/>
    <geometry>
      <sphere radius="0.019"/>
    </geometry>
  </visual>
</link>

<joint name="joint_fixed_branch_10_cylinder_stub_branch_10_sphere_stub" type="fixed">
  <origin rpy="0 0 0" xyz="0 0 0"/>
  <parent link="branch_10_cylinder_stub"/>
  <child link="branch_10_sphere_stub"/>
</joint>

 <link name="branch_10_cylinder">
  <inertial>
    <mass value="1"/>
    <inertia ixx="0.0019749999999999998" ixy="0" ixz="0" iyy="0.0019749999999999998" iyz="0" izz="0.0001"/>
  </inertial>
  <visual>
    <origin rpy="0 0.7853981633974484 1.57" xyz="-0.095 0.06717514421272201 0.06717514421272201"/>
    <geometry>
      <cylinder length="0.15" radius="0.02"/>
    </geometry>
  </visual>
  <collision>
    <origin rpy="0 0.7853981633974484 1.57" xyz="-0.095 0.06717514421272201 0.06717514421272201"/>
    <geometry>
      <cylinder length="0.15" radius="0.02"/>
    </geometry>
  </collision>
 </link>

<joint name="joint_fixed_branch_10_sphere_stub_branch_10_cylinder" type="fixed">
  <origin rpy="0 0 0" xyz="0 0 0"/>
  <parent link="branch_10_sphere_stub"/>
  <child link="branch_10_cylinder"/>
</joint>

<link name="branch_10">
  <inertial>
   <mass value="1"/>
   <inertia ixx="0.00014439999999999999" ixy="0" ixz="0" iyy="0.00014439999999999999" iyz="0" izz="0.00014439999999999999"/>
  </inertial>
  <collision>
    <origin rpy="0 0 0" xyz="0 0 0"/>
    <geometry>
      <sphere radius="0.019"/>
    </geometry>
  </collision>
  <visual>
    <origin rpy="0 0 0" xyz="0 0 0"/>
    <geometry>
      <sphere radius="0.019"/>
    </geometry>
  </visual>
</link>

<joint name="joint_fixed_branch_10_cylinder_branch_10" type="fixed">
  <origin rpy="0 0 0" xyz="-0.095 0.13435028842544403 0.13435028842544403"/>
  <parent link="branch_10_cylinder"/>
  <child link="branch_10"/>
</joint>

<!--############################################################################
branch_11
##############################################################################-->
 <link name="branch_11_cylinder">
  <inertial>
    <mass value="1"/>
    <inertia ixx="0.0019749999999999998" ixy="0" ixz="0" iyy="0.0019749999999999998" iyz="0" izz="0.0001"/>
  </inertial>
  <visual>
    <origin rpy="0 1.57 0" xyz="-0.095 0 0"/>
    <geometry>
      <cylinder length="0.15" radius="0.02"/>
    </geometry>
  </visual>
  <collision>
    <origin rpy="0 1.57 0" xyz="-0.095 0 0"/>
    <geometry>
      <cylinder length="0.15" radius="0.02"/>
    </geometry>
  </collision>
 </link>

<joint name="joint_revolute_branch_10_branch_11_cylinder_Z" type="revolute">
  <origin rpy="0 0 0" xyz="0 0 0"/>
  <parent link="branch_10"/>
  <child link="branch_11_cylinder"/>
  <axis xyz="0 0.7071067811865475 -0.7071067811865476"/>
  <dynamics damping="0.01" friction="0.5"/>
  <limit lower="-1.5707963267948966" upper="1.5707963267948966" effort="0.01" velocity="100"/>
</joint>

<link name="branch_11">
  <inertial>
   <mass value="1"/>
   <inertia ixx="0.00014439999999999999" ixy="0" ixz="0" iyy="0.00014439999999999999" iyz="0" izz="0.00014439999999999999"/>
  </inertial>
  <collision>
    <origin rpy="0 0 0" xyz="0 0 0"/>
    <geometry>
      <sphere radius="0.019"/>
    </geometry>
  </collision>
  <visual>
    <origin rpy="0 0 0" xyz="0 0 0"/>
    <geometry>
      <sphere radius="0.019"/>
    </geometry>
  </visual>
</link>

<joint name="joint_fixed_branch_11_cylinder_branch_11" type="fixed">
  <origin rpy="0 0 0" xyz="-0.19 0 0"/>
  <parent link="branch_11_cylinder"/>
  <child link="branch_11"/>
</joint>

<!--############################################################################
branch_12
##############################################################################-->
 <link name="branch_12_cylinder">
  <inertial>
    <mass value="1"/>
    <inertia ixx="0.0019749999999999998" ixy="0" ixz="0" iyy="0.0019749999999999998" iyz="0" izz="0.0001"/>
  </inertial>
  <visual>
    <origin rpy="0 1.57 0" xyz="-0.095 0 0"/>
    <geometry>
      <cylinder length="0.15" radius="0.02"/>
    </geometry>
  </visual>
  <collision>
    <origin rpy="0 1.57 0" xyz="-0.095 0 0"/>
    <geometry>
      <cylinder length="0.15" radius="0.02"/>
    </geometry>
  </collision>
 </link>

<joint name="joint_revolute_branch_11_branch_12_cylinder_Z" type="revolute">
  <origin rpy="0 0 0" xyz="0 0 0"/>
  <parent link="branch_11"/>
  <child link="branch_12_cylinder"/>
  <axis xyz="0 0.7071067811865475 -0.7071067811865476"/>
  <dynamics damping="0.01" friction="0.5"/>
  <limit lower="-1.5707963267948966" upper="1.5707963267948966" effort="0.01" velocity="100"/>
</joint>

<link name="branch_12">
  <inertial>
   <mass value="1"/>
   <inertia ixx="0.00014439999999999999" ixy="0" ixz="0" iyy="0.00014439999999999999" iyz="0" izz="0.00014439999999999999"/>
  </inertial>
  <collision>
    <origin rpy="0 0 0" xyz="0 0 0"/>
    <geometry>
      <sphere radius="0.019"/>
    </geometry>
  </collision>
  <visual>
    <origin rpy="0 0 0" xyz="0 0 0"/>
    <geometry>
      <sphere radius="0.019"/>
    </geometry>
  </visual>
</link>

<joint name="joint_fixed_branch_12_cylinder_branch_12" type="fixed">
  <origin rpy="0 0 0" xyz="-0.19 0 0"/>
  <parent link="branch_12_cylinder"/>
  <child link="branch_12"/>
</joint>

<!--############################################################################
branch_13
##############################################################################-->
 <link name="branch_13_cylinder">
  <inertial>
    <mass value="1"/>
    <inertia ixx="0.0019749999999999998" ixy="0" ixz="0" iyy="0.0019749999999999998" iyz="0" izz="0.0001"/>
  </inertial>
  <visual>
    <origin rpy="0 1.57 0" xyz="-0.095 0 0"/>
    <geometry>
      <cylinder length="0.15" radius="0.02"/>
    </geometry>
  </visual>
  <collision>
    <origin rpy="0 1.57 0" xyz="-0.095 0 0"/>
    <geometry>
      <cylinder length="0.15" radius="0.02"/>
    </geometry>
  </collision>
 </link>

<joint name="joint_revolute_branch_12_branch_13_cylinder_Z" type="revolute">
  <origin rpy="0 0 0" xyz="0 0 0"/>
  <parent link="branch_12"/>
  <child link="branch_13_cylinder"/>
  <axis xyz="0 0.7071067811865475 -0.7071067811865476"/>
  <dynamics damping="0.01" friction="0.5"/>
  <limit lower="-1.5707963267948966" upper="1.5707963267948966" effort="0.01" velocity="100"/>
</joint>

<link name="branch_13">
  <inertial>
   <mass value="1"/>
   <inertia ixx="0.00014439999999999999" ixy="0" ixz="0" iyy="0.00014439999999999999" iyz="0" izz="0.00014439999999999999"/>
  </inertial>
  <collision>
    <origin rpy="0 0 0" xyz="0 0 0"/>
    <geometry>
      <sphere radius="0.019"/>
    </geometry>
  </collision>
  <visual>
    <origin rpy="0 0 0" xyz="0 0 0"/>
    <geometry>
      <sphere radius="0.019"/>
    </geometry>
  </visual>
</link>

<joint name="joint_fixed_branch_13_cylinder_branch_13" type="fixed">
  <origin rpy="0 0 0" xyz="-0.19 0 0"/>
  <parent link="branch_13_cylinder"/>
  <child link="branch_13"/>
</joint>

<!--############################################################################
branch_14
##############################################################################-->
 <link name="branch_14_cylinder">
  <inertial>
    <mass value="1"/>
    <inertia ixx="0.0019749999999999998" ixy="0" ixz="0" iyy="0.0019749999999999998" iyz="0" izz="0.0001"/>
  </inertial>
  <visual>
    <origin rpy="0 1.57 0" xyz="-0.095 0 0"/>
    <geometry>
      <cylinder length="0.15" radius="0.02"/>
    </geometry>
  </visual>
  <collision>
    <origin rpy="0 1.57 0" xyz="-0.095 0 0"/>
    <geometry>
      <cylinder length="0.15" radius="0.02"/>
    </geometry>
  </collision>
 </link>

<joint name="joint_revolute_branch_13_branch_14_cylinder_Z" type="revolute">
  <origin rpy="0 0 0" xyz="0 0 0"/>
  <parent link="branch_13"/>
  <child link="branch_14_cylinder"/>
  <axis xyz="0 0.7071067811865475 -0.7071067811865476"/>
  <dynamics damping="0.01" friction="0.5"/>
  <limit lower="-1.5707963267948966" upper="1.5707963267948966" effort="0.01" velocity="100"/>
</joint>

<link name="branch_14">
  <inertial>
   <mass value="1"/>
   <inertia ixx="0.00014439999999999999" ixy="0" ixz="0" iyy="0.00014439999999999999" iyz="0" izz="0.00014439999999999999"/>
  </inertial>
  <collision>
    <origin rpy="0 0 0" xyz="0 0 0"/>
    <geometry>
      <sphere radius="0.019"/>
    </geometry>
  </collision>
  <visual>
    <origin rpy="0 0 0" xyz="0 0 0"/>
    <geometry>
      <sphere radius="0.019"/>
    </geometry>
  </visual>
</link>

<joint name="joint_fixed_branch_14_cylinder_branch_14" type="fixed">
  <origin rpy="0 0 0" xyz="-0.19 0 0"/>
  <parent link="branch_14_cylinder"/>
  <child link="branch_14"/>
</joint>

  <klampt package_root="../../.." default_acc_max="4" >
  </klampt>
</robot>