<?xml version="1.0"?>
<robot name="sentinel">
<link name="eye">
  <inertial>
  <mass value="0.05"/>
  <inertia ixx="0.005" ixy="0.001" ixz="0" iyy="0.006" iyz="0" izz="0.007"/>
  </inertial>
  <collision>
    <origin rpy="0 0 0" xyz="0 0 0"/>
    <geometry>
      <sphere radius="0.1"/>
    </geometry>
  </collision>
  <visual>
    <origin rpy="0 0 0" xyz="0 0 0"/>
    <geometry>
      <sphere radius="0.1"/>
    </geometry>
  </visual>
</link>

 <link name="head">
  <inertial>
    <mass value="0.05"/>
    <inertia ixx="0.005" ixy="0.001" ixz="0" iyy="0.006" iyz="0" izz="0.007"/>
  </inertial>
  <visual>
    <origin rpy="0 1.54 0" xyz="-0.05 0 0"/>
    <geometry>
      <cylinder length="0.1" radius="0.1"/>
    </geometry>
  </visual>
  <collision>
    <origin rpy="0 1.54 0" xyz="-0.05 0 0"/>
    <geometry>
      <cylinder length="0.1" radius="0.1"/>
    </geometry>
  </collision>
 </link>

<joint name="joint_eye_head" type="fixed">
  <origin rpy="0 0 0" xyz="0 0 0"/>
  <parent link="eye"/>
  <child link="head"/>
</joint>

<!--############################################################################
branch_00
##############################################################################-->
 <link name="branch_00">
  <inertial>
    <mass value="0.05"/>
    <inertia ixx="0.005" ixy="0.001" ixz="0" iyy="0.006" iyz="0" izz="0.007"/>
  </inertial>
  <visual>
    <origin rpy="0 1.54 0" xyz="-0.075 0 0"/>
    <geometry>
      <cylinder length="0.15" radius="0.01"/>
    </geometry>
  </visual>
  <collision>
    <origin rpy="0 1.54 0" xyz="-0.075 0 0"/>
    <geometry>
      <cylinder length="0.15" radius="0.01"/>
    </geometry>
  </collision>
 </link>

<joint name="head_branch_00_joint" type="fixed">
  <origin rpy="0 0 0" xyz="-0.1 0.07 0.0"/>
  <parent link="head"/>
  <child link="branch_00"/>
</joint>

<link name="branch_00_sphere">
  <inertial>
  <mass value="0.05"/>
  <inertia ixx="0.005" ixy="0.001" ixz="0" iyy="0.006" iyz="0" izz="0.007"/>
  </inertial>
  <collision>
    <origin rpy="0 0 0" xyz="-0.15 0 0"/>
    <geometry>
      <sphere radius="0.02"/>
    </geometry>
  </collision>
  <visual>
    <origin rpy="0 0 0" xyz="-0.15 0 0"/>
    <geometry>
      <sphere radius="0.02"/>
    </geometry>
  </visual>
</link>

<joint name="branch_00_fixed" type="fixed">
  <origin rpy="0 0 0" xyz="0 0 0"/>
  <parent link="branch_00"/>
  <child link="branch_00_sphere"/>
</joint>

 <link name="branch_01">
  <inertial>
    <mass value="0.05"/>
    <inertia ixx="0.005" ixy="0.001" ixz="0" iyy="0.006" iyz="0" izz="0.007"/>
  </inertial>
  <visual>
    <origin rpy="0 1.54 0" xyz="-0.075 0 0"/>
    <geometry>
      <cylinder length="0.15" radius="0.01"/>
    </geometry>
  </visual>
  <collision>
    <origin rpy="0 1.54 0" xyz="-0.075 0 0"/>
    <geometry>
      <cylinder length="0.15" radius="0.01"/>
    </geometry>
  </collision>
 </link>

<joint name="branch_00_branch_01_joint_revolute_Y" type="revolute">
  <origin rpy="0 0 0" xyz="-0.15 0 0"/>
  <parent link="branch_00"/>
  <child link="branch_00_spherical_joint_link"/>
  <axis xyz="0 1 0"/>
  <dynamics damping="0.5" friction="0"/>
  <limit lower="-1.57" upper="1.57" effort="0.01" velocity="1000"/>
</joint>

<link name="branch_00_spherical_joint_link">
  <inertial>
  <mass value="0.05"/>
  <inertia ixx="0.005" ixy="0.001" ixz="0" iyy="0.006" iyz="0" izz="0.007"/>
  </inertial>
  <collision>
    <origin rpy="0 0 0" xyz="0 0 0"/>
    <geometry>
      <sphere radius="0.01"/>
    </geometry>
  </collision>
  <visual>
    <origin rpy="0 0 0" xyz="0 0 0"/>
    <geometry>
      <sphere radius="0.01"/>
    </geometry>
  </visual>
</link>

<joint name="branch_00_branch_01_joint_revolute_X" type="revolute">
  <origin rpy="0 0 0" xyz="0 0 0"/>
  <parent link="branch_00_spherical_joint_link"/>
  <child link="branch_01"/>
  <axis xyz="0 0 1"/>
  <dynamics damping="0.5" friction="0"/>
  <limit lower="-1.57" upper="1.57" effort="0.01" velocity="1000"/>
</joint>

<link name="branch_01_sphere">
  <inertial>
  <mass value="0.05"/>
  <inertia ixx="0.005" ixy="0.001" ixz="0" iyy="0.006" iyz="0" izz="0.007"/>
  </inertial>
  <collision>
    <origin rpy="0 0 0" xyz="0 0 0"/>
    <geometry>
      <sphere radius="0.02"/>
    </geometry>
  </collision>
  <visual>
    <origin rpy="0 0 0" xyz="0 0 0"/>
    <geometry>
      <sphere radius="0.02"/>
    </geometry>
  </visual>
</link>

<joint name="branch_01_fixed" type="fixed">
  <origin rpy="0 0 0" xyz="-0.15 0 0"/>
  <parent link="branch_01"/>
  <child link="branch_01_sphere"/>
</joint>

  <klampt package_root="../.." use_vis_geom="1" />
</robot>