<?xml version="1.0"?>
<robot name="sentinel">
<link name="eye">
  <inertial>
  <mass value="0.05"/>
  <inertia ixx="0.005" ixy="0.001" ixz="0" iyy="0.006" iyz="0" izz="0.007"/>
  </inertial>
  <collision>
    <origin rpy="0 0 0" xyz="0 0 0"/>
    <geometry>
      <sphere radius="0.1"/>
    </geometry>
  </collision>
  <visual>
    <origin rpy="0 0 0" xyz="0 0 0"/>
    <geometry>
      <sphere radius="0.1"/>
    </geometry>
  </visual>
</link>

 <link name="head">
  <inertial>
    <mass value="0.05"/>
    <inertia ixx="0.005" ixy="0.001" ixz="0" iyy="0.006" iyz="0" izz="0.007"/>
  </inertial>
  <visual>
    <origin rpy="0 1.54 0" xyz="-0.05 0 0"/>
    <geometry>
      <cylinder length="0.1" radius="0.1"/>
    </geometry>
  </visual>
  <collision>
    <origin rpy="0 1.57 0" xyz="-0.05 0 0"/>
    <geometry>
      <cylinder length="0.1" radius="0.1"/>
    </geometry>
  </collision>
 </link>

<joint name="joint_eye_head" type="fixed">
  <origin rpy="0 0 0" xyz="0 0 0"/>
  <parent link="eye"/>
  <child link="head"/>
</joint>

<!--############################################################################
branch_00
##############################################################################-->
 <link name="branch_00_cylinder">
  <inertial>
    <mass value="0.05"/>
    <inertia ixx="0.005" ixy="0.001" ixz="0" iyy="0.006" iyz="0" izz="0.007"/>
  </inertial>
  <visual>
    <origin rpy="0 1.54 0" xyz="-0.075 0 0"/>
    <geometry>
      <cylinder length="0.15" radius="0.01"/>
    </geometry>
  </visual>
  <collision>
    <origin rpy="0 1.57 0" xyz="-0.075 0 0"/>
    <geometry>
      <cylinder length="0.15" radius="0.01"/>
    </geometry>
  </collision>
 </link>

<joint name="head_branch_00_joint" type="fixed">
  <origin rpy="0 0 0" xyz="-0.1 0.05 0.0"/>
  <parent link="head"/>
  <child link="branch_00_cylinder"/>
</joint>

<link name="branch_00">
  <inertial>
  <mass value="0.05"/>
  <inertia ixx="0.005" ixy="0.001" ixz="0" iyy="0.006" iyz="0" izz="0.007"/>
  </inertial>
  <collision>
    <origin rpy="0 0 0" xyz="-0.17 0 0"/>
    <geometry>
      <sphere radius="0.019"/>
    </geometry>
  </collision>
  <visual>
    <origin rpy="0 0 0" xyz="-0.17 0 0"/>
    <geometry>
      <sphere radius="0.019"/>
    </geometry>
  </visual>
</link>

<joint name="branch_00_fixed" type="fixed">
  <origin rpy="0 0 0" xyz="0 0 0"/>
  <parent link="branch_00_cylinder"/>
  <child link="branch_00"/>
</joint>

 <link name="branch_01_cylinder">
  <inertial>
    <mass value="0.05"/>
    <inertia ixx="0.005" ixy="0.001" ixz="0" iyy="0.006" iyz="0" izz="0.007"/>
  </inertial>
  <visual>
    <origin rpy="0 1.54 0" xyz="-0.095 0 0"/>
    <geometry>
      <cylinder length="0.15" radius="0.01"/>
    </geometry>
  </visual>
  <collision>
    <origin rpy="0 1.57 0" xyz="-0.095 0 0"/>
    <geometry>
      <cylinder length="0.15" radius="0.01"/>
    </geometry>
  </collision>
 </link>

<joint name="branch_00_branch_01_joint_revolute_Y" type="revolute">
  <origin rpy="0 0 0" xyz="-0.17 0 0"/>
  <parent link="branch_00"/>
  <child link="branch_00_spherical_joint_link"/>
  <axis xyz="0 1 0"/>
  <dynamics damping="0.5" friction="0"/>
  <limit lower="-1.57" upper="1.57" effort="0.01" velocity="100"/>
</joint>

<link name="branch_00_spherical_joint_link" physical="0">
  <inertial>
  <mass value="0.05"/>
  <inertia ixx="0.005" ixy="0.001" ixz="0" iyy="0.006" iyz="0" izz="0.007"/>
  </inertial>
  <collision>
    <origin rpy="0 0 0" xyz="0 0 0"/>
    <geometry>
      <sphere radius="0.001"/>
    </geometry>
  </collision>
  <visual>
    <origin rpy="0 0 0" xyz="0 0 0"/>
    <geometry>
      <sphere radius="0.001"/>
    </geometry>
  </visual>
</link>

<joint name="branch_00_branch_01_joint_revolute_X" type="revolute">
  <origin rpy="0 0 0" xyz="0 0 0"/>
  <parent link="branch_00_spherical_joint_link"/>
  <child link="branch_01_cylinder"/>
  <axis xyz="0 0 1"/>
  <dynamics damping="0.5" friction="0"/>
  <limit lower="-1.57" upper="1.57" effort="0.01" velocity="100"/>
</joint>

<link name="branch_01">
  <inertial>
  <mass value="0.05"/>
  <inertia ixx="0.005" ixy="0.001" ixz="0" iyy="0.006" iyz="0" izz="0.007"/>
  </inertial>
  <collision>
    <origin rpy="0 0 0" xyz="-0.19 0 0"/>
    <geometry>
      <sphere radius="0.019"/>
    </geometry>
  </collision>
  <visual>
    <origin rpy="0 0 0" xyz="-0.19 0 0"/>
    <geometry>
      <sphere radius="0.019"/>
    </geometry>
  </visual>
</link>

<joint name="branch_01_fixed" type="fixed">
  <origin rpy="0 0 0" xyz="0 0 0"/>
  <parent link="branch_01_cylinder"/>
  <child link="branch_01"/>
</joint>

 <link name="branch_02_cylinder">
  <inertial>
    <mass value="0.05"/>
    <inertia ixx="0.005" ixy="0.001" ixz="0" iyy="0.006" iyz="0" izz="0.007"/>
  </inertial>
  <visual>
    <origin rpy="0 1.54 0" xyz="-0.095 0 0"/>
    <geometry>
      <cylinder length="0.15" radius="0.01"/>
    </geometry>
  </visual>
  <collision>
    <origin rpy="0 1.57 0" xyz="-0.095 0 0"/>
    <geometry>
      <cylinder length="0.15" radius="0.01"/>
    </geometry>
  </collision>
 </link>

<joint name="branch_01_branch_02_joint_revolute_Y" type="revolute">
  <origin rpy="0 0 0" xyz="-0.19 0 0"/>
  <parent link="branch_01"/>
  <child link="branch_01_spherical_joint_link"/>
  <axis xyz="0 1 0"/>
  <dynamics damping="0.5" friction="0"/>
  <limit lower="-1.57" upper="1.57" effort="0.01" velocity="100"/>
</joint>

<link name="branch_01_spherical_joint_link" physical="0">
  <inertial>
  <mass value="0.05"/>
  <inertia ixx="0.005" ixy="0.001" ixz="0" iyy="0.006" iyz="0" izz="0.007"/>
  </inertial>
  <collision>
    <origin rpy="0 0 0" xyz="0 0 0"/>
    <geometry>
      <sphere radius="0.001"/>
    </geometry>
  </collision>
  <visual>
    <origin rpy="0 0 0" xyz="0 0 0"/>
    <geometry>
      <sphere radius="0.001"/>
    </geometry>
  </visual>
</link>

<joint name="branch_01_branch_02_joint_revolute_X" type="revolute">
  <origin rpy="0 0 0" xyz="0 0 0"/>
  <parent link="branch_01_spherical_joint_link"/>
  <child link="branch_02_cylinder"/>
  <axis xyz="0 0 1"/>
  <dynamics damping="0.5" friction="0"/>
  <limit lower="-1.57" upper="1.57" effort="0.01" velocity="100"/>
</joint>

<link name="branch_02">
  <inertial>
  <mass value="0.05"/>
  <inertia ixx="0.005" ixy="0.001" ixz="0" iyy="0.006" iyz="0" izz="0.007"/>
  </inertial>
  <collision>
    <origin rpy="0 0 0" xyz="-0.19 0 0"/>
    <geometry>
      <sphere radius="0.019"/>
    </geometry>
  </collision>
  <visual>
    <origin rpy="0 0 0" xyz="-0.19 0 0"/>
    <geometry>
      <sphere radius="0.019"/>
    </geometry>
  </visual>
</link>

<joint name="branch_02_fixed" type="fixed">
  <origin rpy="0 0 0" xyz="0 0 0"/>
  <parent link="branch_02_cylinder"/>
  <child link="branch_02"/>
</joint>

 <link name="branch_03_cylinder">
  <inertial>
    <mass value="0.05"/>
    <inertia ixx="0.005" ixy="0.001" ixz="0" iyy="0.006" iyz="0" izz="0.007"/>
  </inertial>
  <visual>
    <origin rpy="0 1.54 0" xyz="-0.095 0 0"/>
    <geometry>
      <cylinder length="0.15" radius="0.01"/>
    </geometry>
  </visual>
  <collision>
    <origin rpy="0 1.57 0" xyz="-0.095 0 0"/>
    <geometry>
      <cylinder length="0.15" radius="0.01"/>
    </geometry>
  </collision>
 </link>

<joint name="branch_02_branch_03_joint_revolute_Y" type="revolute">
  <origin rpy="0 0 0" xyz="-0.19 0 0"/>
  <parent link="branch_02"/>
  <child link="branch_02_spherical_joint_link"/>
  <axis xyz="0 1 0"/>
  <dynamics damping="0.5" friction="0"/>
  <limit lower="-1.57" upper="1.57" effort="0.01" velocity="100"/>
</joint>

<link name="branch_02_spherical_joint_link" physical="0">
  <inertial>
  <mass value="0.05"/>
  <inertia ixx="0.005" ixy="0.001" ixz="0" iyy="0.006" iyz="0" izz="0.007"/>
  </inertial>
  <collision>
    <origin rpy="0 0 0" xyz="0 0 0"/>
    <geometry>
      <sphere radius="0.001"/>
    </geometry>
  </collision>
  <visual>
    <origin rpy="0 0 0" xyz="0 0 0"/>
    <geometry>
      <sphere radius="0.001"/>
    </geometry>
  </visual>
</link>

<joint name="branch_02_branch_03_joint_revolute_X" type="revolute">
  <origin rpy="0 0 0" xyz="0 0 0"/>
  <parent link="branch_02_spherical_joint_link"/>
  <child link="branch_03_cylinder"/>
  <axis xyz="0 0 1"/>
  <dynamics damping="0.5" friction="0"/>
  <limit lower="-1.57" upper="1.57" effort="0.01" velocity="100"/>
</joint>

<link name="branch_03">
  <inertial>
  <mass value="0.05"/>
  <inertia ixx="0.005" ixy="0.001" ixz="0" iyy="0.006" iyz="0" izz="0.007"/>
  </inertial>
  <collision>
    <origin rpy="0 0 0" xyz="-0.19 0 0"/>
    <geometry>
      <sphere radius="0.019"/>
    </geometry>
  </collision>
  <visual>
    <origin rpy="0 0 0" xyz="-0.19 0 0"/>
    <geometry>
      <sphere radius="0.019"/>
    </geometry>
  </visual>
</link>

<joint name="branch_03_fixed" type="fixed">
  <origin rpy="0 0 0" xyz="0 0 0"/>
  <parent link="branch_03_cylinder"/>
  <child link="branch_03"/>
</joint>

<!--############################################################################
branch_10
##############################################################################-->
 <link name="branch_10_cylinder">
  <inertial>
    <mass value="0.05"/>
    <inertia ixx="0.005" ixy="0.001" ixz="0" iyy="0.006" iyz="0" izz="0.007"/>
  </inertial>
  <visual>
    <origin rpy="0 1.54 0" xyz="-0.075 0 0"/>
    <geometry>
      <cylinder length="0.15" radius="0.01"/>
    </geometry>
  </visual>
  <collision>
    <origin rpy="0 1.57 0" xyz="-0.075 0 0"/>
    <geometry>
      <cylinder length="0.15" radius="0.01"/>
    </geometry>
  </collision>
 </link>

<joint name="head_branch_10_joint" type="fixed">
  <origin rpy="0 0 0" xyz="-0.1 3.06161699787e-18 0.05"/>
  <parent link="head"/>
  <child link="branch_10_cylinder"/>
</joint>

<link name="branch_10">
  <inertial>
  <mass value="0.05"/>
  <inertia ixx="0.005" ixy="0.001" ixz="0" iyy="0.006" iyz="0" izz="0.007"/>
  </inertial>
  <collision>
    <origin rpy="0 0 0" xyz="-0.17 0 0"/>
    <geometry>
      <sphere radius="0.019"/>
    </geometry>
  </collision>
  <visual>
    <origin rpy="0 0 0" xyz="-0.17 0 0"/>
    <geometry>
      <sphere radius="0.019"/>
    </geometry>
  </visual>
</link>

<joint name="branch_10_fixed" type="fixed">
  <origin rpy="0 0 0" xyz="0 0 0"/>
  <parent link="branch_10_cylinder"/>
  <child link="branch_10"/>
</joint>

 <link name="branch_11_cylinder">
  <inertial>
    <mass value="0.05"/>
    <inertia ixx="0.005" ixy="0.001" ixz="0" iyy="0.006" iyz="0" izz="0.007"/>
  </inertial>
  <visual>
    <origin rpy="0 1.54 0" xyz="-0.095 0 0"/>
    <geometry>
      <cylinder length="0.15" radius="0.01"/>
    </geometry>
  </visual>
  <collision>
    <origin rpy="0 1.57 0" xyz="-0.095 0 0"/>
    <geometry>
      <cylinder length="0.15" radius="0.01"/>
    </geometry>
  </collision>
 </link>

<joint name="branch_10_branch_11_joint_revolute_Y" type="revolute">
  <origin rpy="0 0 0" xyz="-0.17 0 0"/>
  <parent link="branch_10"/>
  <child link="branch_10_spherical_joint_link"/>
  <axis xyz="0 1 0"/>
  <dynamics damping="0.5" friction="0"/>
  <limit lower="-1.57" upper="1.57" effort="0.01" velocity="100"/>
</joint>

<link name="branch_10_spherical_joint_link" physical="0">
  <inertial>
  <mass value="0.05"/>
  <inertia ixx="0.005" ixy="0.001" ixz="0" iyy="0.006" iyz="0" izz="0.007"/>
  </inertial>
  <collision>
    <origin rpy="0 0 0" xyz="0 0 0"/>
    <geometry>
      <sphere radius="0.001"/>
    </geometry>
  </collision>
  <visual>
    <origin rpy="0 0 0" xyz="0 0 0"/>
    <geometry>
      <sphere radius="0.001"/>
    </geometry>
  </visual>
</link>

<joint name="branch_10_branch_11_joint_revolute_X" type="revolute">
  <origin rpy="0 0 0" xyz="0 0 0"/>
  <parent link="branch_10_spherical_joint_link"/>
  <child link="branch_11_cylinder"/>
  <axis xyz="0 0 1"/>
  <dynamics damping="0.5" friction="0"/>
  <limit lower="-1.57" upper="1.57" effort="0.01" velocity="100"/>
</joint>

<link name="branch_11">
  <inertial>
  <mass value="0.05"/>
  <inertia ixx="0.005" ixy="0.001" ixz="0" iyy="0.006" iyz="0" izz="0.007"/>
  </inertial>
  <collision>
    <origin rpy="0 0 0" xyz="-0.19 0 0"/>
    <geometry>
      <sphere radius="0.019"/>
    </geometry>
  </collision>
  <visual>
    <origin rpy="0 0 0" xyz="-0.19 0 0"/>
    <geometry>
      <sphere radius="0.019"/>
    </geometry>
  </visual>
</link>

<joint name="branch_11_fixed" type="fixed">
  <origin rpy="0 0 0" xyz="0 0 0"/>
  <parent link="branch_11_cylinder"/>
  <child link="branch_11"/>
</joint>

 <link name="branch_12_cylinder">
  <inertial>
    <mass value="0.05"/>
    <inertia ixx="0.005" ixy="0.001" ixz="0" iyy="0.006" iyz="0" izz="0.007"/>
  </inertial>
  <visual>
    <origin rpy="0 1.54 0" xyz="-0.095 0 0"/>
    <geometry>
      <cylinder length="0.15" radius="0.01"/>
    </geometry>
  </visual>
  <collision>
    <origin rpy="0 1.57 0" xyz="-0.095 0 0"/>
    <geometry>
      <cylinder length="0.15" radius="0.01"/>
    </geometry>
  </collision>
 </link>

<joint name="branch_11_branch_12_joint_revolute_Y" type="revolute">
  <origin rpy="0 0 0" xyz="-0.19 0 0"/>
  <parent link="branch_11"/>
  <child link="branch_11_spherical_joint_link"/>
  <axis xyz="0 1 0"/>
  <dynamics damping="0.5" friction="0"/>
  <limit lower="-1.57" upper="1.57" effort="0.01" velocity="100"/>
</joint>

<link name="branch_11_spherical_joint_link" physical="0">
  <inertial>
  <mass value="0.05"/>
  <inertia ixx="0.005" ixy="0.001" ixz="0" iyy="0.006" iyz="0" izz="0.007"/>
  </inertial>
  <collision>
    <origin rpy="0 0 0" xyz="0 0 0"/>
    <geometry>
      <sphere radius="0.001"/>
    </geometry>
  </collision>
  <visual>
    <origin rpy="0 0 0" xyz="0 0 0"/>
    <geometry>
      <sphere radius="0.001"/>
    </geometry>
  </visual>
</link>

<joint name="branch_11_branch_12_joint_revolute_X" type="revolute">
  <origin rpy="0 0 0" xyz="0 0 0"/>
  <parent link="branch_11_spherical_joint_link"/>
  <child link="branch_12_cylinder"/>
  <axis xyz="0 0 1"/>
  <dynamics damping="0.5" friction="0"/>
  <limit lower="-1.57" upper="1.57" effort="0.01" velocity="100"/>
</joint>

<link name="branch_12">
  <inertial>
  <mass value="0.05"/>
  <inertia ixx="0.005" ixy="0.001" ixz="0" iyy="0.006" iyz="0" izz="0.007"/>
  </inertial>
  <collision>
    <origin rpy="0 0 0" xyz="-0.19 0 0"/>
    <geometry>
      <sphere radius="0.019"/>
    </geometry>
  </collision>
  <visual>
    <origin rpy="0 0 0" xyz="-0.19 0 0"/>
    <geometry>
      <sphere radius="0.019"/>
    </geometry>
  </visual>
</link>

<joint name="branch_12_fixed" type="fixed">
  <origin rpy="0 0 0" xyz="0 0 0"/>
  <parent link="branch_12_cylinder"/>
  <child link="branch_12"/>
</joint>

 <link name="branch_13_cylinder">
  <inertial>
    <mass value="0.05"/>
    <inertia ixx="0.005" ixy="0.001" ixz="0" iyy="0.006" iyz="0" izz="0.007"/>
  </inertial>
  <visual>
    <origin rpy="0 1.54 0" xyz="-0.095 0 0"/>
    <geometry>
      <cylinder length="0.15" radius="0.01"/>
    </geometry>
  </visual>
  <collision>
    <origin rpy="0 1.57 0" xyz="-0.095 0 0"/>
    <geometry>
      <cylinder length="0.15" radius="0.01"/>
    </geometry>
  </collision>
 </link>

<joint name="branch_12_branch_13_joint_revolute_Y" type="revolute">
  <origin rpy="0 0 0" xyz="-0.19 0 0"/>
  <parent link="branch_12"/>
  <child link="branch_12_spherical_joint_link"/>
  <axis xyz="0 1 0"/>
  <dynamics damping="0.5" friction="0"/>
  <limit lower="-1.57" upper="1.57" effort="0.01" velocity="100"/>
</joint>

<link name="branch_12_spherical_joint_link" physical="0">
  <inertial>
  <mass value="0.05"/>
  <inertia ixx="0.005" ixy="0.001" ixz="0" iyy="0.006" iyz="0" izz="0.007"/>
  </inertial>
  <collision>
    <origin rpy="0 0 0" xyz="0 0 0"/>
    <geometry>
      <sphere radius="0.001"/>
    </geometry>
  </collision>
  <visual>
    <origin rpy="0 0 0" xyz="0 0 0"/>
    <geometry>
      <sphere radius="0.001"/>
    </geometry>
  </visual>
</link>

<joint name="branch_12_branch_13_joint_revolute_X" type="revolute">
  <origin rpy="0 0 0" xyz="0 0 0"/>
  <parent link="branch_12_spherical_joint_link"/>
  <child link="branch_13_cylinder"/>
  <axis xyz="0 0 1"/>
  <dynamics damping="0.5" friction="0"/>
  <limit lower="-1.57" upper="1.57" effort="0.01" velocity="100"/>
</joint>

<link name="branch_13">
  <inertial>
  <mass value="0.05"/>
  <inertia ixx="0.005" ixy="0.001" ixz="0" iyy="0.006" iyz="0" izz="0.007"/>
  </inertial>
  <collision>
    <origin rpy="0 0 0" xyz="-0.19 0 0"/>
    <geometry>
      <sphere radius="0.019"/>
    </geometry>
  </collision>
  <visual>
    <origin rpy="0 0 0" xyz="-0.19 0 0"/>
    <geometry>
      <sphere radius="0.019"/>
    </geometry>
  </visual>
</link>

<joint name="branch_13_fixed" type="fixed">
  <origin rpy="0 0 0" xyz="0 0 0"/>
  <parent link="branch_13_cylinder"/>
  <child link="branch_13"/>
</joint>

<!--############################################################################
branch_20
##############################################################################-->
 <link name="branch_20_cylinder">
  <inertial>
    <mass value="0.05"/>
    <inertia ixx="0.005" ixy="0.001" ixz="0" iyy="0.006" iyz="0" izz="0.007"/>
  </inertial>
  <visual>
    <origin rpy="0 1.54 0" xyz="-0.075 0 0"/>
    <geometry>
      <cylinder length="0.15" radius="0.01"/>
    </geometry>
  </visual>
  <collision>
    <origin rpy="0 1.57 0" xyz="-0.075 0 0"/>
    <geometry>
      <cylinder length="0.15" radius="0.01"/>
    </geometry>
  </collision>
 </link>

<joint name="head_branch_20_joint" type="fixed">
  <origin rpy="0 0 0" xyz="-0.1 -0.05 6.12323399574e-18"/>
  <parent link="head"/>
  <child link="branch_20_cylinder"/>
</joint>

<link name="branch_20">
  <inertial>
  <mass value="0.05"/>
  <inertia ixx="0.005" ixy="0.001" ixz="0" iyy="0.006" iyz="0" izz="0.007"/>
  </inertial>
  <collision>
    <origin rpy="0 0 0" xyz="-0.17 0 0"/>
    <geometry>
      <sphere radius="0.019"/>
    </geometry>
  </collision>
  <visual>
    <origin rpy="0 0 0" xyz="-0.17 0 0"/>
    <geometry>
      <sphere radius="0.019"/>
    </geometry>
  </visual>
</link>

<joint name="branch_20_fixed" type="fixed">
  <origin rpy="0 0 0" xyz="0 0 0"/>
  <parent link="branch_20_cylinder"/>
  <child link="branch_20"/>
</joint>

 <link name="branch_21_cylinder">
  <inertial>
    <mass value="0.05"/>
    <inertia ixx="0.005" ixy="0.001" ixz="0" iyy="0.006" iyz="0" izz="0.007"/>
  </inertial>
  <visual>
    <origin rpy="0 1.54 0" xyz="-0.095 0 0"/>
    <geometry>
      <cylinder length="0.15" radius="0.01"/>
    </geometry>
  </visual>
  <collision>
    <origin rpy="0 1.57 0" xyz="-0.095 0 0"/>
    <geometry>
      <cylinder length="0.15" radius="0.01"/>
    </geometry>
  </collision>
 </link>

<joint name="branch_20_branch_21_joint_revolute_Y" type="revolute">
  <origin rpy="0 0 0" xyz="-0.17 0 0"/>
  <parent link="branch_20"/>
  <child link="branch_20_spherical_joint_link"/>
  <axis xyz="0 1 0"/>
  <dynamics damping="0.5" friction="0"/>
  <limit lower="-1.57" upper="1.57" effort="0.01" velocity="100"/>
</joint>

<link name="branch_20_spherical_joint_link" physical="0">
  <inertial>
  <mass value="0.05"/>
  <inertia ixx="0.005" ixy="0.001" ixz="0" iyy="0.006" iyz="0" izz="0.007"/>
  </inertial>
  <collision>
    <origin rpy="0 0 0" xyz="0 0 0"/>
    <geometry>
      <sphere radius="0.001"/>
    </geometry>
  </collision>
  <visual>
    <origin rpy="0 0 0" xyz="0 0 0"/>
    <geometry>
      <sphere radius="0.001"/>
    </geometry>
  </visual>
</link>

<joint name="branch_20_branch_21_joint_revolute_X" type="revolute">
  <origin rpy="0 0 0" xyz="0 0 0"/>
  <parent link="branch_20_spherical_joint_link"/>
  <child link="branch_21_cylinder"/>
  <axis xyz="0 0 1"/>
  <dynamics damping="0.5" friction="0"/>
  <limit lower="-1.57" upper="1.57" effort="0.01" velocity="100"/>
</joint>

<link name="branch_21">
  <inertial>
  <mass value="0.05"/>
  <inertia ixx="0.005" ixy="0.001" ixz="0" iyy="0.006" iyz="0" izz="0.007"/>
  </inertial>
  <collision>
    <origin rpy="0 0 0" xyz="-0.19 0 0"/>
    <geometry>
      <sphere radius="0.019"/>
    </geometry>
  </collision>
  <visual>
    <origin rpy="0 0 0" xyz="-0.19 0 0"/>
    <geometry>
      <sphere radius="0.019"/>
    </geometry>
  </visual>
</link>

<joint name="branch_21_fixed" type="fixed">
  <origin rpy="0 0 0" xyz="0 0 0"/>
  <parent link="branch_21_cylinder"/>
  <child link="branch_21"/>
</joint>

 <link name="branch_22_cylinder">
  <inertial>
    <mass value="0.05"/>
    <inertia ixx="0.005" ixy="0.001" ixz="0" iyy="0.006" iyz="0" izz="0.007"/>
  </inertial>
  <visual>
    <origin rpy="0 1.54 0" xyz="-0.095 0 0"/>
    <geometry>
      <cylinder length="0.15" radius="0.01"/>
    </geometry>
  </visual>
  <collision>
    <origin rpy="0 1.57 0" xyz="-0.095 0 0"/>
    <geometry>
      <cylinder length="0.15" radius="0.01"/>
    </geometry>
  </collision>
 </link>

<joint name="branch_21_branch_22_joint_revolute_Y" type="revolute">
  <origin rpy="0 0 0" xyz="-0.19 0 0"/>
  <parent link="branch_21"/>
  <child link="branch_21_spherical_joint_link"/>
  <axis xyz="0 1 0"/>
  <dynamics damping="0.5" friction="0"/>
  <limit lower="-1.57" upper="1.57" effort="0.01" velocity="100"/>
</joint>

<link name="branch_21_spherical_joint_link" physical="0">
  <inertial>
  <mass value="0.05"/>
  <inertia ixx="0.005" ixy="0.001" ixz="0" iyy="0.006" iyz="0" izz="0.007"/>
  </inertial>
  <collision>
    <origin rpy="0 0 0" xyz="0 0 0"/>
    <geometry>
      <sphere radius="0.001"/>
    </geometry>
  </collision>
  <visual>
    <origin rpy="0 0 0" xyz="0 0 0"/>
    <geometry>
      <sphere radius="0.001"/>
    </geometry>
  </visual>
</link>

<joint name="branch_21_branch_22_joint_revolute_X" type="revolute">
  <origin rpy="0 0 0" xyz="0 0 0"/>
  <parent link="branch_21_spherical_joint_link"/>
  <child link="branch_22_cylinder"/>
  <axis xyz="0 0 1"/>
  <dynamics damping="0.5" friction="0"/>
  <limit lower="-1.57" upper="1.57" effort="0.01" velocity="100"/>
</joint>

<link name="branch_22">
  <inertial>
  <mass value="0.05"/>
  <inertia ixx="0.005" ixy="0.001" ixz="0" iyy="0.006" iyz="0" izz="0.007"/>
  </inertial>
  <collision>
    <origin rpy="0 0 0" xyz="-0.19 0 0"/>
    <geometry>
      <sphere radius="0.019"/>
    </geometry>
  </collision>
  <visual>
    <origin rpy="0 0 0" xyz="-0.19 0 0"/>
    <geometry>
      <sphere radius="0.019"/>
    </geometry>
  </visual>
</link>

<joint name="branch_22_fixed" type="fixed">
  <origin rpy="0 0 0" xyz="0 0 0"/>
  <parent link="branch_22_cylinder"/>
  <child link="branch_22"/>
</joint>

 <link name="branch_23_cylinder">
  <inertial>
    <mass value="0.05"/>
    <inertia ixx="0.005" ixy="0.001" ixz="0" iyy="0.006" iyz="0" izz="0.007"/>
  </inertial>
  <visual>
    <origin rpy="0 1.54 0" xyz="-0.095 0 0"/>
    <geometry>
      <cylinder length="0.15" radius="0.01"/>
    </geometry>
  </visual>
  <collision>
    <origin rpy="0 1.57 0" xyz="-0.095 0 0"/>
    <geometry>
      <cylinder length="0.15" radius="0.01"/>
    </geometry>
  </collision>
 </link>

<joint name="branch_22_branch_23_joint_revolute_Y" type="revolute">
  <origin rpy="0 0 0" xyz="-0.19 0 0"/>
  <parent link="branch_22"/>
  <child link="branch_22_spherical_joint_link"/>
  <axis xyz="0 1 0"/>
  <dynamics damping="0.5" friction="0"/>
  <limit lower="-1.57" upper="1.57" effort="0.01" velocity="100"/>
</joint>

<link name="branch_22_spherical_joint_link" physical="0">
  <inertial>
  <mass value="0.05"/>
  <inertia ixx="0.005" ixy="0.001" ixz="0" iyy="0.006" iyz="0" izz="0.007"/>
  </inertial>
  <collision>
    <origin rpy="0 0 0" xyz="0 0 0"/>
    <geometry>
      <sphere radius="0.001"/>
    </geometry>
  </collision>
  <visual>
    <origin rpy="0 0 0" xyz="0 0 0"/>
    <geometry>
      <sphere radius="0.001"/>
    </geometry>
  </visual>
</link>

<joint name="branch_22_branch_23_joint_revolute_X" type="revolute">
  <origin rpy="0 0 0" xyz="0 0 0"/>
  <parent link="branch_22_spherical_joint_link"/>
  <child link="branch_23_cylinder"/>
  <axis xyz="0 0 1"/>
  <dynamics damping="0.5" friction="0"/>
  <limit lower="-1.57" upper="1.57" effort="0.01" velocity="100"/>
</joint>

<link name="branch_23">
  <inertial>
  <mass value="0.05"/>
  <inertia ixx="0.005" ixy="0.001" ixz="0" iyy="0.006" iyz="0" izz="0.007"/>
  </inertial>
  <collision>
    <origin rpy="0 0 0" xyz="-0.19 0 0"/>
    <geometry>
      <sphere radius="0.019"/>
    </geometry>
  </collision>
  <visual>
    <origin rpy="0 0 0" xyz="-0.19 0 0"/>
    <geometry>
      <sphere radius="0.019"/>
    </geometry>
  </visual>
</link>

<joint name="branch_23_fixed" type="fixed">
  <origin rpy="0 0 0" xyz="0 0 0"/>
  <parent link="branch_23_cylinder"/>
  <child link="branch_23"/>
</joint>

<!--############################################################################
branch_30
##############################################################################-->
 <link name="branch_30_cylinder">
  <inertial>
    <mass value="0.05"/>
    <inertia ixx="0.005" ixy="0.001" ixz="0" iyy="0.006" iyz="0" izz="0.007"/>
  </inertial>
  <visual>
    <origin rpy="0 1.54 0" xyz="-0.075 0 0"/>
    <geometry>
      <cylinder length="0.15" radius="0.01"/>
    </geometry>
  </visual>
  <collision>
    <origin rpy="0 1.57 0" xyz="-0.075 0 0"/>
    <geometry>
      <cylinder length="0.15" radius="0.01"/>
    </geometry>
  </collision>
 </link>

<joint name="head_branch_30_joint" type="fixed">
  <origin rpy="0 0 0" xyz="-0.1 -9.18485099361e-18 -0.05"/>
  <parent link="head"/>
  <child link="branch_30_cylinder"/>
</joint>

<link name="branch_30">
  <inertial>
  <mass value="0.05"/>
  <inertia ixx="0.005" ixy="0.001" ixz="0" iyy="0.006" iyz="0" izz="0.007"/>
  </inertial>
  <collision>
    <origin rpy="0 0 0" xyz="-0.17 0 0"/>
    <geometry>
      <sphere radius="0.019"/>
    </geometry>
  </collision>
  <visual>
    <origin rpy="0 0 0" xyz="-0.17 0 0"/>
    <geometry>
      <sphere radius="0.019"/>
    </geometry>
  </visual>
</link>

<joint name="branch_30_fixed" type="fixed">
  <origin rpy="0 0 0" xyz="0 0 0"/>
  <parent link="branch_30_cylinder"/>
  <child link="branch_30"/>
</joint>

 <link name="branch_31_cylinder">
  <inertial>
    <mass value="0.05"/>
    <inertia ixx="0.005" ixy="0.001" ixz="0" iyy="0.006" iyz="0" izz="0.007"/>
  </inertial>
  <visual>
    <origin rpy="0 1.54 0" xyz="-0.095 0 0"/>
    <geometry>
      <cylinder length="0.15" radius="0.01"/>
    </geometry>
  </visual>
  <collision>
    <origin rpy="0 1.57 0" xyz="-0.095 0 0"/>
    <geometry>
      <cylinder length="0.15" radius="0.01"/>
    </geometry>
  </collision>
 </link>

<joint name="branch_30_branch_31_joint_revolute_Y" type="revolute">
  <origin rpy="0 0 0" xyz="-0.17 0 0"/>
  <parent link="branch_30"/>
  <child link="branch_30_spherical_joint_link"/>
  <axis xyz="0 1 0"/>
  <dynamics damping="0.5" friction="0"/>
  <limit lower="-1.57" upper="1.57" effort="0.01" velocity="100"/>
</joint>

<link name="branch_30_spherical_joint_link" physical="0">
  <inertial>
  <mass value="0.05"/>
  <inertia ixx="0.005" ixy="0.001" ixz="0" iyy="0.006" iyz="0" izz="0.007"/>
  </inertial>
  <collision>
    <origin rpy="0 0 0" xyz="0 0 0"/>
    <geometry>
      <sphere radius="0.001"/>
    </geometry>
  </collision>
  <visual>
    <origin rpy="0 0 0" xyz="0 0 0"/>
    <geometry>
      <sphere radius="0.001"/>
    </geometry>
  </visual>
</link>

<joint name="branch_30_branch_31_joint_revolute_X" type="revolute">
  <origin rpy="0 0 0" xyz="0 0 0"/>
  <parent link="branch_30_spherical_joint_link"/>
  <child link="branch_31_cylinder"/>
  <axis xyz="0 0 1"/>
  <dynamics damping="0.5" friction="0"/>
  <limit lower="-1.57" upper="1.57" effort="0.01" velocity="100"/>
</joint>

<link name="branch_31">
  <inertial>
  <mass value="0.05"/>
  <inertia ixx="0.005" ixy="0.001" ixz="0" iyy="0.006" iyz="0" izz="0.007"/>
  </inertial>
  <collision>
    <origin rpy="0 0 0" xyz="-0.19 0 0"/>
    <geometry>
      <sphere radius="0.019"/>
    </geometry>
  </collision>
  <visual>
    <origin rpy="0 0 0" xyz="-0.19 0 0"/>
    <geometry>
      <sphere radius="0.019"/>
    </geometry>
  </visual>
</link>

<joint name="branch_31_fixed" type="fixed">
  <origin rpy="0 0 0" xyz="0 0 0"/>
  <parent link="branch_31_cylinder"/>
  <child link="branch_31"/>
</joint>

 <link name="branch_32_cylinder">
  <inertial>
    <mass value="0.05"/>
    <inertia ixx="0.005" ixy="0.001" ixz="0" iyy="0.006" iyz="0" izz="0.007"/>
  </inertial>
  <visual>
    <origin rpy="0 1.54 0" xyz="-0.095 0 0"/>
    <geometry>
      <cylinder length="0.15" radius="0.01"/>
    </geometry>
  </visual>
  <collision>
    <origin rpy="0 1.57 0" xyz="-0.095 0 0"/>
    <geometry>
      <cylinder length="0.15" radius="0.01"/>
    </geometry>
  </collision>
 </link>

<joint name="branch_31_branch_32_joint_revolute_Y" type="revolute">
  <origin rpy="0 0 0" xyz="-0.19 0 0"/>
  <parent link="branch_31"/>
  <child link="branch_31_spherical_joint_link"/>
  <axis xyz="0 1 0"/>
  <dynamics damping="0.5" friction="0"/>
  <limit lower="-1.57" upper="1.57" effort="0.01" velocity="100"/>
</joint>

<link name="branch_31_spherical_joint_link" physical="0">
  <inertial>
  <mass value="0.05"/>
  <inertia ixx="0.005" ixy="0.001" ixz="0" iyy="0.006" iyz="0" izz="0.007"/>
  </inertial>
  <collision>
    <origin rpy="0 0 0" xyz="0 0 0"/>
    <geometry>
      <sphere radius="0.001"/>
    </geometry>
  </collision>
  <visual>
    <origin rpy="0 0 0" xyz="0 0 0"/>
    <geometry>
      <sphere radius="0.001"/>
    </geometry>
  </visual>
</link>

<joint name="branch_31_branch_32_joint_revolute_X" type="revolute">
  <origin rpy="0 0 0" xyz="0 0 0"/>
  <parent link="branch_31_spherical_joint_link"/>
  <child link="branch_32_cylinder"/>
  <axis xyz="0 0 1"/>
  <dynamics damping="0.5" friction="0"/>
  <limit lower="-1.57" upper="1.57" effort="0.01" velocity="100"/>
</joint>

<link name="branch_32">
  <inertial>
  <mass value="0.05"/>
  <inertia ixx="0.005" ixy="0.001" ixz="0" iyy="0.006" iyz="0" izz="0.007"/>
  </inertial>
  <collision>
    <origin rpy="0 0 0" xyz="-0.19 0 0"/>
    <geometry>
      <sphere radius="0.019"/>
    </geometry>
  </collision>
  <visual>
    <origin rpy="0 0 0" xyz="-0.19 0 0"/>
    <geometry>
      <sphere radius="0.019"/>
    </geometry>
  </visual>
</link>

<joint name="branch_32_fixed" type="fixed">
  <origin rpy="0 0 0" xyz="0 0 0"/>
  <parent link="branch_32_cylinder"/>
  <child link="branch_32"/>
</joint>

 <link name="branch_33_cylinder">
  <inertial>
    <mass value="0.05"/>
    <inertia ixx="0.005" ixy="0.001" ixz="0" iyy="0.006" iyz="0" izz="0.007"/>
  </inertial>
  <visual>
    <origin rpy="0 1.54 0" xyz="-0.095 0 0"/>
    <geometry>
      <cylinder length="0.15" radius="0.01"/>
    </geometry>
  </visual>
  <collision>
    <origin rpy="0 1.57 0" xyz="-0.095 0 0"/>
    <geometry>
      <cylinder length="0.15" radius="0.01"/>
    </geometry>
  </collision>
 </link>

<joint name="branch_32_branch_33_joint_revolute_Y" type="revolute">
  <origin rpy="0 0 0" xyz="-0.19 0 0"/>
  <parent link="branch_32"/>
  <child link="branch_32_spherical_joint_link"/>
  <axis xyz="0 1 0"/>
  <dynamics damping="0.5" friction="0"/>
  <limit lower="-1.57" upper="1.57" effort="0.01" velocity="100"/>
</joint>

<link name="branch_32_spherical_joint_link" physical="0">
  <inertial>
  <mass value="0.05"/>
  <inertia ixx="0.005" ixy="0.001" ixz="0" iyy="0.006" iyz="0" izz="0.007"/>
  </inertial>
  <collision>
    <origin rpy="0 0 0" xyz="0 0 0"/>
    <geometry>
      <sphere radius="0.001"/>
    </geometry>
  </collision>
  <visual>
    <origin rpy="0 0 0" xyz="0 0 0"/>
    <geometry>
      <sphere radius="0.001"/>
    </geometry>
  </visual>
</link>

<joint name="branch_32_branch_33_joint_revolute_X" type="revolute">
  <origin rpy="0 0 0" xyz="0 0 0"/>
  <parent link="branch_32_spherical_joint_link"/>
  <child link="branch_33_cylinder"/>
  <axis xyz="0 0 1"/>
  <dynamics damping="0.5" friction="0"/>
  <limit lower="-1.57" upper="1.57" effort="0.01" velocity="100"/>
</joint>

<link name="branch_33">
  <inertial>
  <mass value="0.05"/>
  <inertia ixx="0.005" ixy="0.001" ixz="0" iyy="0.006" iyz="0" izz="0.007"/>
  </inertial>
  <collision>
    <origin rpy="0 0 0" xyz="-0.19 0 0"/>
    <geometry>
      <sphere radius="0.019"/>
    </geometry>
  </collision>
  <visual>
    <origin rpy="0 0 0" xyz="-0.19 0 0"/>
    <geometry>
      <sphere radius="0.019"/>
    </geometry>
  </visual>
</link>

<joint name="branch_33_fixed" type="fixed">
  <origin rpy="0 0 0" xyz="0 0 0"/>
  <parent link="branch_33_cylinder"/>
  <child link="branch_33"/>
</joint>

  <klampt package_root="../../.." default_acc_max="4" >
  </klampt>
</robot>