<?xml version="1.0"?>
<robot name="snake_irreducible">
<link name="eye">
  <inertial>
   <mass value="1"/>
   <inertia ixx="0.004" ixy="0" ixz="0" iyy="0.004" iyz="0" izz="0.004"/>
  </inertial>
  <collision>
    <origin rpy="0 0 0" xyz="0 0 0"/>
    <geometry>
      <sphere radius="0.1"/>
    </geometry>
  </collision>
  <visual>
    <origin rpy="0 0 0" xyz="0 0 0"/>
    <geometry>
      <sphere radius="0.1"/>
    </geometry>
  </visual>
</link>

 <link name="head">
  <inertial>
    <mass value="1"/>
    <inertia ixx="0.00333333333333" ixy="0" ixz="0" iyy="0.00333333333333" iyz="0" izz="0.0025"/>
  </inertial>
  <visual>
    <origin rpy="0 1.57 0" xyz="-0.05 0 0"/>
    <geometry>
      <cylinder length="0.1" radius="0.1"/>
    </geometry>
  </visual>
  <collision>
    <origin rpy="0 1.57 0" xyz="-0.05 0 0"/>
    <geometry>
      <cylinder length="0.1" radius="0.1"/>
    </geometry>
  </collision>
 </link>

<joint name="joint_eye_head" type="fixed">
  <origin rpy="0 0 0" xyz="0 0 0"/>
  <parent link="eye"/>
  <child link="head"/>
</joint>

<!--############################################################################
body0
##############################################################################-->
 <link name="body0_cylinder">
  <inertial>
    <mass value="1"/>
    <inertia ixx="0.00145833333333" ixy="0" ixz="0" iyy="0.00145833333333" iyz="0" izz="0.00140625"/>
  </inertial>
  <visual>
    <origin rpy="0 1.57 0" xyz="-0.0125 0 0"/>
    <geometry>
      <cylinder length="0.025" radius="0.075"/>
    </geometry>
  </visual>
  <collision>
    <origin rpy="0 1.57 0" xyz="-0.0125 0 0"/>
    <geometry>
      <cylinder length="0.025" radius="0.075"/>
    </geometry>
  </collision>
 </link>

<joint name="head_body0_joint" type="fixed">
  <origin rpy="0 0 0" xyz="-0.11 0 0"/>
  <parent link="head"/>
  <child link="body0_cylinder"/>
</joint>

<link name="body0">
  <inertial>
   <mass value="1"/>
   <inertia ixx="0.0001444" ixy="0" ixz="0" iyy="0.0001444" iyz="0" izz="0.0001444"/>
  </inertial>
  <collision>
    <origin rpy="0 0 0" xyz="-0.045 0 0"/>
    <geometry>
      <sphere radius="0.019"/>
    </geometry>
  </collision>
  <visual>
    <origin rpy="0 0 0" xyz="-0.045 0 0"/>
    <geometry>
      <sphere radius="0.019"/>
    </geometry>
  </visual>
</link>

<joint name="body0_fixed" type="fixed">
  <origin rpy="0 0 0" xyz="0 0 0"/>
  <parent link="body0_cylinder"/>
  <child link="body0"/>
</joint>

 <link name="body1_cylinder">
  <inertial>
    <mass value="1"/>
    <inertia ixx="0.00473958333333" ixy="0" ixz="0" iyy="0.00473958333333" iyz="0" izz="0.00140625"/>
  </inertial>
  <visual>
    <origin rpy="0 1.57 0" xyz="-0.12 0 0"/>
    <geometry>
      <cylinder length="0.2" radius="0.075"/>
    </geometry>
  </visual>
  <collision>
    <origin rpy="0 1.57 0" xyz="-0.12 0 0"/>
    <geometry>
      <cylinder length="0.2" radius="0.075"/>
    </geometry>
  </collision>
 </link>

<joint name="body0_body1_joint_revolute_Z" type="revolute">
  <origin rpy="0 0 0" xyz="-0.045 0 0"/>
  <parent link="body0"/>
  <child link="body0_spherical_joint_link"/>
  <axis xyz="0 0 1"/>
  <dynamics damping="0.01" friction="0.5"/>
  <limit lower="-0.785398163397" upper="0.785398163397" effort="0.01" velocity="100"/>
</joint>

<link name="body0_spherical_joint_link" physical="0">
  <inertial>
   <mass value="1"/>
   <inertia ixx="4e-07" ixy="0" ixz="0" iyy="4e-07" iyz="0" izz="4e-07"/>
  </inertial>
  <collision>
    <origin rpy="0 0 0" xyz="0 0 0"/>
    <geometry>
      <sphere radius="0.001"/>
    </geometry>
  </collision>
  <visual>
    <origin rpy="0 0 0" xyz="0 0 0"/>
    <geometry>
      <sphere radius="0.001"/>
    </geometry>
  </visual>
</link>

<joint name="body0_body1_joint_revolute_Y" type="revolute">
  <origin rpy="0 0 0" xyz="0 0 0"/>
  <parent link="body0_spherical_joint_link"/>
  <child link="body1_cylinder"/>
  <axis xyz="0 1 0"/>
  <dynamics damping="0.01" friction="0.5"/>
  <limit lower="-0.785398163397" upper="0.785398163397" effort="0.01" velocity="100"/>
</joint>

<link name="body1">
  <inertial>
   <mass value="1"/>
   <inertia ixx="0.0001444" ixy="0" ixz="0" iyy="0.0001444" iyz="0" izz="0.0001444"/>
  </inertial>
  <collision>
    <origin rpy="0 0 0" xyz="-0.24 0 0"/>
    <geometry>
      <sphere radius="0.019"/>
    </geometry>
  </collision>
  <visual>
    <origin rpy="0 0 0" xyz="-0.24 0 0"/>
    <geometry>
      <sphere radius="0.019"/>
    </geometry>
  </visual>
</link>

<joint name="body1_fixed" type="fixed">
  <origin rpy="0 0 0" xyz="0 0 0"/>
  <parent link="body1_cylinder"/>
  <child link="body1"/>
</joint>

 <link name="body2_cylinder">
  <inertial>
    <mass value="1"/>
    <inertia ixx="0.00430989583333" ixy="0" ixz="0" iyy="0.00430989583333" iyz="0" izz="0.0009765625"/>
  </inertial>
  <visual>
    <origin rpy="0 1.57 0" xyz="-0.12 0 0"/>
    <geometry>
      <cylinder length="0.2" radius="0.0625"/>
    </geometry>
  </visual>
  <collision>
    <origin rpy="0 1.57 0" xyz="-0.12 0 0"/>
    <geometry>
      <cylinder length="0.2" radius="0.0625"/>
    </geometry>
  </collision>
 </link>

<joint name="body1_body2_joint_revolute_Z" type="revolute">
  <origin rpy="0 0 0" xyz="-0.24 0 0"/>
  <parent link="body1"/>
  <child link="body1_spherical_joint_link"/>
  <axis xyz="0 0 1"/>
  <dynamics damping="0.01" friction="0.5"/>
  <limit lower="-0.785398163397" upper="0.785398163397" effort="0.01" velocity="100"/>
</joint>

<link name="body1_spherical_joint_link" physical="0">
  <inertial>
   <mass value="1"/>
   <inertia ixx="4e-07" ixy="0" ixz="0" iyy="4e-07" iyz="0" izz="4e-07"/>
  </inertial>
  <collision>
    <origin rpy="0 0 0" xyz="0 0 0"/>
    <geometry>
      <sphere radius="0.001"/>
    </geometry>
  </collision>
  <visual>
    <origin rpy="0 0 0" xyz="0 0 0"/>
    <geometry>
      <sphere radius="0.001"/>
    </geometry>
  </visual>
</link>

<joint name="body1_body2_joint_revolute_Y" type="revolute">
  <origin rpy="0 0 0" xyz="0 0 0"/>
  <parent link="body1_spherical_joint_link"/>
  <child link="body2_cylinder"/>
  <axis xyz="0 1 0"/>
  <dynamics damping="0.01" friction="0.5"/>
  <limit lower="-0.785398163397" upper="0.785398163397" effort="0.01" velocity="100"/>
</joint>

<link name="body2">
  <inertial>
   <mass value="1"/>
   <inertia ixx="0.0001444" ixy="0" ixz="0" iyy="0.0001444" iyz="0" izz="0.0001444"/>
  </inertial>
  <collision>
    <origin rpy="0 0 0" xyz="-0.24 0 0"/>
    <geometry>
      <sphere radius="0.019"/>
    </geometry>
  </collision>
  <visual>
    <origin rpy="0 0 0" xyz="-0.24 0 0"/>
    <geometry>
      <sphere radius="0.019"/>
    </geometry>
  </visual>
</link>

<joint name="body2_fixed" type="fixed">
  <origin rpy="0 0 0" xyz="0 0 0"/>
  <parent link="body2_cylinder"/>
  <child link="body2"/>
</joint>

 <link name="body3_cylinder">
  <inertial>
    <mass value="1"/>
    <inertia ixx="0.00401150173611" ixy="0" ixz="0" iyy="0.00401150173611" iyz="0" izz="0.000678168402778"/>
  </inertial>
  <visual>
    <origin rpy="0 1.57 0" xyz="-0.12 0 0"/>
    <geometry>
      <cylinder length="0.2" radius="0.0520833333333"/>
    </geometry>
  </visual>
  <collision>
    <origin rpy="0 1.57 0" xyz="-0.12 0 0"/>
    <geometry>
      <cylinder length="0.2" radius="0.0520833333333"/>
    </geometry>
  </collision>
 </link>

<joint name="body2_body3_joint_revolute_Z" type="revolute">
  <origin rpy="0 0 0" xyz="-0.24 0 0"/>
  <parent link="body2"/>
  <child link="body2_spherical_joint_link"/>
  <axis xyz="0 0 1"/>
  <dynamics damping="0.01" friction="0.5"/>
  <limit lower="-0.785398163397" upper="0.785398163397" effort="0.01" velocity="100"/>
</joint>

<link name="body2_spherical_joint_link" physical="0">
  <inertial>
   <mass value="1"/>
   <inertia ixx="4e-07" ixy="0" ixz="0" iyy="4e-07" iyz="0" izz="4e-07"/>
  </inertial>
  <collision>
    <origin rpy="0 0 0" xyz="0 0 0"/>
    <geometry>
      <sphere radius="0.001"/>
    </geometry>
  </collision>
  <visual>
    <origin rpy="0 0 0" xyz="0 0 0"/>
    <geometry>
      <sphere radius="0.001"/>
    </geometry>
  </visual>
</link>

<joint name="body2_body3_joint_revolute_Y" type="revolute">
  <origin rpy="0 0 0" xyz="0 0 0"/>
  <parent link="body2_spherical_joint_link"/>
  <child link="body3_cylinder"/>
  <axis xyz="0 1 0"/>
  <dynamics damping="0.01" friction="0.5"/>
  <limit lower="-0.785398163397" upper="0.785398163397" effort="0.01" velocity="100"/>
</joint>

<link name="body3">
  <inertial>
   <mass value="1"/>
   <inertia ixx="0.0001444" ixy="0" ixz="0" iyy="0.0001444" iyz="0" izz="0.0001444"/>
  </inertial>
  <collision>
    <origin rpy="0 0 0" xyz="-0.24 0 0"/>
    <geometry>
      <sphere radius="0.019"/>
    </geometry>
  </collision>
  <visual>
    <origin rpy="0 0 0" xyz="-0.24 0 0"/>
    <geometry>
      <sphere radius="0.019"/>
    </geometry>
  </visual>
</link>

<joint name="body3_fixed" type="fixed">
  <origin rpy="0 0 0" xyz="0 0 0"/>
  <parent link="body3_cylinder"/>
  <child link="body3"/>
</joint>

  <klampt package_root="../../.." default_acc_max="4" >
  </klampt>
</robot>