<?xml version="1.0"?>
<robot name="spider">
<link name="eye">
  <inertial>
   <mass value="1"/>
   <inertia ixx="0.036" ixy="0" ixz="0" iyy="0.036" iyz="0" izz="0.036"/>
  </inertial>
  <collision>
    <origin rpy="0 0 0" xyz="0 0 0"/>
    <geometry>
      <sphere radius="0.3"/>
    </geometry>
  </collision>
  <visual>
    <origin rpy="0 0 0" xyz="0 0 0"/>
    <geometry>
      <sphere radius="0.3"/>
    </geometry>
  </visual>
</link>

<link name="eye_sphere_0">
  <inertial>
   <mass value="1"/>
   <inertia ixx="0.004" ixy="0" ixz="0" iyy="0.004" iyz="0" izz="0.004"/>
  </inertial>
  <collision>
    <origin rpy="0 0 0" xyz="0.4 0.0 0"/>
    <geometry>
      <sphere radius="0.1"/>
    </geometry>
  </collision>
  <visual>
    <origin rpy="0 0 0" xyz="0.4 0.0 0"/>
    <geometry>
      <sphere radius="0.1"/>
    </geometry>
  </visual>
</link>

<joint name="eye_sphere_0_fixed" type="fixed">
  <origin rpy="0 0 0" xyz="0 0 0"/>
  <parent link="eye"/>
  <child link="eye_sphere_0"/>
</joint>

<joint name="leg_0_link0_spherical_Z" type="revolute">
  <origin rpy="0 0 0" xyz="0.4 0.0 0"/>
  <parent link="eye_sphere_0"/>
  <child link="eye_sphere_0_spherical_joint_link"/>
  <axis xyz="0 0 1"/>
  <dynamics damping="1" friction="10"/>
  <limit lower="-0.196349540849" upper="0.196349540849" effort="1" velocity="100"/>
</joint>

<link name="eye_sphere_0_spherical_joint_link" physical="0">
  <inertial>
   <mass value="1"/>
   <inertia ixx="4e-07" ixy="0" ixz="0" iyy="4e-07" iyz="0" izz="4e-07"/>
  </inertial>
  <collision>
    <origin rpy="0 0 0" xyz="0 0 0"/>
    <geometry>
      <sphere radius="0.001"/>
    </geometry>
  </collision>
  <visual>
    <origin rpy="0 0 0" xyz="0 0 0"/>
    <geometry>
      <sphere radius="0.001"/>
    </geometry>
  </visual>
</link>

<joint name="leg_0_link0_spherical_Y" type="revolute">
  <origin rpy="0 0 0" xyz="0 0 0"/>
  <parent link="eye_sphere_0_spherical_joint_link"/>
  <child link="leg_0_link0"/>
  <axis xyz="0 1 0"/>
  <dynamics damping="1" friction="10"/>
  <limit lower="-0.196349540849" upper="0.196349540849" effort="1" velocity="100"/>
</joint>

 <link name="leg_0_link0">
  <inertial>
    <mass value="1"/>
    <inertia ixx="0.00860833333333" ixy="0" ixz="0" iyy="0.00860833333333" iyz="0" izz="0.0016"/>
  </inertial>
  <visual>
    <origin rpy="0 1.57 0.0" xyz="0.25 0.0 0"/>
    <geometry>
      <cylinder length="0.29" radius="0.08"/>
    </geometry>
  </visual>
  <collision>
    <origin rpy="0 1.57 0.0" xyz="0.25 0.0 0"/>
    <geometry>
      <cylinder length="0.29" radius="0.08"/>
    </geometry>
  </collision>
 </link>

<link name="leg_0_link0_sphere">
  <inertial>
   <mass value="1"/>
   <inertia ixx="0.004" ixy="0" ixz="0" iyy="0.004" iyz="0" izz="0.004"/>
  </inertial>
  <collision>
    <origin rpy="0 0 0" xyz="0.5 0.0 0"/>
    <geometry>
      <sphere radius="0.1"/>
    </geometry>
  </collision>
  <visual>
    <origin rpy="0 0 0" xyz="0.5 0.0 0"/>
    <geometry>
      <sphere radius="0.1"/>
    </geometry>
  </visual>
</link>

<joint name="leg_0_link0_fixed" type="fixed">
  <origin rpy="0 0 0" xyz="0 0 0"/>
  <parent link="leg_0_link0"/>
  <child link="leg_0_link0_sphere"/>
</joint>

<joint name="leg_0_link1_spherical_Z" type="revolute">
  <origin rpy="0 0 0" xyz="0.5 0.0 0"/>
  <parent link="leg_0_link0_sphere"/>
  <child link="leg_0_link0_sphere_spherical_joint_link"/>
  <axis xyz="0 0 1"/>
  <dynamics damping="1" friction="10"/>
  <limit lower="-0.196349540849" upper="0.196349540849" effort="1" velocity="100"/>
</joint>

<link name="leg_0_link0_sphere_spherical_joint_link" physical="0">
  <inertial>
   <mass value="1"/>
   <inertia ixx="4e-07" ixy="0" ixz="0" iyy="4e-07" iyz="0" izz="4e-07"/>
  </inertial>
  <collision>
    <origin rpy="0 0 0" xyz="0 0 0"/>
    <geometry>
      <sphere radius="0.001"/>
    </geometry>
  </collision>
  <visual>
    <origin rpy="0 0 0" xyz="0 0 0"/>
    <geometry>
      <sphere radius="0.001"/>
    </geometry>
  </visual>
</link>

<joint name="leg_0_link1_spherical_Y" type="revolute">
  <origin rpy="0 0 0" xyz="0 0 0"/>
  <parent link="leg_0_link0_sphere_spherical_joint_link"/>
  <child link="leg_0_link1"/>
  <axis xyz="0 1 0"/>
  <dynamics damping="1" friction="10"/>
  <limit lower="-0.196349540849" upper="0.196349540849" effort="1" velocity="100"/>
</joint>

 <link name="leg_0_link1">
  <inertial>
    <mass value="1"/>
    <inertia ixx="0.0472333333333" ixy="0" ixz="0" iyy="0.0472333333333" iyz="0" izz="0.0016"/>
  </inertial>
  <visual>
    <origin rpy="0 0 0.0" xyz="0 0 -0.475"/>
    <geometry>
      <cylinder length="0.74" radius="0.08"/>
    </geometry>
  </visual>
  <collision>
    <origin rpy="0 0 0.0" xyz="0 0 -0.475"/>
    <geometry>
      <cylinder length="0.74" radius="0.08"/>
    </geometry>
  </collision>
 </link>

<link name="leg_0_link1_sphere">
  <inertial>
   <mass value="1"/>
   <inertia ixx="0.004" ixy="0" ixz="0" iyy="0.004" iyz="0" izz="0.004"/>
  </inertial>
  <collision>
    <origin rpy="0 0 0" xyz="0 0 -0.95"/>
    <geometry>
      <sphere radius="0.1"/>
    </geometry>
  </collision>
  <visual>
    <origin rpy="0 0 0" xyz="0 0 -0.95"/>
    <geometry>
      <sphere radius="0.1"/>
    </geometry>
  </visual>
</link>

<joint name="leg_0_link1_fixed" type="fixed">
  <origin rpy="0 0 0" xyz="0 0 0"/>
  <parent link="leg_0_link1"/>
  <child link="leg_0_link1_sphere"/>
</joint>

<link name="eye_sphere_1">
  <inertial>
   <mass value="1"/>
   <inertia ixx="0.004" ixy="0" ixz="0" iyy="0.004" iyz="0" izz="0.004"/>
  </inertial>
  <collision>
    <origin rpy="0 0 0" xyz="-0.2 0.346410161514 0"/>
    <geometry>
      <sphere radius="0.1"/>
    </geometry>
  </collision>
  <visual>
    <origin rpy="0 0 0" xyz="-0.2 0.346410161514 0"/>
    <geometry>
      <sphere radius="0.1"/>
    </geometry>
  </visual>
</link>

<joint name="eye_sphere_1_fixed" type="fixed">
  <origin rpy="0 0 0" xyz="0 0 0"/>
  <parent link="eye"/>
  <child link="eye_sphere_1"/>
</joint>

<joint name="leg_1_link0_spherical_Z" type="revolute">
  <origin rpy="0 0 0" xyz="-0.2 0.346410161514 0"/>
  <parent link="eye_sphere_1"/>
  <child link="eye_sphere_1_spherical_joint_link"/>
  <axis xyz="0 0 1"/>
  <dynamics damping="1" friction="10"/>
  <limit lower="-0.196349540849" upper="0.196349540849" effort="1" velocity="100"/>
</joint>

<link name="eye_sphere_1_spherical_joint_link" physical="0">
  <inertial>
   <mass value="1"/>
   <inertia ixx="4e-07" ixy="0" ixz="0" iyy="4e-07" iyz="0" izz="4e-07"/>
  </inertial>
  <collision>
    <origin rpy="0 0 0" xyz="0 0 0"/>
    <geometry>
      <sphere radius="0.001"/>
    </geometry>
  </collision>
  <visual>
    <origin rpy="0 0 0" xyz="0 0 0"/>
    <geometry>
      <sphere radius="0.001"/>
    </geometry>
  </visual>
</link>

<joint name="leg_1_link0_spherical_Y" type="revolute">
  <origin rpy="0 0 0" xyz="0 0 0"/>
  <parent link="eye_sphere_1_spherical_joint_link"/>
  <child link="leg_1_link0"/>
  <axis xyz="0 1 0"/>
  <dynamics damping="1" friction="10"/>
  <limit lower="-0.196349540849" upper="0.196349540849" effort="1" velocity="100"/>
</joint>

 <link name="leg_1_link0">
  <inertial>
    <mass value="1"/>
    <inertia ixx="0.00860833333333" ixy="0" ixz="0" iyy="0.00860833333333" iyz="0" izz="0.0016"/>
  </inertial>
  <visual>
    <origin rpy="0 1.57 2.09439510239" xyz="-0.125 0.216506350946 0"/>
    <geometry>
      <cylinder length="0.29" radius="0.08"/>
    </geometry>
  </visual>
  <collision>
    <origin rpy="0 1.57 2.09439510239" xyz="-0.125 0.216506350946 0"/>
    <geometry>
      <cylinder length="0.29" radius="0.08"/>
    </geometry>
  </collision>
 </link>

<link name="leg_1_link0_sphere">
  <inertial>
   <mass value="1"/>
   <inertia ixx="0.004" ixy="0" ixz="0" iyy="0.004" iyz="0" izz="0.004"/>
  </inertial>
  <collision>
    <origin rpy="0 0 0" xyz="-0.25 0.433012701892 0"/>
    <geometry>
      <sphere radius="0.1"/>
    </geometry>
  </collision>
  <visual>
    <origin rpy="0 0 0" xyz="-0.25 0.433012701892 0"/>
    <geometry>
      <sphere radius="0.1"/>
    </geometry>
  </visual>
</link>

<joint name="leg_1_link0_fixed" type="fixed">
  <origin rpy="0 0 0" xyz="0 0 0"/>
  <parent link="leg_1_link0"/>
  <child link="leg_1_link0_sphere"/>
</joint>

<joint name="leg_1_link1_spherical_Z" type="revolute">
  <origin rpy="0 0 0" xyz="-0.25 0.433012701892 0"/>
  <parent link="leg_1_link0_sphere"/>
  <child link="leg_1_link0_sphere_spherical_joint_link"/>
  <axis xyz="0 0 1"/>
  <dynamics damping="1" friction="10"/>
  <limit lower="-0.196349540849" upper="0.196349540849" effort="1" velocity="100"/>
</joint>

<link name="leg_1_link0_sphere_spherical_joint_link" physical="0">
  <inertial>
   <mass value="1"/>
   <inertia ixx="4e-07" ixy="0" ixz="0" iyy="4e-07" iyz="0" izz="4e-07"/>
  </inertial>
  <collision>
    <origin rpy="0 0 0" xyz="0 0 0"/>
    <geometry>
      <sphere radius="0.001"/>
    </geometry>
  </collision>
  <visual>
    <origin rpy="0 0 0" xyz="0 0 0"/>
    <geometry>
      <sphere radius="0.001"/>
    </geometry>
  </visual>
</link>

<joint name="leg_1_link1_spherical_Y" type="revolute">
  <origin rpy="0 0 0" xyz="0 0 0"/>
  <parent link="leg_1_link0_sphere_spherical_joint_link"/>
  <child link="leg_1_link1"/>
  <axis xyz="0 1 0"/>
  <dynamics damping="1" friction="10"/>
  <limit lower="-0.196349540849" upper="0.196349540849" effort="1" velocity="100"/>
</joint>

 <link name="leg_1_link1">
  <inertial>
    <mass value="1"/>
    <inertia ixx="0.0472333333333" ixy="0" ixz="0" iyy="0.0472333333333" iyz="0" izz="0.0016"/>
  </inertial>
  <visual>
    <origin rpy="0 0 2.09439510239" xyz="0 0 -0.475"/>
    <geometry>
      <cylinder length="0.74" radius="0.08"/>
    </geometry>
  </visual>
  <collision>
    <origin rpy="0 0 2.09439510239" xyz="0 0 -0.475"/>
    <geometry>
      <cylinder length="0.74" radius="0.08"/>
    </geometry>
  </collision>
 </link>

<link name="leg_1_link1_sphere">
  <inertial>
   <mass value="1"/>
   <inertia ixx="0.004" ixy="0" ixz="0" iyy="0.004" iyz="0" izz="0.004"/>
  </inertial>
  <collision>
    <origin rpy="0 0 0" xyz="0 0 -0.95"/>
    <geometry>
      <sphere radius="0.1"/>
    </geometry>
  </collision>
  <visual>
    <origin rpy="0 0 0" xyz="0 0 -0.95"/>
    <geometry>
      <sphere radius="0.1"/>
    </geometry>
  </visual>
</link>

<joint name="leg_1_link1_fixed" type="fixed">
  <origin rpy="0 0 0" xyz="0 0 0"/>
  <parent link="leg_1_link1"/>
  <child link="leg_1_link1_sphere"/>
</joint>

<link name="eye_sphere_2">
  <inertial>
   <mass value="1"/>
   <inertia ixx="0.004" ixy="0" ixz="0" iyy="0.004" iyz="0" izz="0.004"/>
  </inertial>
  <collision>
    <origin rpy="0 0 0" xyz="-0.2 -0.346410161514 0"/>
    <geometry>
      <sphere radius="0.1"/>
    </geometry>
  </collision>
  <visual>
    <origin rpy="0 0 0" xyz="-0.2 -0.346410161514 0"/>
    <geometry>
      <sphere radius="0.1"/>
    </geometry>
  </visual>
</link>

<joint name="eye_sphere_2_fixed" type="fixed">
  <origin rpy="0 0 0" xyz="0 0 0"/>
  <parent link="eye"/>
  <child link="eye_sphere_2"/>
</joint>

<joint name="leg_2_link0_spherical_Z" type="revolute">
  <origin rpy="0 0 0" xyz="-0.2 -0.346410161514 0"/>
  <parent link="eye_sphere_2"/>
  <child link="eye_sphere_2_spherical_joint_link"/>
  <axis xyz="0 0 1"/>
  <dynamics damping="1" friction="10"/>
  <limit lower="-0.196349540849" upper="0.196349540849" effort="1" velocity="100"/>
</joint>

<link name="eye_sphere_2_spherical_joint_link" physical="0">
  <inertial>
   <mass value="1"/>
   <inertia ixx="4e-07" ixy="0" ixz="0" iyy="4e-07" iyz="0" izz="4e-07"/>
  </inertial>
  <collision>
    <origin rpy="0 0 0" xyz="0 0 0"/>
    <geometry>
      <sphere radius="0.001"/>
    </geometry>
  </collision>
  <visual>
    <origin rpy="0 0 0" xyz="0 0 0"/>
    <geometry>
      <sphere radius="0.001"/>
    </geometry>
  </visual>
</link>

<joint name="leg_2_link0_spherical_Y" type="revolute">
  <origin rpy="0 0 0" xyz="0 0 0"/>
  <parent link="eye_sphere_2_spherical_joint_link"/>
  <child link="leg_2_link0"/>
  <axis xyz="0 1 0"/>
  <dynamics damping="1" friction="10"/>
  <limit lower="-0.196349540849" upper="0.196349540849" effort="1" velocity="100"/>
</joint>

 <link name="leg_2_link0">
  <inertial>
    <mass value="1"/>
    <inertia ixx="0.00860833333333" ixy="0" ixz="0" iyy="0.00860833333333" iyz="0" izz="0.0016"/>
  </inertial>
  <visual>
    <origin rpy="0 1.57 4.18879020479" xyz="-0.125 -0.216506350946 0"/>
    <geometry>
      <cylinder length="0.29" radius="0.08"/>
    </geometry>
  </visual>
  <collision>
    <origin rpy="0 1.57 4.18879020479" xyz="-0.125 -0.216506350946 0"/>
    <geometry>
      <cylinder length="0.29" radius="0.08"/>
    </geometry>
  </collision>
 </link>

<link name="leg_2_link0_sphere">
  <inertial>
   <mass value="1"/>
   <inertia ixx="0.004" ixy="0" ixz="0" iyy="0.004" iyz="0" izz="0.004"/>
  </inertial>
  <collision>
    <origin rpy="0 0 0" xyz="-0.25 -0.433012701892 0"/>
    <geometry>
      <sphere radius="0.1"/>
    </geometry>
  </collision>
  <visual>
    <origin rpy="0 0 0" xyz="-0.25 -0.433012701892 0"/>
    <geometry>
      <sphere radius="0.1"/>
    </geometry>
  </visual>
</link>

<joint name="leg_2_link0_fixed" type="fixed">
  <origin rpy="0 0 0" xyz="0 0 0"/>
  <parent link="leg_2_link0"/>
  <child link="leg_2_link0_sphere"/>
</joint>

<joint name="leg_2_link1_spherical_Z" type="revolute">
  <origin rpy="0 0 0" xyz="-0.25 -0.433012701892 0"/>
  <parent link="leg_2_link0_sphere"/>
  <child link="leg_2_link0_sphere_spherical_joint_link"/>
  <axis xyz="0 0 1"/>
  <dynamics damping="1" friction="10"/>
  <limit lower="-0.196349540849" upper="0.196349540849" effort="1" velocity="100"/>
</joint>

<link name="leg_2_link0_sphere_spherical_joint_link" physical="0">
  <inertial>
   <mass value="1"/>
   <inertia ixx="4e-07" ixy="0" ixz="0" iyy="4e-07" iyz="0" izz="4e-07"/>
  </inertial>
  <collision>
    <origin rpy="0 0 0" xyz="0 0 0"/>
    <geometry>
      <sphere radius="0.001"/>
    </geometry>
  </collision>
  <visual>
    <origin rpy="0 0 0" xyz="0 0 0"/>
    <geometry>
      <sphere radius="0.001"/>
    </geometry>
  </visual>
</link>

<joint name="leg_2_link1_spherical_Y" type="revolute">
  <origin rpy="0 0 0" xyz="0 0 0"/>
  <parent link="leg_2_link0_sphere_spherical_joint_link"/>
  <child link="leg_2_link1"/>
  <axis xyz="0 1 0"/>
  <dynamics damping="1" friction="10"/>
  <limit lower="-0.196349540849" upper="0.196349540849" effort="1" velocity="100"/>
</joint>

 <link name="leg_2_link1">
  <inertial>
    <mass value="1"/>
    <inertia ixx="0.0472333333333" ixy="0" ixz="0" iyy="0.0472333333333" iyz="0" izz="0.0016"/>
  </inertial>
  <visual>
    <origin rpy="0 0 4.18879020479" xyz="0 0 -0.475"/>
    <geometry>
      <cylinder length="0.74" radius="0.08"/>
    </geometry>
  </visual>
  <collision>
    <origin rpy="0 0 4.18879020479" xyz="0 0 -0.475"/>
    <geometry>
      <cylinder length="0.74" radius="0.08"/>
    </geometry>
  </collision>
 </link>

<link name="leg_2_link1_sphere">
  <inertial>
   <mass value="1"/>
   <inertia ixx="0.004" ixy="0" ixz="0" iyy="0.004" iyz="0" izz="0.004"/>
  </inertial>
  <collision>
    <origin rpy="0 0 0" xyz="0 0 -0.95"/>
    <geometry>
      <sphere radius="0.1"/>
    </geometry>
  </collision>
  <visual>
    <origin rpy="0 0 0" xyz="0 0 -0.95"/>
    <geometry>
      <sphere radius="0.1"/>
    </geometry>
  </visual>
</link>

<joint name="leg_2_link1_fixed" type="fixed">
  <origin rpy="0 0 0" xyz="0 0 0"/>
  <parent link="leg_2_link1"/>
  <child link="leg_2_link1_sphere"/>
</joint>

  <klampt package_root="../../.." default_acc_max="4" >
  </klampt>
</robot>