<?xml version="1.0"?>
<robot name="robots/snake">
<link name="eye">
  <inertial>
   <mass value="1"/>
   <inertia ixx="0.009" ixy="0" ixz="0" iyy="0.009" iyz="0" izz="0.009"/>
  </inertial>
  <collision>
    <origin rpy="0 0 0" xyz="0 0 0"/>
    <geometry>
      <sphere radius="0.15"/>
    </geometry>
  </collision>
  <visual>
    <origin rpy="0 0 0" xyz="0 0 0"/>
    <geometry>
      <sphere radius="0.15"/>
    </geometry>
  </visual>
</link>

 <link name="head">
  <inertial>
    <mass value="1"/>
    <inertia ixx="0.0075" ixy="0" ixz="0" iyy="0.0075" iyz="0" izz="0.005625"/>
  </inertial>
  <visual>
    <origin rpy="0 1.57 0" xyz="-0.075 0 0"/>
    <geometry>
      <cylinder length="0.15" radius="0.15"/>
    </geometry>
  </visual>
  <collision>
    <origin rpy="0 1.57 0" xyz="-0.075 0 0"/>
    <geometry>
      <cylinder length="0.15" radius="0.15"/>
    </geometry>
  </collision>
 </link>

<joint name="joint_eye_head" type="fixed">
  <origin rpy="0 0 0" xyz="0 0 0"/>
  <parent link="eye"/>
  <child link="head"/>
</joint>

<!--############################################################################
body0
##############################################################################-->
 <link name="body0_cylinder">
  <inertial>
    <mass value="1"/>
    <inertia ixx="0.00207708333333" ixy="0" ixz="0" iyy="0.00207708333333" iyz="0" izz="0.002025"/>
  </inertial>
  <visual>
    <origin rpy="0 1.57 0" xyz="-0.0125 0 0"/>
    <geometry>
      <cylinder length="0.025" radius="0.09"/>
    </geometry>
  </visual>
  <collision>
    <origin rpy="0 1.57 0" xyz="-0.0125 0 0"/>
    <geometry>
      <cylinder length="0.025" radius="0.09"/>
    </geometry>
  </collision>
 </link>

<joint name="head_body0_joint" type="fixed">
  <origin rpy="0 0 0" xyz="-0.16 0 0"/>
  <parent link="head"/>
  <child link="body0_cylinder"/>
</joint>

<link name="body0">
  <inertial>
   <mass value="1"/>
   <inertia ixx="0.002030625" ixy="0" ixz="0" iyy="0.002030625" iyz="0" izz="0.002030625"/>
  </inertial>
  <collision>
    <origin rpy="0 0 0" xyz="-0.1 0 0"/>
    <geometry>
      <sphere radius="0.07125"/>
    </geometry>
  </collision>
  <visual>
    <origin rpy="0 0 0" xyz="-0.1 0 0"/>
    <geometry>
      <sphere radius="0.07125"/>
    </geometry>
  </visual>
</link>

<joint name="body0_fixed" type="fixed">
  <origin rpy="0 0 0" xyz="0 0 0"/>
  <parent link="body0_cylinder"/>
  <child link="body0"/>
</joint>

 <link name="body1_cylinder">
  <inertial>
    <mass value="1"/>
    <inertia ixx="0.00535833333333" ixy="0" ixz="0" iyy="0.00535833333333" iyz="0" izz="0.002025"/>
  </inertial>
  <visual>
    <origin rpy="0 1.57 0" xyz="-0.175 0 0"/>
    <geometry>
      <cylinder length="0.2" radius="0.09"/>
    </geometry>
  </visual>
  <collision>
    <origin rpy="0 1.57 0" xyz="-0.175 0 0"/>
    <geometry>
      <cylinder length="0.2" radius="0.09"/>
    </geometry>
  </collision>
 </link>

<joint name="body0_body1_joint_revolute_Z" type="revolute">
  <origin rpy="0 0 0" xyz="-0.1 0 0"/>
  <parent link="body0"/>
  <child link="body0_spherical_joint_link"/>
  <axis xyz="0 0 1"/>
  <dynamics damping="0.01" friction="0.5"/>
  <limit lower="-0.785398163397" upper="0.785398163397" effort="0.01" velocity="100"/>
</joint>

<link name="body0_spherical_joint_link" physical="0">
  <inertial>
   <mass value="1"/>
   <inertia ixx="4e-07" ixy="0" ixz="0" iyy="4e-07" iyz="0" izz="4e-07"/>
  </inertial>
  <collision>
    <origin rpy="0 0 0" xyz="0 0 0"/>
    <geometry>
      <sphere radius="0.001"/>
    </geometry>
  </collision>
  <visual>
    <origin rpy="0 0 0" xyz="0 0 0"/>
    <geometry>
      <sphere radius="0.001"/>
    </geometry>
  </visual>
</link>

<joint name="body0_body1_joint_revolute_Y" type="revolute">
  <origin rpy="0 0 0" xyz="0 0 0"/>
  <parent link="body0_spherical_joint_link"/>
  <child link="body1_cylinder"/>
  <axis xyz="0 1 0"/>
  <dynamics damping="0.01" friction="0.5"/>
  <limit lower="-0.785398163397" upper="0.785398163397" effort="0.01" velocity="100"/>
</joint>

<link name="body1">
  <inertial>
   <mass value="1"/>
   <inertia ixx="0.002030625" ixy="0" ixz="0" iyy="0.002030625" iyz="0" izz="0.002030625"/>
  </inertial>
  <collision>
    <origin rpy="0 0 0" xyz="-0.35 0 0"/>
    <geometry>
      <sphere radius="0.07125"/>
    </geometry>
  </collision>
  <visual>
    <origin rpy="0 0 0" xyz="-0.35 0 0"/>
    <geometry>
      <sphere radius="0.07125"/>
    </geometry>
  </visual>
</link>

<joint name="body1_fixed" type="fixed">
  <origin rpy="0 0 0" xyz="0 0 0"/>
  <parent link="body1_cylinder"/>
  <child link="body1"/>
</joint>

 <link name="body2_cylinder">
  <inertial>
    <mass value="1"/>
    <inertia ixx="0.00535833333333" ixy="0" ixz="0" iyy="0.00535833333333" iyz="0" izz="0.002025"/>
  </inertial>
  <visual>
    <origin rpy="0 1.57 0" xyz="-0.175 0 0"/>
    <geometry>
      <cylinder length="0.2" radius="0.09"/>
    </geometry>
  </visual>
  <collision>
    <origin rpy="0 1.57 0" xyz="-0.175 0 0"/>
    <geometry>
      <cylinder length="0.2" radius="0.09"/>
    </geometry>
  </collision>
 </link>

<joint name="body1_body2_joint_revolute_Z" type="revolute">
  <origin rpy="0 0 0" xyz="-0.35 0 0"/>
  <parent link="body1"/>
  <child link="body1_spherical_joint_link"/>
  <axis xyz="0 0 1"/>
  <dynamics damping="0.01" friction="0.5"/>
  <limit lower="-0.785398163397" upper="0.785398163397" effort="0.01" velocity="100"/>
</joint>

<link name="body1_spherical_joint_link" physical="0">
  <inertial>
   <mass value="1"/>
   <inertia ixx="4e-07" ixy="0" ixz="0" iyy="4e-07" iyz="0" izz="4e-07"/>
  </inertial>
  <collision>
    <origin rpy="0 0 0" xyz="0 0 0"/>
    <geometry>
      <sphere radius="0.001"/>
    </geometry>
  </collision>
  <visual>
    <origin rpy="0 0 0" xyz="0 0 0"/>
    <geometry>
      <sphere radius="0.001"/>
    </geometry>
  </visual>
</link>

<joint name="body1_body2_joint_revolute_Y" type="revolute">
  <origin rpy="0 0 0" xyz="0 0 0"/>
  <parent link="body1_spherical_joint_link"/>
  <child link="body2_cylinder"/>
  <axis xyz="0 1 0"/>
  <dynamics damping="0.01" friction="0.5"/>
  <limit lower="-0.785398163397" upper="0.785398163397" effort="0.01" velocity="100"/>
</joint>

  <klampt package_root="../../.." default_acc_max="4" >
  </klampt>
</robot>