<?xml version="1.0"?>
<robot name="robots/snake_onelink_inner">
<link name="eye">
  <inertial>
   <mass value="1"/>
   <inertia ixx="0.00576" ixy="0" ixz="0" iyy="0.00576" iyz="0" izz="0.00576"/>
  </inertial>
  <collision>
    <origin rpy="0 0 0" xyz="0 0 0"/>
    <geometry>
      <sphere radius="0.12"/>
    </geometry>
  </collision>
  <visual>
    <origin rpy="0 0 0" xyz="0 0 0"/>
    <geometry>
      <sphere radius="0.12"/>
    </geometry>
  </visual>
</link>

 <link name="head">
  <inertial>
    <mass value="1"/>
    <inertia ixx="0.0048" ixy="0" ixz="0" iyy="0.0048" iyz="0" izz="0.0036"/>
  </inertial>
  <visual>
    <origin rpy="0 1.57 0" xyz="-0.06 0 0"/>
    <geometry>
      <cylinder length="0.12" radius="0.12"/>
    </geometry>
  </visual>
  <collision>
    <origin rpy="0 1.57 0" xyz="-0.06 0 0"/>
    <geometry>
      <cylinder length="0.12" radius="0.12"/>
    </geometry>
  </collision>
 </link>

<joint name="joint_eye_head" type="fixed">
  <origin rpy="0 0 0" xyz="0 0 0"/>
  <parent link="eye"/>
  <child link="head"/>
</joint>

<!--############################################################################
body0
##############################################################################-->
 <link name="body0_cylinder">
  <inertial>
    <mass value="1"/>
    <inertia ixx="0.0037171875" ixy="0" ixz="0" iyy="0.0037171875" iyz="0" izz="0.0036"/>
  </inertial>
  <visual>
    <origin rpy="0 1.57 0" xyz="-0.01875 0 0"/>
    <geometry>
      <cylinder length="0.0375" radius="0.12"/>
    </geometry>
  </visual>
  <collision>
    <origin rpy="0 1.57 0" xyz="-0.01875 0 0"/>
    <geometry>
      <cylinder length="0.0375" radius="0.12"/>
    </geometry>
  </collision>
 </link>

<joint name="head_body0_joint" type="fixed">
  <origin rpy="0 0 0" xyz="-0.13 0 0"/>
  <parent link="head"/>
  <child link="body0_cylinder"/>
</joint>

<link name="body0">
  <inertial>
   <mass value="1"/>
   <inertia ixx="0.0012996" ixy="0" ixz="0" iyy="0.0012996" iyz="0" izz="0.0012996"/>
  </inertial>
  <collision>
    <origin rpy="0 0 0" xyz="-0.0975 0 0"/>
    <geometry>
      <sphere radius="0.057"/>
    </geometry>
  </collision>
  <visual>
    <origin rpy="0 0 0" xyz="-0.0975 0 0"/>
    <geometry>
      <sphere radius="0.057"/>
    </geometry>
  </visual>
</link>

<joint name="body0_fixed" type="fixed">
  <origin rpy="0 0 0" xyz="0 0 0"/>
  <parent link="body0_cylinder"/>
  <child link="body0"/>
</joint>

 <link name="body1_cylinder">
  <inertial>
    <mass value="1"/>
    <inertia ixx="0.0111" ixy="0" ixz="0" iyy="0.0111" iyz="0" izz="0.0036"/>
  </inertial>
  <visual>
    <origin rpy="0 1.57 0" xyz="-0.21 0 0"/>
    <geometry>
      <cylinder length="0.3" radius="0.12"/>
    </geometry>
  </visual>
  <collision>
    <origin rpy="0 1.57 0" xyz="-0.21 0 0"/>
    <geometry>
      <cylinder length="0.3" radius="0.12"/>
    </geometry>
  </collision>
 </link>

<joint name="body0_body1_joint_revolute_Z" type="revolute">
  <origin rpy="0 0 0" xyz="-0.0975 0 0"/>
  <parent link="body0"/>
  <child link="body0_spherical_joint_link"/>
  <axis xyz="0 0 1"/>
  <dynamics damping="0.01" friction="0.5"/>
  <limit lower="-0.785398163397" upper="0.785398163397" effort="0.01" velocity="100"/>
</joint>

<link name="body0_spherical_joint_link" physical="0">
  <inertial>
   <mass value="1"/>
   <inertia ixx="4e-07" ixy="0" ixz="0" iyy="4e-07" iyz="0" izz="4e-07"/>
  </inertial>
  <collision>
    <origin rpy="0 0 0" xyz="0 0 0"/>
    <geometry>
      <sphere radius="0.001"/>
    </geometry>
  </collision>
  <visual>
    <origin rpy="0 0 0" xyz="0 0 0"/>
    <geometry>
      <sphere radius="0.001"/>
    </geometry>
  </visual>
</link>

<joint name="body0_body1_joint_revolute_Y" type="revolute">
  <origin rpy="0 0 0" xyz="0 0 0"/>
  <parent link="body0_spherical_joint_link"/>
  <child link="body1_cylinder"/>
  <axis xyz="0 1 0"/>
  <dynamics damping="0.01" friction="0.5"/>
  <limit lower="-0.785398163397" upper="0.785398163397" effort="0.01" velocity="100"/>
</joint>

  <klampt package_root="../../.." default_acc_max="4" >
  </klampt>
</robot>