<?xml version="1.0"?>
<robot name="magneto/magneto2">
 <link name="foot">
  <inertial>
    <mass value="1"/>
    <inertia ixx="0.0011583333333333335" ixy="0" ixz="0" iyy="0.0011583333333333335" iyz="0" izz="0.0006250000000000001"/>
  </inertial>
  <visual>
    <origin rpy="1.57 0 0" xyz="0 0 0"/>
    <geometry>
      <cylinder length="0.08" radius="0.05"/>
    </geometry>
  </visual>
  <collision>
    <origin rpy="1.57 0 0" xyz="0 0 0"/>
    <geometry>
      <cylinder length="0.08" radius="0.05"/>
    </geometry>
  </collision>
 </link>

 <link name="leg1">
  <inertial>
    <mass value="1"/>
    <inertia ixx="0.0037333333333333337" ixy="0" ixz="0" iyy="0.0037333333333333337" iyz="0" izz="0.0004"/>
  </inertial>
  <visual>
    <origin rpy="0 1.57 0" xyz="0.15000000000000002 0 0"/>
    <geometry>
      <cylinder length="0.2" radius="0.04"/>
    </geometry>
  </visual>
  <collision>
    <origin rpy="0 1.57 0" xyz="0.15000000000000002 0 0"/>
    <geometry>
      <cylinder length="0.2" radius="0.04"/>
    </geometry>
  </collision>
 </link>

<joint name="joint_fixed_foot_leg1" type="fixed">
  <origin rpy="0 0 0" xyz="0 0 0"/>
  <parent link="foot"/>
  <child link="leg1"/>
</joint>

 <link name="joint1">
  <inertial>
    <mass value="1"/>
    <inertia ixx="0.0009333333333333333" ixy="0" ixz="0" iyy="0.0009333333333333333" iyz="0" izz="0.0004"/>
  </inertial>
  <visual>
    <origin rpy="1.57 0 0" xyz="0.29 0 0"/>
    <geometry>
      <cylinder length="0.08" radius="0.04"/>
    </geometry>
  </visual>
  <collision>
    <origin rpy="1.57 0 0" xyz="0.29 0 0"/>
    <geometry>
      <cylinder length="0.08" radius="0.04"/>
    </geometry>
  </collision>
 </link>

<joint name="joint_fixed_leg1_joint1" type="fixed">
  <origin rpy="0 0 0" xyz="0 0 0"/>
  <parent link="leg1"/>
  <child link="joint1"/>
</joint>

 <link name="leg2">
  <inertial>
    <mass value="1"/>
    <inertia ixx="0.013733333333333334" ixy="0" ixz="0" iyy="0.013733333333333334" iyz="0" izz="0.0004"/>
  </inertial>
  <visual>
    <origin rpy="0 1.57 0" xyz="0.24000000000000002 0 0"/>
    <geometry>
      <cylinder length="0.4" radius="0.04"/>
    </geometry>
  </visual>
  <collision>
    <origin rpy="0 1.57 0" xyz="0.24000000000000002 0 0"/>
    <geometry>
      <cylinder length="0.4" radius="0.04"/>
    </geometry>
  </collision>
 </link>

<joint name="joint_revolute_joint1_leg2_Z" type="revolute">
  <origin rpy="0 0 0" xyz="0.29 0 0"/>
  <parent link="joint1"/>
  <child link="leg2"/>
  <axis xyz="0 1 0"/>
  <dynamics damping="0.01" friction="0.5"/>
  <limit lower="-1.57" upper="1.57" effort="0.01" velocity="100"/>
</joint>

 <link name="joint2">
  <inertial>
    <mass value="1"/>
    <inertia ixx="0.0009333333333333333" ixy="0" ixz="0" iyy="0.0009333333333333333" iyz="0" izz="0.0004"/>
  </inertial>
  <visual>
    <origin rpy="1.57 0 0" xyz="0.48000000000000004 0 0"/>
    <geometry>
      <cylinder length="0.08" radius="0.04"/>
    </geometry>
  </visual>
  <collision>
    <origin rpy="1.57 0 0" xyz="0.48000000000000004 0 0"/>
    <geometry>
      <cylinder length="0.08" radius="0.04"/>
    </geometry>
  </collision>
 </link>

<joint name="joint_fixed_leg2_joint2" type="fixed">
  <origin rpy="0 0 0" xyz="0 0 0"/>
  <parent link="leg2"/>
  <child link="joint2"/>
</joint>

 <link name="leg3">
  <inertial>
    <mass value="1"/>
    <inertia ixx="0.0037333333333333337" ixy="0" ixz="0" iyy="0.0037333333333333337" iyz="0" izz="0.0004"/>
  </inertial>
  <visual>
    <origin rpy="0 1.57 0" xyz="0.14 0 0"/>
    <geometry>
      <cylinder length="0.2" radius="0.04"/>
    </geometry>
  </visual>
  <collision>
    <origin rpy="0 1.57 0" xyz="0.14 0 0"/>
    <geometry>
      <cylinder length="0.2" radius="0.04"/>
    </geometry>
  </collision>
 </link>

<joint name="joint_revolute_joint2_leg3_Z" type="revolute">
  <origin rpy="0 0 0" xyz="0.48000000000000004 0 0"/>
  <parent link="joint2"/>
  <child link="leg3"/>
  <axis xyz="0 1 0"/>
  <dynamics damping="0.01" friction="0.5"/>
  <limit lower="-1.57" upper="1.57" effort="0.01" velocity="100"/>
</joint>

 <link name="foot2">
  <inertial>
    <mass value="1"/>
    <inertia ixx="0.0011583333333333335" ixy="0" ixz="0" iyy="0.0011583333333333335" iyz="0" izz="0.0006250000000000001"/>
  </inertial>
  <visual>
    <origin rpy="1.57 0 0" xyz="0.29000000000000004 0 0"/>
    <geometry>
      <cylinder length="0.08" radius="0.05"/>
    </geometry>
  </visual>
  <collision>
    <origin rpy="1.57 0 0" xyz="0.29000000000000004 0 0"/>
    <geometry>
      <cylinder length="0.08" radius="0.05"/>
    </geometry>
  </collision>
 </link>

<joint name="joint_fixed_leg3_foot2" type="fixed">
  <origin rpy="0 0 0" xyz="0 0 0"/>
  <parent link="leg3"/>
  <child link="foot2"/>
</joint>

  <klampt package_root="../../.." default_acc_max="4" >
  </klampt>
</robot>